Workbook

Sheet Quotation
A1: QUOTATION — Renovation and Extension, 53 Shlonsky St., Haifa
A2: Employer: Zohar Mor Yosef and Rami Dana | Contractor: [Contractor name] | Date: 14/10/2026 | Quotation no.: [__]
A3: All amounts in GBP (£), excluding VAT, price base October 2026. Unit rates include the contractor's overheads and profit (15%).
A5: Item | B5: Description | C5: Scope | D5: Unit | E5: Qty | F5: Unit rate | G5: Amount | H5: Remarks
A6: Chapter 1 — Preparation and Site Establishment
A7: 01.01 | B7: Site establishment | C7: Setting up work and storage areas, workers' facilities and access coordination. | D7: lot | E7: 1 | F7: 2580 | G7: =IF(AND(ISNUMBER(E7),ISNUMBER(F7)),ROUND(E7*F7,2),"") -> 2580
A8: 01.02 | B8: Site hoarding, signage and safety | C8: Temporary hoarding, site and hazard signage, and the safety measures required for the works. | D8: lot | E8: 1 | F8: 1290 | G8: =IF(AND(ISNUMBER(E8),ISNUMBER(F8)),ROUND(E8*F8,2),"") -> 1290
A9: 01.03 | B9: Temporary water connection | C9: Temporary water connection from the approved source, tested. | D9: lot | E9: 1 | F9: 484 | G9: =IF(AND(ISNUMBER(E9),ISNUMBER(F9)),ROUND(E9*F9,2),"") -> 484
A10: 01.04 | B10: Temporary electrical connection | C10: Temporary power connection by a licensed electrician, with protection and testing. | D10: lot | E10: 1 | F10: 970 | G10: =IF(AND(ISNUMBER(E10),ISNUMBER(F10)),ROUND(E10*F10,2),"") -> 970
A11: 01.05 | B11: Protection of existing elements | C11: Protective covers for floors, openings, windows, stairs, railings, walls and plants to be retained. | D11: lot | E11: 1 | F11: 1610 | G11: =IF(AND(ISNUMBER(E11),ISNUMBER(F11)),ROUND(E11*F11,2),"") -> 1610
A12: 01.06 | B12: Survey, verification and laser setting-out | C12: Survey of the existing building, verification against architectural and services drawings, setting-out of positions and levels. | D12: lot | E12: 1 | F12: 970 | G12: =IF(AND(ISNUMBER(E12),ISNUMBER(F12)),ROUND(E12*F12,2),"") -> 970
A13: 01.07 | B13: Waste skip and waste collection area | C13: Skip placement and a waste collection area; removal of waste to a licensed site. | D13: lot | E13: 1 | F13: 2900 | G13: =IF(AND(ISNUMBER(E13),ISNUMBER(F13)),ROUND(E13*F13,2),"") -> 2900
A14: 01.08 | B14: Ongoing site cleaning | C14: Periodic cleaning of work areas and passages throughout the works. | D14: lot | E14: 1 | F14: 2900 | G14: =IF(AND(ISNUMBER(E14),ISNUMBER(F14)),ROUND(E14*F14,2),"") -> 2900
A15: 01.09 | B15: External scaffolding | C15: Erection, rental for the works period (about 4.5 months), maintenance and removal of compliant external scaffolding around the facades, for sawing the decorative concrete frames and the facade plaster works. | D15: m² | E15: 225 | F15: 40.5 | G15: =IF(AND(ISNUMBER(E15),ISNUMBER(F15)),ROUND(E15*F15,2),"") -> 9112.5 | H15: Provisional quantity – remeasured
A16: Total – Chapter 1 | G16: =IF(COUNT(G7:G15)=0,"",SUM(G7:G15)) -> 22816.5
A18: Chapter 2 — Demolition, Removals and Disposal
A19: 02.01 | B19: Demolition of walls and partitions – basement | C19: Demolition of existing walls and partitions per demolition drawings. | D19: m² | E19: 62 | F19: 38.5 | G19: =IF(AND(ISNUMBER(E19),ISNUMBER(F19)),ROUND(E19*F19,2),"") -> 2387
A20: 02.02 | B20: Demolition of walls and partitions – ground floor | C20: Demolition of existing walls and partitions per demolition drawings. | D20: m² | E20: 51 | F20: 38.5 | G20: =IF(AND(ISNUMBER(E20),ISNUMBER(F20)),ROUND(E20*F20,2),"") -> 1963.5
A21: 02.03 | B21: Demolition of walls and partitions – first floor | C21: Demolition of existing walls and partitions per demolition drawings. | D21: m² | E21: 85 | F21: 38.5 | G21: =IF(AND(ISNUMBER(E21),ISNUMBER(F21)),ROUND(E21*F21,2),"") -> 3272.5
A22: 02.04 | B22: Removal of existing gypsum ceilings | C22: Removal of existing suspended gypsum ceilings. | D22: m² | E22: 10 | F22: 16 | G22: =IF(AND(ISNUMBER(E22),ISNUMBER(F22)),ROUND(E22*F22,2),"") -> 160
A23: 02.05 | B23: Removal of existing flooring | C23: Removal of existing floor finishes. | D23: m² | E23: 40 | F23: 29 | G23: =IF(AND(ISNUMBER(E23),ISNUMBER(F23)),ROUND(E23*F23,2),"") -> 1160
A24: 02.06 | B24: Removal of existing kitchen cabinets | C24: Removal of existing kitchen cabinets, complete. | D24: lot | E24: 1 | F24: 650 | G24: =IF(AND(ISNUMBER(E24),ISNUMBER(F24)),ROUND(E24*F24,2),"") -> 650
A25: 02.07 | B25: Removal of other existing joinery | C25: Removal of other existing cabinets and joinery. | D25: pcs | E25: 1 | F25: 810 | G25: =IF(AND(ISNUMBER(E25),ISNUMBER(F25)),ROUND(E25*F25,2),"") -> 810
A26: 02.08 | B26: Removal of existing aluminium windows and shutters | C26: Complete removal of existing aluminium windows and roller shutters. | D26: lot | E26: 1 | F26: 1940 | G26: =IF(AND(ISNUMBER(E26),ISNUMBER(F26)),ROUND(E26*F26,2),"") -> 1940
A27: 02.09 | B27: Removal of interior and entrance doors and frames | C27: Complete removal of existing interior and entrance doors and frames. | D27: lot | E27: 1 | F27: 1130 | G27: =IF(AND(ISNUMBER(E27),ISNUMBER(F27)),ROUND(E27*F27,2),"") -> 1130
A28: 02.10 | B28: Removal of bathrooms, WCs and sanitary ware | C28: Complete removal of existing bathrooms, WCs and sanitary fixtures. | D28: lot | E28: 1 | F28: 2580 | G28: =IF(AND(ISNUMBER(E28),ISNUMBER(F28)),ROUND(E28*F28,2),"") -> 2580
A29: 02.11 | B29: Removal of electrical points, accessories and light fittings | C29: Removal of existing electrical points, accessories and light fittings. | D29: lot | E29: 1 | F29: 1290 | G29: =IF(AND(ISNUMBER(E29),ISNUMBER(F29)),ROUND(E29*F29,2),"") -> 1290
A30: 02.12 | B30: Removal of existing exposed plumbing | C30: Removal of existing exposed plumbing pipework. | D30: lot | E30: 1 | F30: 970 | G30: =IF(AND(ISNUMBER(E30),ISNUMBER(F30)),ROUND(E30*F30,2),"") -> 970
... A38: 02.20 | B38: Removal of existing entrance stairs | C38: Removal of the existing entrance stairs, including cutting, loading and removal of waste, ahead of the new floating steps. | D38: lot | E38: 1 | F38: 970 | G38: =IF(AND(ISNUMBER(E38),ISNUMBER(F38)),ROUND(E38*F38,2),"") -> 970
A39: 02.21 | B39: Removal of lawn and garden planting | C39: Removal of existing lawn, shrubs and garden planting in the development areas, including roots, loading and removal to a licensed site. | D39: m² | E39: 65 | F39: 11.5 | G39: =IF(AND(ISNUMBER(E39),ISNUMBER(F39)),ROUND(E39*F39,2),"") -> 747.5 | H39: Provisional quantity – remeasured
A40: Total – Chapter 2 | G40: =IF(COUNT(G19:G39)=0,"",SUM(G19:G39)) -> 38872.5
A42: Chapter 3 — Structural Works and Extensions
A43: 03.01 | B43: Enlargement of living-room balcony and new pergola | C43: Complete structural works per the structural engineer's drawings and specification. | D43: lot | E43: 1 | F43: 22600 | G43: =IF(AND(ISNUMBER(E43),ISNUMBER(F43)),ROUND(E43*F43,2),"") -> 22600 | H43: Lump sum – adjusted on receipt of structural drawings
A44: 03.02 | B44: New room addition on the gallery level | C44: Complete structural works for the room per structural and architectural drawings, including connections to the existing structure and openings. Finishes and services under their own chapters. | D44: lot | E44: 1 | F44: 38700 | G44: =IF(AND(ISNUMBER(E44),ISNUMBER(F44)),ROUND(E44*F44,2),"") -> 38700 | H44: Lump sum – adjusted on receipt of structural drawings
A45: 03.03 | B45: New entrance and staircase | C45: Complete works for the new entrance and staircase per the structural engineer. | D45: lot | E45: 1 | F45: 12300 | G45: =IF(AND(ISNUMBER(E45),ISNUMBER(F45)),ROUND(E45*F45,2),"") -> 12300 | H45: Lump sum – adjusted on receipt of structural drawings
A46: 03.04 | B46: Strengthening of existing internal staircase | C46: Strengthening per the structural engineer, after removal of the balustrade. | D46: lot | E46: 1 | F46: 5800 | G46: =IF(AND(ISNUMBER(E46),ISNUMBER(F46)),ROUND(E46*F46,2),"") -> 5800 | H46: Lump sum – adjusted on receipt of structural drawings
A47: 03.05 | B47: Floating entrance stairs | C47: 12 new floating (cantilevered) steps at the entrance replacing the existing stairs, approx. 1.15 m wide, including reinforcement, anchoring and preparation for cladding, per structural and architectural drawings. Cladding under item 13.08. | D47: pcs | E47: 12 | F47: 900 | G47: =IF(AND(ISNUMBER(E47),ISNUMBER(F47)),ROUND(E47*F47,2),"") -> 10800 | H47: Lump sum – adjusted on receipt of structural drawings; Final dimension per existing on site
A48: Total – Chapter 3 | G48: =IF(COUNT(G43:G47)=0,"",SUM(G43:G47)) -> 90200
A50: Chapter 4 — New Block Wall Partitions
A51: 04.01 | B51: New block walls (20 cm) – basement | C51: Block walls per drawings. | D51: m² | E51: 6.3 | F51: 97 | G51: =IF(AND(ISNUMBER(E51),ISNUMBER(F51)),ROUND(E51*F51,2),"") -> 611.1
...

Sheet Summary
A1: Summary of Quotation
A3: Chapter | B3: Amount | C3: % of total
A4: 1. Preparation and Site Establishment | B4: ='Quotation'!G16 -> 22816.5 | C4: =IF($B$17=0,0,B4/$B$17) -> 0.051692172
A5: 2. Demolition, Removals and Disposal | B5: ='Quotation'!G40 -> 38872.5 | C5: =IF($B$17=0,0,B5/$B$17) -> 0.08806802
A6: 3. Structural Works and Extensions | B6: ='Quotation'!G48 -> 90200 | C6: =IF($B$17=0,0,B6/$B$17) -> 0.2043536
A7: 4. New Block Wall Partitions | B7: ='Quotation'!G54 -> 2529.76 | C7: =IF($B$17=0,0,B7/$B$17) -> 0.0057313256
A8: 5. Plumbing, Sanitary Fixtures and Taps | B8: ='Quotation'!G90 -> 42750 | C8: =IF($B$17=0,0,B8/$B$17) -> 0.096852733
A9: 6. Electrical Works | B9: ='Quotation'!G104 -> 42063 | C9: =IF($B$17=0,0,B9/$B$17) -> 0.095296292
A10: 7. Lighting and Light Switches | B10: ='Quotation'!G126 -> 45055.5 | C10: =IF($B$17=0,0,B10/$B$17) -> 0.10207598
A11: 9. Gypsum Partitions and Ceilings | B11: ='Quotation'!G133 -> 10676.1 | C11: =IF($B$17=0,0,B11/$B$17) -> 0.024187356
A12: 10. Internal Waterproofing | B12: ='Quotation'!G139 -> 10306.5 | C12: =IF($B$17=0,0,B12/$B$17) -> 0.023350004
A13: 12. Window Sills and Sealing | B13: ='Quotation'!G145 -> 7154.42 | C13: =IF($B$17=0,0,B13/$B$17) -> 0.016208775
A14: 13. Flooring, Wall Tiling and Cladding | B14: ='Quotation'!G155 -> 66017.5 | C14: =IF($B$17=0,0,B14/$B$17) -> 0.14956667
A15: 14. Plaster, Skim Coat and Paint | B15: ='Quotation'!G161 -> 41220 | C15: =IF($B$17=0,0,B15/$B$17) -> 0.093386424
A16: 17. External Development | B16: ='Quotation'!G169 -> 21730 | C16: =IF($B$17=0,0,B16/$B$17) -> 0.04923064
A17: Total before VAT | B17: =SUM(B4:B16) -> 441391.78
A18: VAT (20%) | B18: ='Quotation'!G172 -> 88278.36
A19: TOTAL INCLUDING VAT | B19: =B17+B18 -> 529670.14

Sheet Terms & Exclusions
A1: # | B1: Terms & Exclusions
A2: 1 | B2: Basis | C2: The quotation is based on the Technical Specification Book (rev. 20, 06/07/2026), the architectural drawings "New Construction" – ground and first floor (17/09/2026) and the Contractor Quantity Schedule dated 24/09/2026. Where documents differ, the schedule of 24/09/2026 was used.
A3: 2 | B3: Quantities | C3: Quantities per the above documents. Items marked "provisional" or "per measurement on site" will be remeasured; the final account follows quantities actually executed.
A4: 3 | B4: Structure | C4: Chapter 3 (balcony and pergola, gallery room, entrance and stairs, strengthening of internal stairs) is a lump sum per the structural engineer's drawings; the price will be adjusted on receipt of the complete structural drawings.
A5: 4 | B5: Supply | C5: Sanitary ware and taps, light fittings, air-conditioning units, water heaters and floor and wall tiles are supplied by the Employer; the Contractor installs. Kitchen sinks are installed by the countertop supplier.
A6: 5 | B6: Exclusions | C6: Swimming pool; carpentry (kitchen, bathroom and wardrobe cabinets); aluminium windows and doors, interior and entrance doors, gates and shutters; parapet works; furniture; permits and fees; consultants' fees (structural, waterproofing, lighting); electricity company charges for the supply upgrade.
A7: 6 | B7: Tests | C7: Required tests and approvals (structural engineer, waterproofing consultant, certified electrical inspector, flood and pressure tests) are included.
A8: 7 | B8: Prices | C8: Prices in GBP, excluding VAT, price base October 2026, no indexation unless agreed otherwise.
A9: 8 | B9: Commercial terms | C9: Validity: [__ days] | Payment terms: [__] | Programme: [__]

Sheet Market survey (internal)
A1: Category | B1: Market data found (2026) | C1: Sources
A2: Plasterboard stud partition | B2: £30–£65/m²; acoustic / insulated £55–£100/m² | C2: trade2base.com/blog/stud-wall-costs-uk ; trade2base.com/blog/dry-lining-costs-uk ; fantasticservices.com/cost-guides/handyman/plastering/
A3: Large-format porcelain floor tiling (labour) | B3: £50–£80/m² (labour only); London/South East +20–30% | C3: trade2base.com/blog/tiling-pricing-guide-uk ; myjobquote.co.uk/questions/large-format-tile-installation-cost
A4: New socket point (electrician) | B4: £100–£250 per socket (new location) | C4: fantasticservices.com/cost-guides/electrical/socket-replacement/ ; myjobquote.co.uk/costs/new-plug-sockets
A5: Interior painting | B5: £14–£26/m² (prep, 2 coats, materials); skim coat adds £12–£20/m² | C5: bestbuilders.co.uk/costs/painting-cost-calculator ; trade2base.com/blog/painting-decorating-costs-uk
A6: Concrete path | B6: £60–£90/m² supplied and laid (2026) | C6: trade2base.com/blog/garden-path-costs-uk ; less.co.uk/home-improvements/driveways/concrete-cost
A7: Scaffolding | B7: ≈ £22.5/m² (one listing); typical house £1,500–£3,500 erected, hired, dismantled | C7: checkatrade.com (GU6 listing) ; lakeside-hire.co.uk ; less.co.uk/home-improvements/scaffolding/cost
A8: Exchange rate | B8: ≈ 4.10 ILS per GBP (9 Sep 2026 snapshot 4.0953; October values are forecasts only) | C8: longforecast.com/gbp-ils ; ofx.com
A10: Method: each unit rate = Israeli renovation-level base rate (ILS) × category multiplier ÷ exchange rate, then + 15% overheads and profit. Multipliers were calibrated on the anchors below (partition, tiling, electrical points, painting, concrete path, scaffolding); trades without an anchor use the average multiplier of the anchored ones. Calibration multipliers: part=0.62, tile=0.95, elec=1.86, paint=1.6, conc=0.77, scaf=1.69, gen=1.15. FX 4.1 ILS/GBP.
A11: Caveats: sources are mostly trade/lead-generation websites with wide, partly undated ranges; no official price book was used. The site is in Haifa, Israel – rates are UK market reference rates and were not adjusted for Israeli site conditions or logistics. English version assumes the UK market (GBP); confirm if another English-speaking market (e.g. USA/USD) is intended. All prices should be verified against supplier quotations before submission.
