Workbook

Sheet Quotation
A1: QUOTATION – Renovation and Extension, 53 Shlonsky St., Haifa
A2: Employer: Zohar Mor Yosef and Rami Dana | Contractor: [Contractor name] | Date: 08/10/2026 | Quotation no.: [__]
A3: All amounts in NIS (₪), excluding VAT, price base October 2026. Rates include contractor's overheads and profit.
A5: Item | B5: Description | C5: Scope | D5: Unit | E5: Qty | F5: Qty basis | G5: Rate (₪) | H5: Amount (₪) | I5: Remarks
A6: Chapter 1 — Preparation and Site Establishment
A7: 01.01 | B7: Site establishment | C7: Setting up work and storage areas, workers' facilities and access coordination. | D7: lot | E7: 1 | F7: Per documents | G7: 9200 | H7: =ROUND(E7*G7,2)
A8: 01.02 | B8: Site hoarding, signage and safety | C8: Temporary hoarding, site and hazard signage, and the safety measures required for the works. | D8: lot | E8: 1 | F8: Per documents | G8: 4600 | H8: =ROUND(E8*G8,2)
A9: 01.03 | B9: Temporary water connection | C9: Temporary water connection from the approved source, tested. | D9: lot | E9: 1 | F9: Per documents | G9: 1725 | H9: =ROUND(E9*G9,2)
A10: 01.04 | B10: Temporary electrical connection | C10: Temporary power connection by a licensed electrician, with protection and testing. | D10: lot | E10: 1 | F10: Per documents | G10: 3450 | H10: =ROUND(E10*G10,2)
A11: 01.05 | B11: Protection of existing elements | C11: Protective covers for floors, openings, windows, stairs, railings, walls and plants to be retained. | D11: lot | E11: 1 | F11: Per documents | G11: 5750 | H11: =ROUND(E11*G11,2)
A12: 01.06 | B12: Survey, verification and laser setting-out | C12: Survey of the existing building, verification against architectural and services drawings, setting-out of positions and levels. | D12: lot | E12: 1 | F12: Per documents | G12: 3450 | H12: =ROUND(E12*G12,2)
A13: 01.07 | B13: Waste skip and waste collection area | C13: Skip placement and a waste collection area; removal of waste to a licensed site. | D13: lot | E13: 1 | F13: Per documents | G13: 10350 | H13: =ROUND(E13*G13,2)
A14: 01.08 | B14: Ongoing site cleaning | C14: Periodic cleaning of work areas and passages throughout the works. | D14: lot | E14: 1 | F14: Per documents | G14: 10350 | H14: =ROUND(E14*G14,2)
A15: 01.09 | B15: External scaffolding | C15: Erection, rental for the works period, maintenance and removal of compliant external scaffolding around the facades, for sawing the decorative concrete frames, parapet works and facade plaster. | D15: m² | E15: 225 | F15: Provisional – remeasure | G15: 98 | H15: =ROUND(E15*G15,2)
A16: Total – Chapter 01 | H16: =SUM(H7:H15)
A18: Chapter 2 — Demolition, Removals and Disposal
A19: 02.01 | B19: Demolition of walls and partitions – basement | C19: Demolition of existing walls and partitions per demolition drawings. | D19: m² | E19: 62 | F19: Per documents | G19: 138 | H19: =ROUND(E19*G19,2)
A20: 02.02 | B20: Demolition of walls and partitions – ground floor | C20: Demolition of existing walls and partitions per demolition drawings. | D20: m² | E20: 51 | F20: Per documents | G20: 138 | H20: =ROUND(E20*G20,2)
A21: 02.03 | B21: Demolition of walls and partitions – first floor | C21: Demolition of existing walls and partitions per demolition drawings. | D21: m² | E21: 85 | F21: Per documents | G21: 138 | H21: =ROUND(E21*G21,2)
A22: 02.04 | B22: Removal of existing gypsum ceilings | C22: Removal of existing suspended gypsum ceilings. | D22: m² | E22: 10 | F22: Per documents | G22: 57 | H22: =ROUND(E22*G22,2)
A23: 02.05 | B23: Removal of existing flooring | C23: Removal of existing floor finishes. | D23: m² | E23: 40 | F23: Per documents | G23: 103 | H23: =ROUND(E23*G23,2)
A24: 02.06 | B24: Removal of existing kitchen cabinets | C24: Removal of existing kitchen cabinets, complete. | D24: lot | E24: 1 | F24: Per documents | G24: 2300 | H24: =ROUND(E24*G24,2)
A25: 02.07 | B25: Removal of other existing joinery | C25: Removal of other existing cabinets and joinery. | D25: pcs | E25: 1 | F25: Per documents | G25: 2875 | H25: =ROUND(E25*G25,2)
A26: 02.08 | B26: Removal of existing aluminium windows and shutters | C26: Complete removal of existing aluminium windows and roller shutters. | D26: lot | E26: 1 | F26: Per documents | G26: 6900 | H26: =ROUND(E26*G26,2)
A27: 02.09 | B27: Removal of interior and entrance doors and frames | C27: Complete removal of interior and entrance doors and frames. | D27: lot | E27: 1 | F27: Per documents | G27: 4025 | H27: =ROUND(E27*G27,2)
A28: 02.10 | B28: Removal of bathrooms, WCs and sanitary ware | C28: Complete removal of existing bathrooms, WCs and sanitary fixtures. | D28: lot | E28: 1 | F28: Per documents | G28: 9200 | H28: =ROUND(E28*G28,2)
A29: 02.11 | B29: Removal of electrical points, accessories and light fittings | C29: Removal of existing electrical points, accessories and light fittings. | D29: lot | E29: 1 | F29: Per documents | G29: 4600 | H29: =ROUND(E29*G29,2)
A30: 02.12 | B30: Removal of existing exposed plumbing | C30: Removal of existing exposed plumbing pipework. | D30: lot | E30: 1 | F30: Per documents | G30: 3450 | H30: =ROUND(E30*G30,2)
... A38: 02.20 | B38: Removal of granolithic flooring | C38: Removal of granolithic flooring in the parking area, entrance and paths. | D38: m² | E38: 100 | F38: Per documents | G38: 115 | H38: =ROUND(E38*G38,2)
A39: Total – Chapter 02 | H39: =SUM(H19:H38)
A41: Chapter 3 — Structural Works and Extensions
A42: 03.01 | B42: Enlargement of living-room balcony and new pergola | C42: Complete structural works per the structural engineer's drawings and specification. | D42: lot | E42: 1 | F42: Estimate – per engineer | G42: 80500 | H42: =ROUND(E42*G42,2) | I42: Provisional sum pending structural drawings
A43: 03.02 | B43: New room addition on the gallery level | C43: Complete structural works for the room addition per structural and architectural drawings, including connections to the existing structure and openings. Finishes and services under their own chapters. | D43: lot | E43: 1 | F43: Estimate – per engineer | G43: 138000 | H43: =ROUND(E43*G43,2) | I43: Provisional sum pending structural drawings
A44: 03.03 | B44: New entrance and staircase | C44: Complete works for the new entrance and staircase per the structural engineer. | D44: lot | E44: 1 | F44: Estimate – per engineer | G44: 43700 | H44: =ROUND(E44*G44,2) | I44: Provisional sum pending structural drawings
A45: 03.04 | B45: Strengthening of existing internal staircase | C45: Strengthening per the structural engineer, after removal of the balustrade. | D45: lot | E45: 1 | F45: Estimate – per engineer | G45: 20700 | H45: =ROUND(E45*G45,2) | I45: Provisional sum pending structural drawings
A46: Total – Chapter 03 | H46: =SUM(H42:H45)
A48: Chapter 4 — New Block Wall Partitions
A49: 04.01 | B49: New block walls (20 cm) – basement | C49: Block walls per drawings. | D49: m² | E49: 6.3 | F49: Per documents | G49: 345 | H49: =ROUND(E49*G49,2)
A50: 04.02 | B50: New block walls (20 cm) – ground floor | C50: Block walls per drawings. | D50: m² | E50: 17.7 | F50: Per documents | G50: 345 | H50: =ROUND(E50*G50,2)
A51: 04.03 | B51: New block walls (20 cm) – first floor and gallery | C51: Block walls per drawings. | D51: m² | E51: 2.08 | F51: Per documents | G51: 345 | H51: =ROUND(E51*G51,2)
...

Sheet Summary
A1: Summary of Quotation
A3: Chapter | B3: Amount (₪)
A4: 1. Preparation and Site Establishment | B4: =Quotation!H16
A5: 2. Demolition, Removals and Disposal | B5: =Quotation!H39
A6: 3. Structural Works and Extensions | B6: =Quotation!H46
A7: 4. New Block Wall Partitions | B7: =Quotation!H52
A8: 5. Plumbing, Sanitary Fixtures and Taps | B8: =Quotation!H88
A9: 6. Electrical Works | B9: =Quotation!H106
A10: 7. Lighting and Light Switches | B10: =Quotation!H129
A11: 8. Air Conditioning | B11: =Quotation!H136
A12: 9. Gypsum Partitions and Ceilings | B12: =Quotation!H143
A13: 10. Internal Waterproofing | B13: =Quotation!H150
A14: 11. Roof and Parapet Waterproofing | B14: =Quotation!H158
A15: 12. Window Sills and Door Thresholds | B15: =Quotation!H165
A16: 13. Flooring, Wall Tiling and Skirting | B16: =Quotation!H174
A17: 14. External Coloured Plaster | B17: =Quotation!H180
A18: 15. Plaster Repairs, Skim Coat and Internal Painting | B18: =Quotation!H186
A19: 16. Aluminium, Doors and Gates | B19: =Quotation!H197
A20: 17. External Development | B20: =Quotation!H204
A21: 18. Communications, Security, Intercom and Audio Infrastructure | B21: =Quotation!H212
A22: Total before discount | B22: =SUM(B4:B21)
A23: Discount | B23: =-ROUND(B22*C23,2) | C23: 0.25
A24: Total after discount, excl. VAT | B24: =B22+B23
A25: VAT | B25: =ROUND(B24*C25,2) | C25: 0.18
A26: TOTAL INCLUDING VAT | B26: =B24+B25

Sheet Notes & Exclusions
A1: # | B1: Type | C1: Note
A2: 1 | B2: Basis | C2: Quotation based on: Technical Specification Book rev. 20 (06/07/2026); architectural drawings "New Construction" – ground floor (sheet 13) and first floor (sheet 23), dated 17/09/2026; Contractor Quantity Schedule dated 24/09/2026; the Employer's bill of quantities. Where documents differ, the Quantity Schedule dated 24/09/2026 was used.
A3: 2 | B3: Quantities | C3: Items marked "Provisional – remeasure" have no quantity in the documents provided (air conditioning, switches, emergency lighting, water heaters, direct connections, communication points, roof/parapet, scaffolding). They are priced on estimated quantities and will be remeasured on site.
A4: 3 | B4: Structural | C4: Chapter 3 (balcony and pergola, gallery room, entrance and stairs, strengthening of internal stairs) is a provisional sum. The structural engineer's complete drawings were not provided; the price will be adjusted on receipt.
A5: 4 | B5: Supply | C5: Sanitary ware and taps, light fittings, air-conditioning units, water heaters, and floor / wall tiles are supplied by the Employer; the Contractor installs. Aluminium, doors, gates, shutters and stone sills are supplied and installed.
A6: 5 | B6: Exclusion | C6: Swimming pool (all works), carpentry (kitchen, bathroom and wardrobe cabinets), furniture, permits and fees, consultants' fees, and electricity company charges for the supply upgrade.
A7: 6 | B7: Exclusion | C7: Items that depend on the Employer's decisions: electric shutters (optional), garden plant types, final fixture models.
A8: 7 | B8: Tests | C8: Required tests and approvals (structural engineer, waterproofing consultant, certified electrical inspector, flood tests) are included as per the specification.
A9: 8 | B9: Commercial | C9: Validity: [__ days] | Payment terms: [__] | Price adjustment: [__]
A10: 9 | B10: Discount | C10: A discount of 25% on the total of the quotation is shown in the Summary sheet.

Sheet Programme
A1: Phase | B1: Start | C1: Finish
A2: Contract award and orders placed | B2: 46327 | C2: 46327
A3: Site establishment and approvals to demolish | B3: 46328 | C3: 46341
A4: Demolition and removals | B4: 46342 | C4: 46369
A5: Scaffolding erected / removed | B5: 46342 | C5: 46475
A6: Structural works and extensions | B6: 46370 | C6: 46420
A7: Roof and parapet | B7: 46370 | C7: 46405
A8: MEP rough-in and tests | B8: 46376 | C8: 46406
A9: Gypsum and waterproofing | B9: 46407 | C9: 46448
A10: Facade and external works | B10: 46421 | C10: 46484
A11: Interior finishes (tiling, plaster, paint, fittings) | B11: 46422 | C11: 46525
A12: Inspections, handover preparation | B12: 46526 | C12: 46546
A13: Handover | B13: 46546 | C13: 46546
A15: Indicative programme, working week Sunday–Thursday, start 01/11/2026. Excludes holidays and weather delays. Total duration approx. 31 weeks.
