Workbook

Sheet Programme
A1: PROGRAMME — Renovation and Extension, 53 Shlonsky St., Haifa (UK market assumptions)
A2: Start date (Monday): | D2: 46335 | F2: Durations are first-pass assumptions (working days, Mon–Fri) for a UK contractor. Holidays and shutdowns are taken from the Calendar sheet; change the start date or durations and all dates and the Gantt update.
A3: Weekend (Sat, Sun): | D3: 0000011
A5: ID | B5: Activity | C5: Quote items | D5: Dur. (wd) | E5: P1 | F5: P2 | G5: P3 | H5: P4 | I5: P5 | J5: P6 | K5: Pred. finish | L5: Start | M5: Finish | N5: Critical* | O5: By | Q5: =$D$2-WEEKDAY($D$2,2)+1+0 -> 46335 | R5: =$D$2-WEEKDAY($D$2,2)+1+7 -> 46342 | S5: =$D$2-WEEKDAY($D$2,2)+1+14 -> 46349 | T5: =$D$2-WEEKDAY($D$2,2)+1+21 -> 46356 | U5: =$D$2-WEEKDAY($D$2,2)+1+28 -> 46363 | V5: =$D$2-WEEKDAY($D$2,2)+1+35 -> 46370 | W5: =$D$2-WEEKDAY($D$2,2)+1+42 -> 46377 | X5: =$D$2-WEEKDAY($D$2,2)+1+49 -> 46384 | Y5: =$D$2-WEEKDAY($D$2,2)+1+56 -> 46391 | Z5: =$D$2-WEEKDAY($D$2,2)+1+63 -> 46398 | AA5: =$D$2-WEEKDAY($D$2,2)+1+70 -> 46405 | AB5: =$D$2-WEEKDAY($D$2,2)+1+77 -> 46412 | AC5: =$D$2-WEEKDAY($D$2,2)+1+84 -> 46419 | AD5: =$D$2-WEEKDAY($D$2,2)+1+91 -> 46426 | AE5: =$D$2-WEEKDAY($D$2,2)+1+98 -> 46433 | AF5: =$D$2-WEEKDAY($D$2,2)+1+105 -> 46440 | AG5: =$D$2-WEEKDAY($D$2,2)+1+112 -> 46447 | AH5: =$D$2-WEEKDAY($D$2,2)+1+119 -> 46454 | AI5: =$D$2-WEEKDAY($D$2,2)+1+126 -> 46461 | AJ5: =$D$2-WEEKDAY($D$2,2)+1+133 -> 46468 | AK5: =$D$2-WEEKDAY($D$2,2)+1+140 -> 46475 | AL5: =$D$2-WEEKDAY($D$2,2)+1+147 -> 46482 | AM5: =$D$2-WEEKDAY($D$2,2)+1+154 -> 46489 | AN5: =$D$2-WEEKDAY($D$2,2)+1+161 -> 46496 | AO5: =$D$2-WEEKDAY($D$2,2)+1+168 -> 46503 | AP5: =$D$2-WEEKDAY($D$2,2)+1+175 -> 46510 | AQ5: =$D$2-WEEKDAY($D$2,2)+1+182 -> 46517 | AR5: =$D$2-WEEKDAY($D$2,2)+1+189 -> 46524 | AS5: =$D$2-WEEKDAY($D$2,2)+1+196 -> 46531 | AT5: =$D$2-WEEKDAY($D$2,2)+1+203 -> 46538 | AU5: =$D$2-WEEKDAY($D$2,2)+1+210 -> 46545 | AV5: =$D$2-WEEKDAY($D$2,2)+1+217 -> 46552 | AW5: =$D$2-WEEKDAY($D$2,2)+1+224 -> 46559 | AX5: =$D$2-WEEKDAY($D$2,2)+1+231 -> 46566 | AY5: =$D$2-WEEKDAY($D$2,2)+1+238 -> 46573 | AZ5: =$D$2-WEEKDAY($D$2,2)+1+245 -> 46580 | BA5: =$D$2-WEEKDAY($D$2,2)+1+252 -> 46587 | BB5: =$D$2-WEEKDAY($D$2,2)+1+259 -> 46594 | BC5: =$D$2-WEEKDAY($D$2,2)+1+266 -> 46601 | BD5: =$D$2-WEEKDAY($D$2,2)+1+273 -> 46608 | BE5: =$D$2-WEEKDAY($D$2,2)+1+280 -> 46615 | BF5: =$D$2-WEEKDAY($D$2,2)+1+287 -> 46622 | BG5: =$D$2-WEEKDAY($D$2,2)+1+294 -> 46629 | BH5: =$D$2-WEEKDAY($D$2,2)+1+301 -> 46636 | BI5: =$D$2-WEEKDAY($D$2,2)+1+308 -> 46643 | BJ5: =$D$2-WEEKDAY($D$2,2)+1+315 -> 46650 | BK5: =$D$2-WEEKDAY($D$2,2)+1+322 -> 46657 | BL5: =$D$2-WEEKDAY($D$2,2)+1+329 -> 46664 | BM5: =$D$2-WEEKDAY($D$2,2)+1+336 -> 46671 | BN5: =$D$2-WEEKDAY($D$2,2)+1+343 -> 46678 | BO5: =$D$2-WEEKDAY($D$2,2)+1+350 -> 46685 | BP5: =$D$2-WEEKDAY($D$2,2)+1+357 -> 46692 | BQ5: =$D$2-WEEKDAY($D$2,2)+1+364 -> 46699 | BR5: =$D$2-WEEKDAY($D$2,2)+1+371 -> 46706 | BS5: =$D$2-WEEKDAY($D$2,2)+1+378 -> 46713 | BT5: =$D$2-WEEKDAY($D$2,2)+1+385 -> 46720 | BU5: =$D$2-WEEKDAY($D$2,2)+1+392 -> 46727 | BV5: =$D$2-WEEKDAY($D$2,2)+1+399 -> 46734 | BW5: =$D$2-WEEKDAY($D$2,2)+1+406 -> 46741 | BX5: =$D$2-WEEKDAY($D$2,2)+1+413 -> 46748 | BY5: =$D$2-WEEKDAY($D$2,2)+1+420 -> 46755 | BZ5: =$D$2-WEEKDAY($D$2,2)+1+427 -> 46762 | CA5: =$D$2-WEEKDAY($D$2,2)+1+434 -> 46769 | CB5: =$D$2-WEEKDAY($D$2,2)+1+441 -> 46776 | CC5: =$D$2-WEEKDAY($D$2,2)+1+448 -> 46783 | CD5: =$D$2-WEEKDAY($D$2,2)+1+455 -> 46790 | CE5: =$D$2-WEEKDAY($D$2,2)+1+462 -> 46797 | CF5: =$D$2-WEEKDAY($D$2,2)+1+469 -> 46804 | CG5: =$D$2-WEEKDAY($D$2,2)+1+476 -> 46811 | CH5: =$D$2-WEEKDAY($D$2,2)+1+483 -> 46818
B6: Non-working days in week | Q6: =COUNTIFS('Calendar'!$A$5:$A$17,">="&Q$5,'Calendar'!$A$5:$A$17,"<="&Q$5+4) -> 0 | R6: =COUNTIFS('Calendar'!$A$5:$A$17,">="&R$5,'Calendar'!$A$5:$A$17,"<="&R$5+4) -> 0 | S6: =COUNTIFS('Calendar'!$A$5:$A$17,">="&S$5,'Calendar'!$A$5:$A$17,"<="&S$5+4) -> 0 | T6: =COUNTIFS('Calendar'!$A$5:$A$17,">="&T$5,'Calendar'!$A$5:$A$17,"<="&T$5+4) -> 0 | U6: =COUNTIFS('Calendar'!$A$5:$A$17,">="&U$5,'Calendar'!$A$5:$A$17,"<="&U$5+4) -> 0 | V6: =COUNTIFS('Calendar'!$A$5:$A$17,">="&V$5,'Calendar'!$A$5:$A$17,"<="&V$5+4) -> 0 | W6: =COUNTIFS('Calendar'!$A$5:$A$17,">="&W$5,'Calendar'!$A$5:$A$17,"<="&W$5+4) -> 2 | X6: =COUNTIFS('Calendar'!$A$5:$A$17,">="&X$5,'Calendar'!$A$5:$A$17,"<="&X$5+4) -> 5 | ... CH6: =COUNTIFS('Calendar'!$A$5:$A$17,">="&CH$5,'Calendar'!$A$5:$A$17,"<="&CH$5+4) -> 0
A7: Contract, approvals and orders
A8: A010 | B8: Contract award and notice to proceed | C8: — | D8: 0 | K8: =MAX($D$2-1,IFERROR(INDEX($M$7:$M$76,MATCH(E8,$A$7:$A$76,0)),0),IFERROR(INDEX($M$7:$M$76,MATCH(F8,$A$7:$A$76,0)),0),IFERROR(INDEX($M$7:$M$76,MATCH(G8,$A$7:$A$76,0)),0),IFERROR(INDEX($M$7:$M$76,MATCH(H8,$A$7:$A$76,0)),0),IFERROR(INDEX($M$7:$M$76,MATCH(I8,$A$7:$A$76,0)),0),IFERROR(INDEX($M$7:$M$76,MATCH(J8,$A$7:$A$76,0)),0)) -> 46334 | L8: =IF(D8=0,IF(COUNTA(E8:J8)=0,$D$2,K8),WORKDAY.INTL(K8,1,$D$3,'Calendar'!$A$5:$A$17)) -> 46335 | M8: =IF(D8=0,L8,WORKDAY.INTL(L8,D8-1,$D$3,'Calendar'!$A$5:$A$17)) -> 46335 | N8: ● | O8: Contractor
A9: A020 | B9: Utility application – electricity supply upgrade and new service pillar (DNO) | C9: 06.07 | D9: 40 | E9: A010 | K9: =MAX($D$2-1,IFERROR(INDEX($M$7:$M$76,MATCH(E9,$A$7:$A$76,0)),0),IFERROR(INDEX($M$7:$M$76,MATCH(F9,$A$7:$A$76,0)),0),IFERROR(INDEX($M$7:$M$76,MATCH(G9,$A$7:$A$76,0)),0),IFERROR(INDEX($M$7:$M$76,MATCH(H9,$A$7:$A$76,0)),0),IFERROR(INDEX($M$7:$M$76,MATCH(I9,$A$7:$A$76,0)),0),IFERROR(INDEX($M$7:$M$76,MATCH(J9,$A$7:$A$76,0)),0)) -> 46335 | L9: =IF(D9=0,IF(COUNTA(E9:J9)=0,$D$2,K9),WORKDAY.INTL(K9,1,$D$3,'Calendar'!$A$5:$A$17)) -> 46336 | M9: =IF(D9=0,L9,WORKDAY.INTL(L9,D9-1,$D$3,'Calendar'!$A$5:$A$17)) -> 46401 | O9: Others / Employer
A10: A030 | B10: Approval of samples, materials and colours (plaster mock-up) | C10: 14.01 | D10: 10 | E10: A010 | K10: =MAX($D$2-1,IFERROR(INDEX($M$7:$M$76,MATCH(E10,$A$7:$A$76,0)),0),IFERROR(INDEX($M$7:$M$76,MATCH(F10,$A$7:$A$76,0)),0),IFERROR(INDEX($M$7:$M$76,MATCH(G10,$A$7:$A$76,0)),0),IFERROR(INDEX($M$7:$M$76,MATCH(H10,$A$7:$A$76,0)),0),IFERROR(INDEX($M$7:$M$76,MATCH(I10,$A$7:$A$76,0)),0),IFERROR(INDEX($M$7:$M$76,MATCH(J10,$A$7:$A$76,0)),0)) -> 46335 | L10: =IF(D10=0,IF(COUNTA(E10:J10)=0,$D$2,K10),WORKDAY.INTL(K10,1,$D$3,'Calendar'!$A$5:$A$17)) -> 46336 | M10: =IF(D10=0,L10,WORKDAY.INTL(L10,D10-1,$D$3,'Calendar'!$A$5:$A$17)) -> 46349 | O10: Contractor
A11: A050 | B11: Employer supply: order and deliver sanitary ware, taps and light fittings | C11: 05, 07 | D11: 20 | E11: A030 | K11: =MAX($D$2-1,IFERROR(INDEX($M$7:$M$76,MATCH(E11,$A$7:$A$76,0)),0),IFERROR(INDEX($M$7:$M$76,MATCH(F11,$A$7:$A$76,0)),0),IFERROR(INDEX($M$7:$M$76,MATCH(G11,$A$7:$A$76,0)),0),IFERROR(INDEX($M$7:$M$76,MATCH(H11,$A$7:$A$76,0)),0),IFERROR(INDEX($M$7:$M$76,MATCH(I11,$A$7:$A$76,0)),0),IFERROR(INDEX($M$7:$M$76,MATCH(J11,$A$7:$A$76,0)),0)) -> 46349 | L11: =IF(D11=0,IF(COUNTA(E11:J11)=0,$D$2,K11),WORKDAY.INTL(K11,1,$D$3,'Calendar'!$A$5:$A$17)) -> 46350 | M11: =IF(D11=0,L11,WORKDAY.INTL(L11,D11-1,$D$3,'Calendar'!$A$5:$A$17)) -> 46377 | O11: Others / Employer
A12: A055 | B12: Employer supply: order and deliver floor and wall tiles | C12: 13 | D12: 20 | E12: A030 | K12: =MAX($D$2-1,IFERROR(INDEX($M$7:$M$76,MATCH(E12,$A$7:$A$76,0)),0),IFERROR(INDEX($M$7:$M$76,MATCH(F12,$A$7:$A$76,0)),0),IFERROR(INDEX($M$7:$M$76,MATCH(G12,$A$7:$A$76,0)),0),IFERROR(INDEX($M$7:$M$76,MATCH(H12,$A$7:$A$76,0)),0),IFERROR(INDEX($M$7:$M$76,MATCH(I12,$A$7:$A$76,0)),0),IFERROR(INDEX($M$7:$M$76,MATCH(J12,$A$7:$A$76,0)),0)) -> 46349 | L12: =IF(D12=0,IF(COUNTA(E12:J12)=0,$D$2,K12),WORKDAY.INTL(K12,1,$D$3,'Calendar'!$A$5:$A$17)) -> 46350 | M12: =IF(D12=0,L12,WORKDAY.INTL(L12,D12-1,$D$3,'Calendar'!$A$5:$A$17)) -> 46377 | O12: Others / Employer
A13: Site set-up
A14: S010 | B14: Site set-up, hoarding, temporary water and power, skip | C14: 01.01–01.04, 01.07 | D14: 5 | E14: A010 | K14: =MAX($D$2-1,IFERROR(INDEX($M$7:$M$76,MATCH(E14,$A$7:$A$76,0)),0),IFERROR(INDEX($M$7:$M$76,MATCH(F14,$A$7:$A$76,0)),0),IFERROR(INDEX($M$7:$M$76,MATCH(G14,$A$7:$A$76,0)),0),IFERROR(INDEX($M$7:$M$76,MATCH(H14,$A$7:$A$76,0)),0),IFERROR(INDEX($M$7:$M$76,MATCH(I14,$A$7:$A$76,0)),0),IFERROR(INDEX($M$7:$M$76,MATCH(J14,$A$7:$A$76,0)),0)) -> 46335 | L14: =IF(D14=0,IF(COUNTA(E14:J14)=0,$D$2,K14),WORKDAY.INTL(K14,1,$D$3,'Calendar'!$A$5:$A$17)) -> 46336 | M14: =IF(D14=0,L14,WORKDAY.INTL(L14,D14-1,$D$3,'Calendar'!$A$5:$A$17)) -> 46342 | N14: ● | O14: Contractor
A15: S020 | B15: Protection of existing elements, survey and laser setting-out | C15: 01.05, 01.06 | D15: 4 | E15: S010 | K15: =MAX($D$2-1,IFERROR(INDEX($M$7:$M$76,MATCH(E15,$A$7:$A$76,0)),0),IFERROR(INDEX($M$7:$M$76,MATCH(F15,$A$7:$A$76,0)),0),IFERROR(INDEX($M$7:$M$76,MATCH(G15,$A$7:$A$76,0)),0),IFERROR(INDEX($M$7:$M$76,MATCH(H15,$A$7:$A$76,0)),0),IFERROR(INDEX($M$7:$M$76,MATCH(I15,$A$7:$A$76,0)),0),IFERROR(INDEX($M$7:$M$76,MATCH(J15,$A$7:$A$76,0)),0)) -> 46342 | L15: =IF(D15=0,IF(COUNTA(E15:J15)=0,$D$2,K15),WORKDAY.INTL(K15,1,$D$3,'Calendar'!$A$5:$A$17)) -> 46343 | M15: =IF(D15=0,L15,WORKDAY.INTL(L15,D15-1,$D$3,'Calendar'!$A$5:$A$17)) -> 46346 | N15: ● | O15: Contractor
A16: S030 | B16: Written approval to start demolition | C16: — | D16: 1 | E16: S020 | K16: =MAX($D$2-1,IFERROR(INDEX($M$7:$M$76,MATCH(E16,$A$7:$A$76,0)),0),IFERROR(INDEX($M$7:$M$76,MATCH(F16,$A$7:$A$76,0)),0),IFERROR(INDEX($M$7:$M$76,MATCH(G16,$A$7:$A$76,0)),0),IFERROR(INDEX($M$7:$M$76,MATCH(H16,$A$7:$A$76,0)),0),IFERROR(INDEX($M$7:$M$76,MATCH(I16,$A$7:$A$76,0)),0),IFERROR(INDEX($M$7:$M$76,MATCH(J16,$A$7:$A$76,0)),0)) -> 46346 | L16: =IF(D16=0,IF(COUNTA(E16:J16)=0,$D$2,K16),WORKDAY.INTL(K16,1,$D$3,'Calendar'!$A$5:$A$17)) -> 46349 | M16: =IF(D16=0,L16,WORKDAY.INTL(L16,D16-1,$D$3,'Calendar'!$A$5:$A$17)) -> 46349 | N16: ● | O16: Contractor
A17: Demolition and removals
A18: D010 | B18: Strip-out: windows, doors, sanitary ware, cabinets, A/C, electrics, exposed plumbing | C18: 02.06–02.13 | D18: 8 | E18: S030 | K18: =MAX($D$2-1,IFERROR(INDEX($M$7:$M$76,MATCH(E18,$A$7:$A$76,0)),0),IFERROR(INDEX($M$7:$M$76,MATCH(F18,$A$7:$A$76,0)),0),IFERROR(INDEX($M$7:$M$76,MATCH(G18,$A$7:$A$76,0)),0),IFERROR(INDEX($M$7:$M$76,MATCH(H18,$A$7:$A$76,0)),0),IFERROR(INDEX($M$7:$M$76,MATCH(I18,$A$7:$A$76,0)),0),IFERROR(INDEX($M$7:$M$76,MATCH(J18,$A$7:$A$76,0)),0)) -> 46349 | L18: =IF(D18=0,IF(COUNTA(E18:J18)=0,$D$2,K18),WORKDAY.INTL(K18,1,$D$3,'Calendar'!$A$5:$A$17)) -> 46350 | M18: =IF(D18=0,L18,WORKDAY.INTL(L18,D18-1,$D$3,'Calendar'!$A$5:$A$17)) -> 46359 | N18: ● | O18: Contractor
A19: D020 | B19: Demolition of walls and partitions – basement (62 m²) | C19: 02.01 | D19: 3 | E19: D010 | K19: =MAX($D$2-1,IFERROR(INDEX($M$7:$M$76,MATCH(E19,$A$7:$A$76,0)),0),IFERROR(INDEX($M$7:$M$76,MATCH(F19,$A$7:$A$76,0)),0),IFERROR(INDEX($M$7:$M$76,MATCH(G19,$A$7:$A$76,0)),0),IFERROR(INDEX($M$7:$M$76,MATCH(H19,$A$7:$A$76,0)),0),IFERROR(INDEX($M$7:$M$76,MATCH(I19,$A$7:$A$76,0)),0),IFERROR(INDEX($M$7:$M$76,MATCH(J19,$A$7:$A$76,0)),0)) -> 46359 | L19: =IF(D19=0,IF(COUNTA(E19:J19)=0,$D$2,K19),WORKDAY.INTL(K19,1,$D$3,'Calendar'!$A$5:$A$17)) -> 46360 | M19: =IF(D19=0,L19,WORKDAY.INTL(L19,D19-1,$D$3,'Calendar'!$A$5:$A$17)) -> 46364 | O19: Contractor
A20: D030 | B20: Demolition of walls and partitions – ground floor (51 m²) | C20: 02.02 | D20: 3 | E20: D010 | K20: =MAX($D$2-1,IFERROR(INDEX($M$7:$M$76,MATCH(E20,$A$7:$A$76,0)),0),IFERROR(INDEX($M$7:$M$76,MATCH(F20,$A$7:$A$76,0)),0),IFERROR(INDEX($M$7:$M$76,MATCH(G20,$A$7:$A$76,0)),0),IFERROR(INDEX($M$7:$M$76,MATCH(H20,$A$7:$A$76,0)),0),IFERROR(INDEX($M$7:$M$76,MATCH(I20,$A$7:$A$76,0)),0),IFERROR(INDEX($M$7:$M$76,MATCH(J20,$A$7:$A$76,0)),0)) -> 46359 | L20: =IF(D20=0,IF(COUNTA(E20:J20)=0,$D$2,K20),WORKDAY.INTL(K20,1,$D$3,'Calendar'!$A$5:$A$17)) -> 46360 | M20: =IF(D20=0,L20,WORKDAY.INTL(L20,D20-1,$D$3,'Calendar'!$A$5:$A$17)) -> 46364 | O20: Contractor
A21: D040 | B21: Demolition of walls and partitions – first floor (85 m²) | C21: 02.03 | D21: 4 | E21: D010 | K21: =MAX($D$2-1,IFERROR(INDEX($M$7:$M$76,MATCH(E21,$A$7:$A$76,0)),0),IFERROR(INDEX($M$7:$M$76,MATCH(F21,$A$7:$A$76,0)),0),IFERROR(INDEX($M$7:$M$76,MATCH(G21,$A$7:$A$76,0)),0),IFERROR(INDEX($M$7:$M$76,MATCH(H21,$A$7:$A$76,0)),0),IFERROR(INDEX($M$7:$M$76,MATCH(I21,$A$7:$A$76,0)),0),IFERROR(INDEX($M$7:$M$76,MATCH(J21,$A$7:$A$76,0)),0)) -> 46359 | L21: =IF(D21=0,IF(COUNTA(E21:J21)=0,$D$2,K21),WORKDAY.INTL(K21,1,$D$3,'Calendar'!$A$5:$A$17)) -> 46360 | M21: =IF(D21=0,L21,WORKDAY.INTL(L21,D21-1,$D$3,'Calendar'!$A$5:$A$17)) -> 46365 | O21: Contractor
A22: D050 | B22: Removal of ceilings, floors and wall panels | C22: 02.04, 02.05, 02.18 | D22: 6 | E22: D010 | K22: =MAX($D$2-1,IFERROR(INDEX($M$7:$M$76,MATCH(E22,$A$7:$A$76,0)),0),IFERROR(INDEX($M$7:$M$76,MATCH(F22,$A$7:$A$76,0)),0),IFERROR(INDEX($M$7:$M$76,MATCH(G22,$A$7:$A$76,0)),0),IFERROR(INDEX($M$7:$M$76,MATCH(H22,$A$7:$A$76,0)),0),IFERROR(INDEX($M$7:$M$76,MATCH(I22,$A$7:$A$76,0)),0),IFERROR(INDEX($M$7:$M$76,MATCH(J22,$A$7:$A$76,0)),0)) -> 46359 | L22: =IF(D22=0,IF(COUNTA(E22:J22)=0,$D$2,K22),WORKDAY.INTL(K22,1,$D$3,'Calendar'!$A$5:$A$17)) -> 46360 | M22: =IF(D22=0,L22,WORKDAY.INTL(L22,D22-1,$D$3,'Calendar'!$A$5:$A$17)) -> 46367 | N22: ● | O22: Contractor
A23: X010 | B23: Erect external scaffolding | C23: 01.09 | D23: 5 | E23: S030 | K23: =MAX($D$2-1,IFERROR(INDEX($M$7:$M$76,MATCH(E23,$A$7:$A$76,0)),0),IFERROR(INDEX($M$7:$M$76,MATCH(F23,$A$7:$A$76,0)),0),IFERROR(INDEX($M$7:$M$76,MATCH(G23,$A$7:$A$76,0)),0),IFERROR(INDEX($M$7:$M$76,MATCH(H23,$A$7:$A$76,0)),0),IFERROR(INDEX($M$7:$M$76,MATCH(I23,$A$7:$A$76,0)),0),IFERROR(INDEX($M$7:$M$76,MATCH(J23,$A$7:$A$76,0)),0)) -> 46349 | L23: =IF(D23=0,IF(COUNTA(E23:J23)=0,$D$2,K23),WORKDAY.INTL(K23,1,$D$3,'Calendar'!$A$5:$A$17)) -> 46350 | M23: =IF(D23=0,L23,WORKDAY.INTL(L23,D23-1,$D$3,'Calendar'!$A$5:$A$17)) -> 46356 | O23: Contractor
A24: D055 | B24: Sawing and removal of decorative concrete frames from scaffold | C24: 02.15 | D24: 6 | E24: X010 | F24: D010 | K24: =MAX($D$2-1,IFERROR(INDEX($M$7:$M$76,MATCH(E24,$A$7:$A$76,0)),0),IFERROR(INDEX($M$7:$M$76,MATCH(F24,$A$7:$A$76,0)),0),IFERROR(INDEX($M$7:$M$76,MATCH(G24,$A$7:$A$76,0)),0),IFERROR(INDEX($M$7:$M$76,MATCH(H24,$A$7:$A$76,0)),0),IFERROR(INDEX($M$7:$M$76,MATCH(I24,$A$7:$A$76,0)),0),IFERROR(INDEX($M$7:$M$76,MATCH(J24,$A$7:$A$76,0)),0)) -> 46359 | L24: =IF(D24=0,IF(COUNTA(E24:J24)=0,$D$2,K24),WORKDAY.INTL(K24,1,$D$3,'Calendar'!$A$5:$A$17)) -> 46360 | M24: =IF(D24=0,L24,WORKDAY.INTL(L24,D24-1,$D$3,'Calendar'!$A$5:$A$17)) -> 46367 | N24: ● | O24: Contractor
A25: D060 | B25: Removal of granolithic flooring, old entrance stairs and garden planting | C25: 02.19–02.21 | D25: 8 | E25: S030 | K25: =MAX($D$2-1,IFERROR(INDEX($M$7:$M$76,MATCH(E25,$A$7:$A$76,0)),0),IFERROR(INDEX($M$7:$M$76,MATCH(F25,$A$7:$A$76,0)),0),IFERROR(INDEX($M$7:$M$76,MATCH(G25,$A$7:$A$76,0)),0),IFERROR(INDEX($M$7:$M$76,MATCH(H25,$A$7:$A$76,0)),0),IFERROR(INDEX($M$7:$M$76,MATCH(I25,$A$7:$A$76,0)),0),IFERROR(INDEX($M$7:$M$76,MATCH(J25,$A$7:$A$76,0)),0)) -> 46349 | L25: =IF(D25=0,IF(COUNTA(E25:J25)=0,$D$2,K25),WORKDAY.INTL(K25,1,$D$3,'Calendar'!$A$5:$A$17)) -> 46350 | M25: =IF(D25=0,L25,WORKDAY.INTL(L25,D25-1,$D$3,'Calendar'!$A$5:$A$17)) -> 46359 | O25: Contractor
A26: D065 | B26: Waste removal and thorough cleaning | C26: 02.16, 02.17 | D26: 4 | E26: D020 | F26: D030 | G26: D040 | H26: D050 | I26: D055 | J26: D060 | K26: =MAX($D$2-1,IFERROR(INDEX($M$7:$M$76,MATCH(E26,$A$7:$A$76,0)),0),IFERROR(INDEX($M$7:$M$76,MATCH(F26,$A$7:$A$76,0)),0),IFERROR(INDEX($M$7:$M$76,MATCH(G26,$A$7:$A$76,0)),0),IFERROR(INDEX($M$7:$M$76,MATCH(H26,$A$7:$A$76,0)),0),IFERROR(INDEX($M$7:$M$76,MATCH(I26,$A$7:$A$76,0)),0),IFERROR(INDEX($M$7:$M$76,MATCH(J26,$A$7:$A$76,0)),0)) -> 46367 | L26: =IF(D26=0,IF(COUNTA(E26:J26)=0,$D$2,K26),WORKDAY.INTL(K26,1,$D$3,'Calendar'!$A$5:$A$17)) -> 46370 | M26: =IF(D26=0,L26,WORKDAY.INTL(L26,D26-1,$D$3,'Calendar'!$A$5:$A$17)) -> 46373 | N26: ● | O26: Contractor
A27: D070 | B27: Structural engineer and designer approval to start building | C27: — | D27: 2 | E27: D065 | K27: =MAX($D$2-1,IFERROR(INDEX($M$7:$M$76,MATCH(E27,$A$7:$A$76,0)),0),IFERROR(INDEX($M$7:$M$76,MATCH(F27,$A$7:$A$76,0)),0),IFERROR(INDEX($M$7:$M$76,MATCH(G27,$A$7:$A$76,0)),0),IFERROR(INDEX($M$7:$M$76,MATCH(H27,$A$7:$A$76,0)),0),IFERROR(INDEX($M$7:$M$76,MATCH(I27,$A$7:$A$76,0)),0),IFERROR(INDEX($M$7:$M$76,MATCH(J27,$A$7:$A$76,0)),0)) -> 46373 | L27: =IF(D27=0,IF(COUNTA(E27:J27)=0,$D$2,K27),WORKDAY.INTL(K27,1,$D$3,'Calendar'!$A$5:$A$17)) -> 46374 | M27: =IF(D27=0,L27,WORKDAY.INTL(L27,D27-1,$D$3,'Calendar'!$A$5:$A$17)) -> 46377 | N27: ● | O27: Contractor
A28: Structure and extensions
A29: K010 | B29: Strengthening of the existing internal staircase | C29: 03.04 | D29: 10 | E29: D070 | K29: =MAX($D$2-1,IFERROR(INDEX($M$7:$M$76,MATCH(E29,$A$7:$A$76,0)),0),IFERROR(INDEX($M$7:$M$76,MATCH(F29,$A$7:$A$76,0)),0),IFERROR(INDEX($M$7:$M$76,MATCH(G29,$A$7:$A$76,0)),0),IFERROR(INDEX($M$7:$M$76,MATCH(H29,$A$7:$A$76,0)),0),IFERROR(INDEX($M$7:$M$76,MATCH(I29,$A$7:$A$76,0)),0),IFERROR(INDEX($M$7:$M$76,MATCH(J29,$A$7:$A$76,0)),0)) -> 46377 | L29: =IF(D29=0,IF(COUNTA(E29:J29)=0,$D$2,K29),WORKDAY.INTL(K29,1,$D$3,'Calendar'!$A$5:$A$17)) -> 46378 | M29: =IF(D29=0,L29,WORKDAY.INTL(L29,D29-1,$D$3,'Calendar'!$A$5:$A$17)) -> 46401 | O29: Contractor
A30: K020 | B30: New entrance and staircase structure | C30: 03.03 | D30: 15 | E30: D070 | K30: =MAX($D$2-1,IFERROR(INDEX($M$7:$M$76,MATCH(E30,$A$7:$A$76,0)),0),IFERROR(INDEX($M$7:$M$76,MATCH(F30,$A$7:$A$76,0)),0),IFERROR(INDEX($M$7:$M$76,MATCH(G30,$A$7:$A$76,0)),0),IFERROR(INDEX($M$7:$M$76,MATCH(H30,$A$7:$A$76,0)),0),IFERROR(INDEX($M$7:$M$76,MATCH(I30,$A$7:$A$76,0)),0),IFERROR(INDEX($M$7:$M$76,MATCH(J30,$A$7:$A$76,0)),0)) -> 46377 | L30: =IF(D30=0,IF(COUNTA(E30:J30)=0,$D$2,K30),WORKDAY.INTL(K30,1,$D$3,'Calendar'!$A$5:$A$17)) -> 46378 | M30: =IF(D30=0,L30,WORKDAY.INTL(L30,D30-1,$D$3,'Calendar'!$A$5:$A$17)) -> 46408 | O30: Contractor
A31: K025 | B31: Floating entrance steps (12 steps) | C31: 03.05 | D31: 8 | E31: K020 | K31: =MAX($D$2-1,IFERROR(INDEX($M$7:$M$76,MATCH(E31,$A$7:$A$76,0)),0),IFERROR(INDEX($M$7:$M$76,MATCH(F31,$A$7:$A$76,0)),0),IFERROR(INDEX($M$7:$M$76,MATCH(G31,$A$7:$A$76,0)),0),IFERROR(INDEX($M$7:$M$76,MATCH(H31,$A$7:$A$76,0)),0),IFERROR(INDEX($M$7:$M$76,MATCH(I31,$A$7:$A$76,0)),0),IFERROR(INDEX($M$7:$M$76,MATCH(J31,$A$7:$A$76,0)),0)) -> 46408 | L31: =IF(D31=0,IF(COUNTA(E31:J31)=0,$D$2,K31),WORKDAY.INTL(K31,1,$D$3,'Calendar'!$A$5:$A$17)) -> 46409 | M31: =IF(D31=0,L31,WORKDAY.INTL(L31,D31-1,$D$3,'Calendar'!$A$5:$A$17)) -> 46420 | O31: Contractor
A32: K030 | B32: Balcony enlargement and pergola | C32: 03.01 | D32: 30 | E32: D070 | K32: =MAX($D$2-1,IFERROR(INDEX($M$7:$M$76,MATCH(E32,$A$7:$A$76,0)),0),IFERROR(INDEX($M$7:$M$76,MATCH(F32,$A$7:$A$76,0)),0),IFERROR(INDEX($M$7:$M$76,MATCH(G32,$A$7:$A$76,0)),0),IFERROR(INDEX($M$7:$M$76,MATCH(H32,$A$7:$A$76,0)),0),IFERROR(INDEX($M$7:$M$76,MATCH(I32,$A$7:$A$76,0)),0),IFERROR(INDEX($M$7:$M$76,MATCH(J32,$A$7:$A$76,0)),0)) -> 46377 | L32: =IF(D32=0,IF(COUNTA(E32:J32)=0,$D$2,K32),WORKDAY.INTL(K32,1,$D$3,'Calendar'!$A$5:$A$17)) -> 46378 | M32: =IF(D32=0,L32,WORKDAY.INTL(L32,D32-1,$D$3,'Calendar'!$A$5:$A$17)) -> 46429 | O32: Contractor
A33: K040 | B33: Gallery-level room addition | C33: 03.02 | D33: 35 | E33: D070 | K33: =MAX($D$2-1,IFERROR(INDEX($M$7:$M$76,MATCH(E33,$A$7:$A$76,0)),0),IFERROR(INDEX($M$7:$M$76,MATCH(F33,$A$7:$A$76,0)),0),IFERROR(INDEX($M$7:$M$76,MATCH(G33,$A$7:$A$76,0)),0),IFERROR(INDEX($M$7:$M$76,MATCH(H33,$A$7:$A$76,0)),0),IFERROR(INDEX($M$7:$M$76,MATCH(I33,$A$7:$A$76,0)),0),IFERROR(INDEX($M$7:$M$76,MATCH(J33,$A$7:$A$76,0)),0)) -> 46377 | L33: =IF(D33=0,IF(COUNTA(E33:J33)=0,$D$2,K33),WORKDAY.INTL(K33,1,$D$3,'Calendar'!$A$5:$A$17)) -> 46378 | M33: =IF(D33=0,L33,WORKDAY.INTL(L33,D33-1,$D$3,'Calendar'!$A$5:$A$17)) -> 46436 | N33: ● | O33: Contractor
A34: K050 | B34: Structural engineer sign-off: structure complete | C34: — | D34: 2 | E34: K010 | F34: K020 | G34: K025 | H34: K030 | I34: K040 | K34: =MAX($D$2-1,IFERROR(INDEX($M$7:$M$76,MATCH(E34,$A$7:$A$76,0)),0),IFERROR(INDEX($M$7:$M$76,MATCH(F34,$A$7:$A$76,0)),0),IFERROR(INDEX($M$7:$M$76,MATCH(G34,$A$7:$A$76,0)),0),IFERROR(INDEX($M$7:$M$76,MATCH(H34,$A$7:$A$76,0)),0),IFERROR(INDEX($M$7:$M$76,MATCH(I34,$A$7:$A$76,0)),0),IFERROR(INDEX($M$7:$M$76,MATCH(J34,$A$7:$A$76,0)),0)) -> 46436 | L34: =IF(D34=0,IF(COUNTA(E34:J34)=0,$D$2,K34),WORKDAY.INTL(K34,1,$D$3,'Calendar'!$A$5:$A$17)) -> 46437 | M34: =IF(D34=0,L34,WORKDAY.INTL(L34,D34-1,$D$3,'Calendar'!$A$5:$A$17)) -> 46440 | N34: ● | O34: Contractor
A35: Concealed services
A36: B010 | B36: New block walls (26 m²) | C36: 04.01–04.03 | D36: 4 | E36: D070 | K36: =MAX($D$2-1,IFERROR(INDEX($M$7:$M$76,MATCH(E36,$A$7:$A$76,0)),0),IFERROR(INDEX($M$7:$M$76,MATCH(F36,$A$7:$A$76,0)),0),IFERROR(INDEX($M$7:$M$76,MATCH(G36,$A$7:$A$76,0)),0),IFERROR(INDEX($M$7:$M$76,MATCH(H36,$A$7:$A$76,0)),0),IFERROR(INDEX($M$7:$M$76,MATCH(I36,$A$7:$A$76,0)),0),IFERROR(INDEX($M$7:$M$76,MATCH(J36,$A$7:$A$76,0)),0)) -> 46377 | L36: =IF(D36=0,IF(COUNTA(E36:J36)=0,$D$2,K36),WORKDAY.INTL(K36,1,$D$3,'Calendar'!$A$5:$A$17)) -> 46378 | M36: =IF(D36=0,L36,WORKDAY.INTL(L36,D36-1,$D$3,'Calendar'!$A$5:$A$17)) -> 46393 | O36: Contractor
A37: P010 | B37: Plumbing first fix: points, main supply and drainage | C37: 05.25–05.33 | D37: 20 | E37: D070 | F37: B010 | K37: =MAX($D$2-1,IFERROR(INDEX($M$7:$M$76,MATCH(E37,$A$7:$A$76,0)),0),IFERROR(INDEX($M$7:$M$76,MATCH(F37,$A$7:$A$76,0)),0),IFERROR(INDEX($M$7:$M$76,MATCH(G37,$A$7:$A$76,0)),0),IFERROR(INDEX($M$7:$M$76,MATCH(H37,$A$7:$A$76,0)),0),IFERROR(INDEX($M$7:$M$76,MATCH(I37,$A$7:$A$76,0)),0),IFERROR(INDEX($M$7:$M$76,MATCH(J37,$A$7:$A$76,0)),0)) -> 46393 | L37: =IF(D37=0,IF(COUNTA(E37:J37)=0,$D$2,K37),WORKDAY.INTL(K37,1,$D$3,'Calendar'!$A$5:$A$17)) -> 46394 | M37: =IF(D37=0,L37,WORKDAY.INTL(L37,D37-1,$D$3,'Calendar'!$A$5:$A$17)) -> 46421 | O37: Contractor
A38: E010 | B38: Electrical first fix: conduits, points and board extension | C38: 06.01–06.06, 06.10, 06.11, 07.11, 07.20 | D38: 20 | E38: D070 | F38: B010 | K38: =MAX($D$2-1,IFERROR(INDEX($M$7:$M$76,MATCH(E38,$A$7:$A$76,0)),0),IFERROR(INDEX($M$7:$M$76,MATCH(F38,$A$7:$A$76,0)),0),IFERROR(INDEX($M$7:$M$76,MATCH(G38,$A$7:$A$76,0)),0),IFERROR(INDEX($M$7:$M$76,MATCH(H38,$A$7:$A$76,0)),0),IFERROR(INDEX($M$7:$M$76,MATCH(I38,$A$7:$A$76,0)),0),IFERROR(INDEX($M$7:$M$76,MATCH(J38,$A$7:$A$76,0)),0)) -> 46393 | L38: =IF(D38=0,IF(COUNTA(E38:J38)=0,$D$2,K38),WORKDAY.INTL(K38,1,$D$3,'Calendar'!$A$5:$A$17)) -> 46394 | M38: =IF(D38=0,L38,WORKDAY.INTL(L38,D38-1,$D$3,'Calendar'!$A$5:$A$17)) -> 46421 | O38: Contractor
A39: Q010 | B39: Plumbing pressure and leak tests, designer sign-off | C39: 05.35 | D39: 3 | E39: P010 | K39: =MAX($D$2-1,IFERROR(INDEX($M$7:$M$76,MATCH(E39,$A$7:$A$76,0)),0),IFERROR(INDEX($M$7:$M$76,MATCH(F39,$A$7:$A$76,0)),0),IFERROR(INDEX($M$7:$M$76,MATCH(G39,$A$7:$A$76,0)),0),IFERROR(INDEX($M$7:$M$76,MATCH(H39,$A$7:$A$76,0)),0),IFERROR(INDEX($M$7:$M$76,MATCH(I39,$A$7:$A$76,0)),0),IFERROR(INDEX($M$7:$M$76,MATCH(J39,$A$7:$A$76,0)),0)) -> 46421 | L39: =IF(D39=0,IF(COUNTA(E39:J39)=0,$D$2,K39),WORKDAY.INTL(K39,1,$D$3,'Calendar'!$A$5:$A$17)) -> 46422 | M39: =IF(D39=0,L39,WORKDAY.INTL(L39,D39-1,$D$3,'Calendar'!$A$5:$A$17)) -> 46426 | O39: Contractor
A40: Q020 | B40: Electrical first-fix inspection (earthing and RCD tests) | C40: 06.09 | D40: 3 | E40: E010 | K40: =MAX($D$2-1,IFERROR(INDEX($M$7:$M$76,MATCH(E40,$A$7:$A$76,0)),0),IFERROR(INDEX($M$7:$M$76,MATCH(F40,$A$7:$A$76,0)),0),IFERROR(INDEX($M$7:$M$76,MATCH(G40,$A$7:$A$76,0)),0),IFERROR(INDEX($M$7:$M$76,MATCH(H40,$A$7:$A$76,0)),0),IFERROR(INDEX($M$7:$M$76,MATCH(I40,$A$7:$A$76,0)),0),IFERROR(INDEX($M$7:$M$76,MATCH(J40,$A$7:$A$76,0)),0)) -> 46421 | L40: =IF(D40=0,IF(COUNTA(E40:J40)=0,$D$2,K40),WORKDAY.INTL(K40,1,$D$3,'Calendar'!$A$5:$A$17)) -> 46422 | M40: =IF(D40=0,L40,WORKDAY.INTL(L40,D40-1,$D$3,'Calendar'!$A$5:$A$17)) -> 46426 | O40: Contractor
A41: Gypsum and waterproofing
...

Sheet Calendar
A1: Calendar and non-working days
A2: Sources: UK bank holidays (Central Bedfordshire Council / gov.uk list), BOE calendar 2027 (Garrigues), French legal holidays (Code du travail L.3133-1); verify against official lists.
A4: Date | B4: Holiday / closure | C4: Type | D4: Day
A5: 46380 | B5: Construction Christmas shutdown | C5: Industry custom (assumption) | D5: Thu
A6: 46381 | B6: Christmas Day | C6: Bank holiday (England & Wales) | D6: Fri
A7: 46384 | B7: Boxing Day (substitute day) | C7: Bank holiday (England & Wales) | D7: Mon
A8: 46385 | B8: Construction Christmas shutdown | C8: Industry custom (assumption) | D8: Tue
A9: 46386 | B9: Construction Christmas shutdown | C9: Industry custom (assumption) | D9: Wed
A10: 46387 | B10: Construction Christmas shutdown | C10: Industry custom (assumption) | D10: Thu
A11: 46388 | B11: New Year's Day | C11: Bank holiday (England & Wales) | D11: Fri
A12: 46391 | B12: Construction Christmas shutdown | C12: Industry custom (assumption) | D12: Mon
A13: 46472 | B13: Good Friday | C13: Bank holiday (England & Wales) | D13: Fri
A14: 46475 | B14: Easter Monday | C14: Bank holiday (England & Wales) | D14: Mon
A15: 46510 | B15: Early May bank holiday | C15: Bank holiday (England & Wales) | D15: Mon
A16: 46538 | B16: Spring bank holiday | C16: Bank holiday (England & Wales) | D16: Mon
A17: 46629 | B17: Summer bank holiday | C17: Bank holiday (England & Wales) | D17: Mon

Sheet Local practice
A1: Local-market assumptions
A3: 1 | B3: Working week Monday–Friday, 8 h/day; Saturdays are not scheduled.
A4: 2 | B4: Public holidays: England and Wales bank holidays (verified for 2026–2027: Christmas Day 25/12/2026, Boxing Day substitute 28/12/2026, New Year 01/01/2027, Good Friday 26/03/2027, Easter Monday 29/03/2027, Early May 03/05/2027, Spring 31/05/2027, Summer 30/08/2027). Scotland and Northern Ireland differ – adjust if the site is there.
A5: 3 | B5: Construction industry Christmas shutdown assumed 24 Dec 2026 – 4 Jan 2027 (industry custom; confirm with subcontractors).
A6: 4 | B6: Winter weather: durations of external activities are increased by 20% for the November–March season (scaffold, facade, paths, earthworks, landscaping, balcony works).
A7: 5 | B7: Planning permission and Building Regulations approval are assumed obtained before the start (householder planning decisions are statutory 8 weeks); Building Control stage inspections and the completion certificate are part of the handover.
A8: 6 | B8: Electrical work is certified at completion with an Electrical Installation Certificate (Part P / Building Control notification).
A9: 7 | B9: DNO supply upgrade lead time is assumed 40 working days and runs in parallel; it is outside the contractor's control.
A10: 8 | B10: Employer-supplied items (sanitary ware, taps, lights, tiles): 20 working days order-to-delivery assumed.
A11: 9 | B11: Aluminium windows and doors are by others (outside this quotation): 40 working days after demolition approval assumed; facade plaster, sills and sealing depend on them.
A12: 10 | B12: Scope follows the UK quotation (no pool, no parapet/roof works, no carpentry). All durations are assumptions to be confirmed with the site manager and subcontractors.
