Workbook

Sheet Presupuesto
A1: PRESUPUESTO — Reforma y ampliación, calle Shlonsky 53, Haifa
A2: Propiedad: Zohar Mor Yosef y Rami Dana | Contratista: [Nombre del contratista] | Fecha: 14/10/2026 | Presupuesto n.º: [__]
A3: Todos los importes en EUR (€), sin IVA, base de precios octubre 2026. Los precios unitarios incluyen gastos generales y beneficio del contratista (15 %).
A5: Partida | B5: Designación | C5: Descripción | D5: Unidad | E5: Cant. | F5: Precio unitario | G5: Importe | H5: Observaciones
A6: Capítulo 1 — Preparación e instalación de obra
A7: 01.01 | B7: Instalación de obra | C7: Habilitación de zonas de trabajo y acopio, instalaciones para operarios y coordinación de accesos. | D7: global | E7: 1 | F7: 1420 | G7: =IF(AND(ISNUMBER(E7),ISNUMBER(F7)),ROUND(E7*F7,2),"") -> 1420
A8: 01.02 | B8: Vallado, señalización y seguridad de obra | C8: Vallado provisional, carteles de obra y de peligro y medidas de seguridad necesarias durante la obra. | D8: global | E8: 1 | F8: 710 | G8: =IF(AND(ISNUMBER(E8),ISNUMBER(F8)),ROUND(E8*F8,2),"") -> 710
A9: 01.03 | B9: Acometida provisional de agua | C9: Acometida provisional de agua desde el punto autorizado, con comprobación. | D9: global | E9: 1 | F9: 266 | G9: =IF(AND(ISNUMBER(E9),ISNUMBER(F9)),ROUND(E9*F9,2),"") -> 266
A10: 01.04 | B10: Acometida eléctrica provisional | C10: Acometida eléctrica provisional realizada por electricista autorizado, con protecciones y comprobación. | D10: global | E10: 1 | F10: 530 | G10: =IF(AND(ISNUMBER(E10),ISNUMBER(F10)),ROUND(E10*F10,2),"") -> 530
A11: 01.05 | B11: Protección de elementos existentes | C11: Protecciones de suelos, huecos, ventanas, escaleras, barandillas, paredes y plantas que se conservan. | D11: global | E11: 1 | F11: 890 | G11: =IF(AND(ISNUMBER(E11),ISNUMBER(F11)),ROUND(E11*F11,2),"") -> 890
A12: 01.06 | B12: Replanteo, verificación y marcado láser | C12: Medición del edificio existente, verificación con los planos de arquitectura e instalaciones y replanteo de posiciones y niveles. | D12: global | E12: 1 | F12: 530 | G12: =IF(AND(ISNUMBER(E12),ISNUMBER(F12)),ROUND(E12*F12,2),"") -> 530
A13: 01.07 | B13: Contenedor de residuos y zona de acopio | C13: Colocación de contenedor y zona de acopio; retirada de residuos a vertedero autorizado. | D13: global | E13: 1 | F13: 1600 | G13: =IF(AND(ISNUMBER(E13),ISNUMBER(F13)),ROUND(E13*F13,2),"") -> 1600
A14: 01.08 | B14: Limpieza periódica de obra | C14: Limpieza periódica de las zonas de trabajo y de paso durante toda la obra. | D14: global | E14: 1 | F14: 1600 | G14: =IF(AND(ISNUMBER(E14),ISNUMBER(F14)),ROUND(E14*F14,2),"") -> 1600
A15: 01.09 | B15: Andamio exterior | C15: Montaje, alquiler durante la obra (unos 4,5 meses), mantenimiento y desmontaje de andamio exterior homologado alrededor de las fachadas, para el corte de los marcos de hormigón decorativos y los trabajos de revoco de fachada. | D15: m² | E15: 225 | F15: 32 | G15: =IF(AND(ISNUMBER(E15),ISNUMBER(F15)),ROUND(E15*F15,2),"") -> 7200 | H15: Cantidad provisional – se medirá en obra
A16: Total – Capítulo 1 | G16: =IF(COUNT(G7:G15)=0,"",SUM(G7:G15)) -> 14746
A18: Capítulo 2 — Demoliciones, desmontajes y retirada de residuos
A19: 02.01 | B19: Demolición de muros y tabiques – sótano | C19: Demolición de muros y tabiques existentes según planos de demolición. | D19: m² | E19: 62 | F19: 21.5 | G19: =IF(AND(ISNUMBER(E19),ISNUMBER(F19)),ROUND(E19*F19,2),"") -> 1333
A20: 02.02 | B20: Demolición de muros y tabiques – planta baja | C20: Demolición de muros y tabiques existentes según planos de demolición. | D20: m² | E20: 51 | F20: 21.5 | G20: =IF(AND(ISNUMBER(E20),ISNUMBER(F20)),ROUND(E20*F20,2),"") -> 1096.5
A21: 02.03 | B21: Demolición de muros y tabiques – primera planta | C21: Demolición de muros y tabiques existentes según planos de demolición. | D21: m² | E21: 85 | F21: 21.5 | G21: =IF(AND(ISNUMBER(E21),ISNUMBER(F21)),ROUND(E21*F21,2),"") -> 1827.5
A22: 02.04 | B22: Desmontaje de falsos techos de yeso laminado | C22: Desmontaje de los falsos techos de yeso laminado existentes. | D22: m² | E22: 10 | F22: 8.9 | G22: =IF(AND(ISNUMBER(E22),ISNUMBER(F22)),ROUND(E22*F22,2),"") -> 89
A23: 02.05 | B23: Levantado de pavimentos existentes | C23: Levantado de los pavimentos existentes. | D23: m² | E23: 40 | F23: 16 | G23: =IF(AND(ISNUMBER(E23),ISNUMBER(F23)),ROUND(E23*F23,2),"") -> 640
A24: 02.06 | B24: Desmontaje de muebles de cocina existentes | C24: Desmontaje completo de los muebles de cocina existentes. | D24: global | E24: 1 | F24: 355 | G24: =IF(AND(ISNUMBER(E24),ISNUMBER(F24)),ROUND(E24*F24,2),"") -> 355
A25: 02.07 | B25: Desmontaje de otros armarios y carpintería | C25: Desmontaje de otros armarios y elementos de carpintería existentes. | D25: ud | E25: 1 | F25: 444 | G25: =IF(AND(ISNUMBER(E25),ISNUMBER(F25)),ROUND(E25*F25,2),"") -> 444
A26: 02.08 | B26: Desmontaje de ventanas de aluminio y persianas existentes | C26: Desmontaje completo de las ventanas de aluminio y persianas existentes. | D26: global | E26: 1 | F26: 1060 | G26: =IF(AND(ISNUMBER(E26),ISNUMBER(F26)),ROUND(E26*F26,2),"") -> 1060
A27: 02.09 | B27: Desmontaje de puertas interiores y de entrada y sus marcos | C27: Desmontaje completo de las puertas interiores y de entrada y sus marcos. | D27: global | E27: 1 | F27: 620 | G27: =IF(AND(ISNUMBER(E27),ISNUMBER(F27)),ROUND(E27*F27,2),"") -> 620
A28: 02.10 | B28: Desmontaje de baños, aseos y aparatos sanitarios | C28: Desmontaje completo de baños, aseos y aparatos sanitarios existentes. | D28: global | E28: 1 | F28: 1420 | G28: =IF(AND(ISNUMBER(E28),ISNUMBER(F28)),ROUND(E28*F28,2),"") -> 1420
A29: 02.11 | B29: Desmontaje de puntos, mecanismos y luminarias eléctricas | C29: Desmontaje de los puntos, mecanismos y luminarias eléctricas existentes. | D29: global | E29: 1 | F29: 710 | G29: =IF(AND(ISNUMBER(E29),ISNUMBER(F29)),ROUND(E29*F29,2),"") -> 710
A30: 02.12 | B30: Desmontaje de fontanería vista existente | C30: Desmontaje de las tuberías de fontanería vistas existentes. | D30: global | E30: 1 | F30: 530 | G30: =IF(AND(ISNUMBER(E30),ISNUMBER(F30)),ROUND(E30*F30,2),"") -> 530
... A38: 02.20 | B38: Demolición de la escalera de entrada existente | C38: Demolición de la escalera de entrada existente, incluido corte, carga y retirada, previa a los nuevos escalones volados. | D38: global | E38: 1 | F38: 530 | G38: =IF(AND(ISNUMBER(E38),ISNUMBER(F38)),ROUND(E38*F38,2),"") -> 530
A39: 02.21 | B39: Retirada de césped y plantas de jardín | C39: Retirada del césped, arbustos y plantas de jardín existentes en las zonas de urbanización, incluidas raíces, carga y retirada. | D39: m² | E39: 65 | F39: 6.2 | G39: =IF(AND(ISNUMBER(E39),ISNUMBER(F39)),ROUND(E39*F39,2),"") -> 403 | H39: Cantidad provisional – se medirá en obra
A40: Total – Capítulo 2 | G40: =IF(COUNT(G19:G39)=0,"",SUM(G19:G39)) -> 21385.5
A42: Capítulo 3 — Obras de estructura y ampliaciones
A43: 03.01 | B43: Ampliación del balcón del salón y nueva pérgola | C43: Obra estructural completa según planos y especificaciones del ingeniero de estructuras. | D43: global | E43: 1 | F43: 12400 | G43: =IF(AND(ISNUMBER(E43),ISNUMBER(F43)),ROUND(E43*F43,2),"") -> 12400 | H43: Importe global – se ajustará al recibir los planos de estructura
A44: 03.02 | B44: Nueva habitación en el nivel de galería | C44: Obra estructural completa de la habitación según planos de estructura y arquitectura, incluidas conexiones con la estructura existente y huecos. Acabados e instalaciones en sus capítulos. | D44: global | E44: 1 | F44: 21300 | G44: =IF(AND(ISNUMBER(E44),ISNUMBER(F44)),ROUND(E44*F44,2),"") -> 21300 | H44: Importe global – se ajustará al recibir los planos de estructura
A45: 03.03 | B45: Nueva entrada y nueva escalera | C45: Obra completa de la nueva entrada y escalera según el ingeniero de estructuras. | D45: global | E45: 1 | F45: 6700 | G45: =IF(AND(ISNUMBER(E45),ISNUMBER(F45)),ROUND(E45*F45,2),"") -> 6700 | H45: Importe global – se ajustará al recibir los planos de estructura
A46: 03.04 | B46: Refuerzo de la escalera interior existente | C46: Refuerzo según el ingeniero de estructuras, tras retirar la barandilla. | D46: global | E46: 1 | F46: 3190 | G46: =IF(AND(ISNUMBER(E46),ISNUMBER(F46)),ROUND(E46*F46,2),"") -> 3190 | H46: Importe global – se ajustará al recibir los planos de estructura
A47: 03.05 | B47: Escalones de entrada volados | C47: 12 nuevos escalones volados (en voladizo) en la entrada, en sustitución de la escalera existente, de unos 1,15 m de ancho, con armado, anclajes y preparación para el revestimiento, según planos de estructura y arquitectura. Revestimiento en la partida 13.08. | D47: ud | E47: 12 | F47: 497 | G47: =IF(AND(ISNUMBER(E47),ISNUMBER(F47)),ROUND(E47*F47,2),"") -> 5964 | H47: Importe global – se ajustará al recibir los planos de estructura; Medida definitiva según lo existente en obra
A48: Total – Capítulo 3 | G48: =IF(COUNT(G43:G47)=0,"",SUM(G43:G47)) -> 49554
A50: Capítulo 4 — Nuevos muros de bloque
A51: 04.01 | B51: Nuevos muros de bloque (20 cm) – sótano | C51: Muros de bloque según planos. | D51: m² | E51: 6.3 | F51: 53 | G51: =IF(AND(ISNUMBER(E51),ISNUMBER(F51)),ROUND(E51*F51,2),"") -> 333.9
...

Sheet Resumen
A1: Resumen del presupuesto
A3: Capítulo | B3: Importe | C3: % del total
A4: 1. Preparación e instalación de obra | B4: ='Presupuesto'!G16 -> 14746 | C4: =IF($B$18=0,0,B4/$B$18) -> 0.060761164
A5: 2. Demoliciones, desmontajes y retirada de residuos | B5: ='Presupuesto'!G40 -> 21385.5 | C5: =IF($B$18=0,0,B5/$B$18) -> 0.088119346
A6: 3. Obras de estructura y ampliaciones | B6: ='Presupuesto'!G48 -> 49554 | C6: =IF($B$18=0,0,B6/$B$18) -> 0.20418817
A7: 4. Nuevos muros de bloque | B7: ='Presupuesto'!G54 -> 1382.24 | C7: =IF($B$18=0,0,B7/$B$18) -> 0.0056955454
A8: 5. Fontanería, aparatos sanitarios y griferías | B8: ='Presupuesto'!G90 -> 23491.5 | C8: =IF($B$18=0,0,B8/$B$18) -> 0.096797158
A9: 6. Instalación eléctrica | B9: ='Presupuesto'!G104 -> 15301 | C9: =IF($B$18=0,0,B9/$B$18) -> 0.063048052
A10: 7. Iluminación e interruptores | B10: ='Presupuesto'!G126 -> 15051 | C10: =IF($B$18=0,0,B10/$B$18) -> 0.062017923
A11: 9. Tabiques y techos de yeso laminado | B11: ='Presupuesto'!G133 -> 7450 | C11: =IF($B$18=0,0,B11/$B$18) -> 0.030697862
A12: 10. Impermeabilización interior | B12: ='Presupuesto'!G139 -> 5653 | C12: =IF($B$18=0,0,B12/$B$18) -> 0.023293291
A13: 12. Alféizares y sellado de ventanas | B13: ='Presupuesto'!G145 -> 3219.89 | C13: =IF($B$18=0,0,B13/$B$18) -> 0.013267616
A14: 13. Pavimentos, alicatados y revestimientos | B14: ='Presupuesto'!G155 -> 28510.6 | C14: =IF($B$18=0,0,B14/$B$18) -> 0.11747845
A15: 14. Enlucidos, alisados y pintura | B15: ='Presupuesto'!G161 -> 19093.5 | C15: =IF($B$18=0,0,B15/$B$18) -> 0.078675118
A16: 17. Obras exteriores | B16: ='Presupuesto'!G169 -> 13470 | C16: =IF($B$18=0,0,B16/$B$18) -> 0.055503383
A17: 21. Piscina | B17: ='Presupuesto'!G176 -> 24379.68 | C17: =IF($B$18=0,0,B17/$B$18) -> 0.10045692
A18: Total sin IVA | B18: =SUM(B4:B17) -> 242687.91
A19: IVA (21%) | B19: ='Presupuesto'!G179 -> 50964.46
A20: TOTAL CON IVA | B20: =B18+B19 -> 293652.37

Sheet Condiciones y exclusiones
A1: # | B1: Condiciones y exclusiones
A2: 1 | B2: Base del presupuesto | C2: El presupuesto se basa en el Pliego Técnico (rev. 20, 06/07/2026), los planos de arquitectura «Obra nueva» – planta baja y primera planta (17/09/2026) y el cuadro de cantidades del contratista de 24/09/2026. En caso de discrepancia prevalece el cuadro del 24/09/2026.
A3: 2 | B3: Cantidades | C3: Cantidades según los documentos anteriores. Las partidas «provisionales» o «según medición en obra» se medirán; la liquidación final seguirá las cantidades realmente ejecutadas.
A4: 3 | B4: Estructura | C4: El capítulo 3 (balcón y pérgola, habitación en galería, entrada y escalera, refuerzo de la escalera interior) es un importe global según planos del ingeniero de estructuras; el precio se ajustará al recibir los planos completos.
A5: 4 | B5: Suministro | C5: Aparatos sanitarios y griferías, luminarias, unidades de aire acondicionado, termos y baldosas de suelo y pared los suministra la propiedad; el contratista los instala. Los fregaderos de cocina los instala el proveedor de la encimera.
A6: 5 | B6: Exclusiones | C6: Carpintería (muebles de cocina, baño y armarios); ventanas y puertas de aluminio, puertas interiores y de entrada, cancelas y persianas; trabajos de peto de cubierta; mobiliario; licencias y tasas; honorarios de consultores (estructura, impermeabilización, iluminación); cargos de la compañía eléctrica por ampliación de potencia. La piscina SÍ está incluida (capítulo 21).
A7: 6 | B7: Pruebas | C7: Las pruebas y aprobaciones exigidas (ingeniero de estructuras, consultor de impermeabilización, inspector eléctrico autorizado, pruebas de inundación y presión) están incluidas.
A8: 7 | B8: Precios | C8: Precios en EUR, sin IVA, base octubre 2026, sin revisión salvo pacto en contrario.
A9: 8 | B9: Condiciones comerciales | C9: Validez: [__ días] | Forma de pago: [__] | Plazo: [__]

Sheet Estudio de mercado (interno)
A1: Categoría | B1: Datos de mercado encontrados (2026) | C1: Fuentes
A2: Tabique de yeso laminado | B2: 25–55 €/m² (media 30 €/m²), material y mano de obra | C2: habitissimo.es/presupuestos/pladur ; habitissimo.es/presupuestos/tabique-pladur
A3: Suelo porcelánico (colocación) | B3: 28–60 €/m² (media 45 €/m², material incluido); baño rectificado 50 €/m² | C3: habitissimo.es/presupuestos/suelo-porcelanico
A4: Punto de luz / enchufe | B4: 30–60 € por punto (referencia sin fecha); electricista ≈ 50 €/h | C4: cronoshare.com (prensa Valencia) ; sensorautomotriz.com/preguntas-frecuentes/cuanto-vale-poner-un-enchufe
A5: Pintura interior | B5: 8–12 €/m² (referencia sin fecha) | C5: trustlocal.es/coste/pintor-coste/
A6: Andamio | B6: ≈ 22 €/m² (partida de presupuesto público, Zaragoza, montaje y alquiler); otra partida ≈ 10 €/m² montaje y desmontaje | C6: zaragoza.es (anuncio 85085) ; caib.es (documento 485932)
A7: Piscina de obra | B7: 8×4×1,6 m en hormigón armado ≈ 10.000 € (tabla sin fecha); proyectado ≈ 16.000 € (foro); estimación propia 14.000–20.000 € con revestimiento y equipos | C7: habitissimo.es/presupuestos/construccion-piscinas ; todoexpertos.com/categorias/casa-y-jardin/piscinas
A8: Mano de obra | B8: oficial de primera: 26–36 €/h tarifa de venta (zonas medias), 36–50 €/h País Vasco/Navarra | C8: presupix.com/blog/precio-hora-oficial-construccion ; caasa.es/precios/
A9: Tipo de cambio | B9: ≈ 3,50 ILS por 1 EUR (≈ 3,46 a principios de agosto de 2026; octubre = previsiones) | C9: ofx.com ; b-sharpe.com
A11: Método: cada precio unitario = precio base israelí de reforma (ILS) × coeficiente de categoría ÷ tipo de cambio, más 15 % de gastos generales y beneficio. Los coeficientes se calibraron con las referencias siguientes (tabiques, solados, puntos eléctricos, pintura, andamio); los oficios sin referencia usan la media. Coeficientes: part=0.37, tile=0.35, elec=0.53, paint=0.56, conc=0.55, scaf=1.15, gen=0.54. FX 3.5 ILS/EUR.
A12: Salvedades: fuentes mayoritariamente comerciales, rangos amplios y algunos sin fecha; no se usó ninguna base de precios oficial. Faltan datos de 2026 para tabiques, solados, hormigón y andamio en parte de las fuentes (hay resultados de otros países que se descartaron). Piscina: estimación propia con datos antiguos; el cerramiento de seguridad es una estimación sin fuente. La obra está en Haifa (Israel) – precios de referencia del mercado español, sin ajustar a las condiciones locales. Verificar con presupuestos de proveedores antes de presentar.
