Workbook

Sheet Devis
A1: DEVIS — Rénovation et extension, 53 rue Shlonsky, Haïfa
A2: Maître d'ouvrage : Zohar Mor Yosef et Rami Dana | Entreprise : [Nom de l'entreprise] | Date : 14/10/2026 | Devis n° : [__]
A3: Tous les montants en EUR (€), hors TVA, base de prix octobre 2026. Les prix unitaires incluent les frais généraux et la marge de l'entreprise (15 %).
A5: Poste | B5: Désignation | C5: Description | D5: Unité | E5: Qté | F5: Prix unitaire | G5: Montant | H5: Remarques
A6: Chapitre 1 — Préparation et installation de chantier
A7: 01.01 | B7: Installation de chantier | C7: Mise en place des zones de travail et de stockage, des installations du personnel et coordination des accès. | D7: forfait | E7: 1 | F7: 2210 | G7: =IF(AND(ISNUMBER(E7),ISNUMBER(F7)),ROUND(E7*F7,2),"") -> 2210
A8: 01.02 | B8: Clôture, signalisation et sécurité du chantier | C8: Clôture provisoire, panneaux de chantier et de danger, et mesures de sécurité requises pendant les travaux. | D8: forfait | E8: 1 | F8: 1100 | G8: =IF(AND(ISNUMBER(E8),ISNUMBER(F8)),ROUND(E8*F8,2),"") -> 1100
A9: 01.03 | B9: Branchement d'eau provisoire | C9: Branchement d'eau provisoire depuis la source agréée, avec essai. | D9: forfait | E9: 1 | F9: 414 | G9: =IF(AND(ISNUMBER(E9),ISNUMBER(F9)),ROUND(E9*F9,2),"") -> 414
A10: 01.04 | B10: Branchement électrique provisoire | C10: Branchement électrique provisoire réalisé par un électricien qualifié, avec protections et essais. | D10: forfait | E10: 1 | F10: 830 | G10: =IF(AND(ISNUMBER(E10),ISNUMBER(F10)),ROUND(E10*F10,2),"") -> 830
A11: 01.05 | B11: Protection des éléments existants | C11: Protections des sols, ouvertures, fenêtres, escaliers, garde-corps, murs et végétaux à conserver. | D11: forfait | E11: 1 | F11: 1380 | G11: =IF(AND(ISNUMBER(E11),ISNUMBER(F11)),ROUND(E11*F11,2),"") -> 1380
A12: 01.06 | B12: Relevés, vérification et traçage laser | C12: Relevé du bâti existant, vérification par rapport aux plans d'architecture et des lots techniques, traçage des positions et des niveaux. | D12: forfait | E12: 1 | F12: 830 | G12: =IF(AND(ISNUMBER(E12),ISNUMBER(F12)),ROUND(E12*F12,2),"") -> 830
A13: 01.07 | B13: Benne à déchets et zone de collecte | C13: Mise en place d'une benne et d'une zone de collecte ; évacuation des déchets vers un site agréé. | D13: forfait | E13: 1 | F13: 2480 | G13: =IF(AND(ISNUMBER(E13),ISNUMBER(F13)),ROUND(E13*F13,2),"") -> 2480
A14: 01.08 | B14: Nettoyage courant du chantier | C14: Nettoyage périodique des zones de travail et des circulations pendant toute la durée des travaux. | D14: forfait | E14: 1 | F14: 2480 | G14: =IF(AND(ISNUMBER(E14),ISNUMBER(F14)),ROUND(E14*F14,2),"") -> 2480
A15: 01.09 | B15: Échafaudage extérieur | C15: Montage, location pour la durée des travaux (environ 4,5 mois), entretien et démontage d'un échafaudage extérieur conforme autour des façades, pour le sciage des cadres en béton décoratifs et les travaux d'enduit de façade. | D15: m² | E15: 225 | F15: 40 | G15: =IF(AND(ISNUMBER(E15),ISNUMBER(F15)),ROUND(E15*F15,2),"") -> 9000 | H15: Quantité provisoire – métrée sur place
A16: Total – Chapitre 1 | G16: =IF(COUNT(G7:G15)=0,"",SUM(G7:G15)) -> 20724
A18: Chapitre 2 — Démolition, dépose et évacuation
A19: 02.01 | B19: Démolition de murs et cloisons – sous-sol | C19: Démolition des murs et cloisons existants selon les plans de démolition. | D19: m² | E19: 62 | F19: 33 | G19: =IF(AND(ISNUMBER(E19),ISNUMBER(F19)),ROUND(E19*F19,2),"") -> 2046
A20: 02.02 | B20: Démolition de murs et cloisons – rez-de-chaussée | C20: Démolition des murs et cloisons existants selon les plans de démolition. | D20: m² | E20: 51 | F20: 33 | G20: =IF(AND(ISNUMBER(E20),ISNUMBER(F20)),ROUND(E20*F20,2),"") -> 1683
A21: 02.03 | B21: Démolition de murs et cloisons – 1er étage | C21: Démolition des murs et cloisons existants selon les plans de démolition. | D21: m² | E21: 85 | F21: 33 | G21: =IF(AND(ISNUMBER(E21),ISNUMBER(F21)),ROUND(E21*F21,2),"") -> 2805
A22: 02.04 | B22: Dépose des faux plafonds en plaques de plâtre | C22: Dépose des faux plafonds en plaques de plâtre existants. | D22: m² | E22: 10 | F22: 14 | G22: =IF(AND(ISNUMBER(E22),ISNUMBER(F22)),ROUND(E22*F22,2),"") -> 140
A23: 02.05 | B23: Dépose des revêtements de sol existants | C23: Dépose des revêtements de sol existants. | D23: m² | E23: 40 | F23: 25 | G23: =IF(AND(ISNUMBER(E23),ISNUMBER(F23)),ROUND(E23*F23,2),"") -> 1000
A24: 02.06 | B24: Dépose des meubles de cuisine existants | C24: Dépose complète des meubles de cuisine existants. | D24: forfait | E24: 1 | F24: 550 | G24: =IF(AND(ISNUMBER(E24),ISNUMBER(F24)),ROUND(E24*F24,2),"") -> 550
A25: 02.07 | B25: Dépose des autres meubles et menuiseries | C25: Dépose des autres meubles et ouvrages de menuiserie existants. | D25: u | E25: 1 | F25: 690 | G25: =IF(AND(ISNUMBER(E25),ISNUMBER(F25)),ROUND(E25*F25,2),"") -> 690
A26: 02.08 | B26: Dépose des fenêtres aluminium et volets roulants existants | C26: Dépose complète des fenêtres en aluminium et des volets roulants existants. | D26: forfait | E26: 1 | F26: 1660 | G26: =IF(AND(ISNUMBER(E26),ISNUMBER(F26)),ROUND(E26*F26,2),"") -> 1660
A27: 02.09 | B27: Dépose des portes intérieures et d'entrée et de leurs huisseries | C27: Dépose complète des portes intérieures et d'entrée et de leurs huisseries. | D27: forfait | E27: 1 | F27: 970 | G27: =IF(AND(ISNUMBER(E27),ISNUMBER(F27)),ROUND(E27*F27,2),"") -> 970
A28: 02.10 | B28: Dépose des salles de bains, WC et appareils sanitaires | C28: Dépose complète des salles de bains, WC et appareils sanitaires existants. | D28: forfait | E28: 1 | F28: 2210 | G28: =IF(AND(ISNUMBER(E28),ISNUMBER(F28)),ROUND(E28*F28,2),"") -> 2210
A29: 02.11 | B29: Dépose des points, appareillages et luminaires électriques | C29: Dépose des points électriques, appareillages et luminaires existants. | D29: forfait | E29: 1 | F29: 1100 | G29: =IF(AND(ISNUMBER(E29),ISNUMBER(F29)),ROUND(E29*F29,2),"") -> 1100
A30: 02.12 | B30: Dépose des canalisations apparentes existantes | C30: Dépose des canalisations de plomberie apparentes existantes. | D30: forfait | E30: 1 | F30: 830 | G30: =IF(AND(ISNUMBER(E30),ISNUMBER(F30)),ROUND(E30*F30,2),"") -> 830
... A38: 02.20 | B38: Dépose de l'escalier d'entrée existant | C38: Dépose de l'escalier d'entrée existant, y compris découpe, chargement et évacuation, avant la réalisation des nouvelles marches suspendues. | D38: forfait | E38: 1 | F38: 830 | G38: =IF(AND(ISNUMBER(E38),ISNUMBER(F38)),ROUND(E38*F38,2),"") -> 830
A39: 02.21 | B39: Dépose du gazon et des plantations | C39: Dépose du gazon, arbustes et plantations existants dans les zones aménagées, y compris racines, chargement et évacuation. | D39: m² | E39: 65 | F39: 9.7 | G39: =IF(AND(ISNUMBER(E39),ISNUMBER(F39)),ROUND(E39*F39,2),"") -> 630.5 | H39: Quantité provisoire – métrée sur place
A40: Total – Chapitre 2 | G40: =IF(COUNT(G19:G39)=0,"",SUM(G19:G39)) -> 33221.1
A42: Chapitre 3 — Travaux de structure et extensions
A43: 03.01 | B43: Agrandissement du balcon du salon et nouvelle pergola | C43: Travaux de structure complets selon les plans et le cahier des charges de l'ingénieur structure. | D43: forfait | E43: 1 | F43: 19300 | G43: =IF(AND(ISNUMBER(E43),ISNUMBER(F43)),ROUND(E43*F43,2),"") -> 19300 | H43: Forfait – ajusté à réception des plans de structure
A44: 03.02 | B44: Nouvelle pièce au niveau de la galerie | C44: Travaux de structure complets de la pièce selon les plans de structure et d'architecture, y compris liaisons avec l'existant et réservations. Finitions et lots techniques dans leurs chapitres. | D44: forfait | E44: 1 | F44: 33100 | G44: =IF(AND(ISNUMBER(E44),ISNUMBER(F44)),ROUND(E44*F44,2),"") -> 33100 | H44: Forfait – ajusté à réception des plans de structure
A45: 03.03 | B45: Nouvelle entrée et nouvel escalier | C45: Travaux complets de la nouvelle entrée et de l'escalier selon l'ingénieur structure. | D45: forfait | E45: 1 | F45: 10500 | G45: =IF(AND(ISNUMBER(E45),ISNUMBER(F45)),ROUND(E45*F45,2),"") -> 10500 | H45: Forfait – ajusté à réception des plans de structure
A46: 03.04 | B46: Renforcement de l'escalier intérieur existant | C46: Renforcement selon l'ingénieur structure, après dépose du garde-corps. | D46: forfait | E46: 1 | F46: 4970 | G46: =IF(AND(ISNUMBER(E46),ISNUMBER(F46)),ROUND(E46*F46,2),"") -> 4970 | H46: Forfait – ajusté à réception des plans de structure
A47: 03.05 | B47: Marches d'entrée suspendues | C47: 12 nouvelles marches suspendues (en console) à l'entrée, en remplacement de l'escalier existant, largeur d'environ 1,15 m, y compris ferraillage, ancrages et préparation au revêtement, selon plans de structure et d'architecture. Revêtement au poste 13.08. | D47: u | E47: 12 | F47: 770 | G47: =IF(AND(ISNUMBER(E47),ISNUMBER(F47)),ROUND(E47*F47,2),"") -> 9240 | H47: Forfait – ajusté à réception des plans de structure; Dimension définitive selon l'existant sur place
A48: Total – Chapitre 3 | G48: =IF(COUNT(G43:G47)=0,"",SUM(G43:G47)) -> 77110
A50: Chapitre 4 — Nouveaux murs en blocs
A51: 04.01 | B51: Nouveaux murs en blocs (20 cm) – sous-sol | C51: Murs en blocs selon plans. | D51: m² | E51: 6.3 | F51: 83 | G51: =IF(AND(ISNUMBER(E51),ISNUMBER(F51)),ROUND(E51*F51,2),"") -> 522.9
...

Sheet Récapitulatif
A1: Récapitulatif du devis
A3: Chapitre | B3: Montant | C3: % du total
A4: 1. Préparation et installation de chantier | B4: ='Devis'!G16 -> 20724 | C4: =IF($B$17=0,0,B4/$B$17) -> 0.057311627
A5: 2. Démolition, dépose et évacuation | B5: ='Devis'!G40 -> 33221.1 | C5: =IF($B$17=0,0,B5/$B$17) -> 0.091871998
A6: 3. Travaux de structure et extensions | B6: ='Devis'!G48 -> 77110 | C6: =IF($B$17=0,0,B6/$B$17) -> 0.21324549
A7: 4. Nouveaux murs en blocs | B7: ='Devis'!G54 -> 2164.64 | C7: =IF($B$17=0,0,B7/$B$17) -> 0.0059862497
A8: 5. Plomberie, appareils sanitaires et robinetterie | B8: ='Devis'!G90 -> 36513.5 | C8: =IF($B$17=0,0,B8/$B$17) -> 0.10097704
A9: 6. Électricité | B9: ='Devis'!G104 -> 34030 | C9: =IF($B$17=0,0,B9/$B$17) -> 0.094108988
A10: 7. Éclairage et interrupteurs | B10: ='Devis'!G126 -> 36028 | C10: =IF($B$17=0,0,B10/$B$17) -> 0.099634399
A11: 9. Cloisons et plafonds en plaques de plâtre | B11: ='Devis'!G133 -> 8264.85 | C11: =IF($B$17=0,0,B11/$B$17) -> 0.022856205
A12: 10. Étanchéité intérieure | B12: ='Devis'!G139 -> 8839.9 | C12: =IF($B$17=0,0,B12/$B$17) -> 0.02444649
A13: 12. Appuis de fenêtre et calfeutrement | B13: ='Devis'!G145 -> 4719.18 | C13: =IF($B$17=0,0,B13/$B$17) -> 0.013050757
A14: 13. Sols, faïence et revêtements | B14: ='Devis'!G155 -> 40750.85 | C14: =IF($B$17=0,0,B14/$B$17) -> 0.11269531
A15: 14. Enduits, lissage et peinture | B15: ='Devis'!G161 -> 39546 | C15: =IF($B$17=0,0,B15/$B$17) -> 0.10936333
A16: 17. Aménagements extérieurs | B16: ='Devis'!G169 -> 19690 | C16: =IF($B$17=0,0,B16/$B$17) -> 0.054452129
A17: Total HT | B17: =SUM(B4:B16) -> 361602.02
A18: TVA (20%) | B18: ='Devis'!G172 -> 72320.4
A19: TOTAL TTC | B19: =B17+B18 -> 433922.42

Sheet Conditions et exclusions
A1: # | B1: Conditions et exclusions
A2: 1 | B2: Base du devis | C2: Le devis repose sur le cahier des charges techniques (révision 20, 06/07/2026), les plans d'architecture « Construction neuve » – rez-de-chaussée et 1er étage (17/09/2026) et le bordereau de quantités de l'entreprise du 24/09/2026. En cas de divergence, le bordereau du 24/09/2026 prévaut.
A3: 2 | B3: Quantités | C3: Quantités selon les documents ci-dessus. Les postes « provisoires » ou « selon métré sur place » seront métrés ; le décompte final suit les quantités réellement exécutées.
A4: 3 | B4: Structure | C4: Le chapitre 3 (balcon et pergola, pièce en galerie, entrée et escalier, renforcement de l'escalier intérieur) est un forfait selon les plans de l'ingénieur structure ; le prix sera ajusté à réception des plans de structure complets.
A5: 4 | B5: Fournitures | C5: Appareils sanitaires et robinetterie, luminaires, unités de climatisation, chauffe-eau et carreaux de sol et muraux sont fournis par le maître d'ouvrage ; l'entreprise les pose. Les éviers de cuisine sont posés par le fournisseur du plan de travail.
A6: 5 | B6: Exclusions | C6: Piscine ; menuiserie (meubles de cuisine, de salle de bains et dressings) ; fenêtres et portes en aluminium, portes intérieures et d'entrée, portails et volets ; travaux d'acrotère ; mobilier ; permis et taxes ; honoraires des consultants (structure, étanchéité, éclairage) ; frais du fournisseur d'électricité pour l'augmentation de puissance.
A7: 6 | B7: Essais | C7: Les essais et approbations requis (ingénieur structure, bureau d'étanchéité, contrôleur électrique agréé, essais de mise en eau et de pression) sont inclus.
A8: 7 | B8: Prix | C8: Prix en EUR, hors TVA, base octobre 2026, sans révision sauf accord contraire.
A9: 8 | B9: Conditions commerciales | C9: Validité : [__ jours] | Conditions de paiement : [__] | Planning : [__]

Sheet Étude de marché (interne)
A1: Catégorie | B1: Données de marché trouvées (2026) | C1: Sources
A2: Cloison en plaques de plâtre | B2: 27–41 €/m² HT (standard) ; hydrofuge 30–45 ; isolant 38–60 | C2: prix-travaux-m2.com/prix-cloison-placo.php (janv. 2026) ; habitatpresto.com/mag/renovation/cloison-placo/tarif-plaquiste
A3: Pose de carrelage grand format | B3: 120×120 : 50–60 €/m² posé, fourniture comprise (page datée juil. 2025) ; main-d'œuvre seule : référence belge 25–55 €/m² | C3: prix-travaux-m2.com/prix-pose-carrelage.php ; blog.trustup.be/fr/?p=1107 (Belgique)
A4: Point électrique / prise | B4: Aucun tarif français trouvé ; référence belge 80–250 € pour une prise | C4: blog.trustup.be/fr/travaux/electricite/ (Belgique – indicatif)
A5: Peinture intérieure | B5: murs 20–48 €/m² HT, fournitures incluses ; plafonds 25–55 €/m² | C5: habitatpresto.com/mag/revetement/mur/dossier-peinture-interieure
A6: Allée en dalle béton | B6: 60–100 €/m² HT (allée carrossable 12–20 cm) ; 55–115 €/m² pose comprise | C6: prix-travaux-m2.com/prix-dalle-de-beton.php ; habitatpresto.com/mag/maconnerie/prix-dalle-beton
A7: Échafaudage | B7: pose 20–50 €/m² (indicatif, sans date) ; exemple belge 1 200 € HTVA pour 80 m² | C7: conseils.hellopro.fr/guide-de-prix-des-echafaudages-1212.html ; blog.trustup.be/fr/prix-renovation-facade/
A8: Taux de change | B8: ≈ 3,50 ILS pour 1 EUR (≈ 3,46 début août 2026 ; valeurs d'octobre = prévisions) | C8: ofx.com/en-au/exchange-rates/eur-to-ils/ ; b-sharpe.com
A10: Méthode : chaque prix unitaire = prix de base israélien de rénovation (ILS) × coefficient de catégorie ÷ taux de change, puis + 15 % de frais généraux et marge. Les coefficients ont été calés sur les repères ci-dessous (cloisons, carrelage, points électriques, peinture, dalle béton, échafaudage) ; les corps d'état sans repère utilisent la moyenne des coefficients calés. Coefficients : part=0.41, tile=0.5, elec=1.27, paint=1.4, conc=0.7, scaf=1.44, gen=0.84. FX 3.5 ILS/EUR.
A11: Réserves : sources majoritairement commerciales, fourchettes larges et parfois sans date ; aucun bordereau officiel utilisé. Aucun tarif français pour les points électriques (référence belge). Le chantier est à Haïfa (Israël) – prix de référence du marché français, non ajustés aux conditions locales. À vérifier avec des devis fournisseurs avant remise.
