Workbook

Sheet לוח זמנים
A1: לוח זמנים – שיפוץ ותוספות, שלונסקי 53, חיפה (ישראל; צוות פועלים סינים)
A2: תאריך התחלה (יום א׳): | D2: 46334 | F2: משכי הבסיס מחושבים לימי עבודה של 8 שעות. המשך בפועל = משך הבסיס ÷ מקדם התפוקה (מעוגל כלפי מעלה). ב-10 שעות ביום המקדם 1.18 (תפוקה שולית יורדת). מגמת העבודה: א׳–ה׳. אפשר לשנות שעות, תאריך התחלה, משכים וחגים – התאריכים והגאנט מתעדכנים.
A3: ימי מנוחה (שישי, שבת): | D3: 0000110
A4: שעות עבודה ביום: | D4: 10
A5: מקדם תפוקה: | D5: =ROUND(1+(D4-8)*0.09,2) -> 1.18
A7: ✡
A9: מס׳ | B9: פעילות | C9: סעיפי הצעת מחיר | D9: משך בסיס (ימי 8 ש׳) | E9: משך בפועל (ימים) | F9: ק1 | G9: ק2 | H9: ק3 | I9: ק4 | J9: ק5 | K9: ק6 | L9: סיום הקודמות | M9: התחלה | N9: סיום | O9: קריטי* | P9: על ידי | R9: =$D$2-MOD(WEEKDAY($D$2,1)-1,7)+0 -> 46334 | S9: =$D$2-MOD(WEEKDAY($D$2,1)-1,7)+7 -> 46341 | T9: =$D$2-MOD(WEEKDAY($D$2,1)-1,7)+14 -> 46348 | U9: =$D$2-MOD(WEEKDAY($D$2,1)-1,7)+21 -> 46355 | V9: =$D$2-MOD(WEEKDAY($D$2,1)-1,7)+28 -> 46362 | W9: =$D$2-MOD(WEEKDAY($D$2,1)-1,7)+35 -> 46369 | X9: =$D$2-MOD(WEEKDAY($D$2,1)-1,7)+42 -> 46376 | Y9: =$D$2-MOD(WEEKDAY($D$2,1)-1,7)+49 -> 46383 | Z9: =$D$2-MOD(WEEKDAY($D$2,1)-1,7)+56 -> 46390 | AA9: =$D$2-MOD(WEEKDAY($D$2,1)-1,7)+63 -> 46397 | AB9: =$D$2-MOD(WEEKDAY($D$2,1)-1,7)+70 -> 46404 | AC9: =$D$2-MOD(WEEKDAY($D$2,1)-1,7)+77 -> 46411 | AD9: =$D$2-MOD(WEEKDAY($D$2,1)-1,7)+84 -> 46418 | AE9: =$D$2-MOD(WEEKDAY($D$2,1)-1,7)+91 -> 46425 | AF9: =$D$2-MOD(WEEKDAY($D$2,1)-1,7)+98 -> 46432 | AG9: =$D$2-MOD(WEEKDAY($D$2,1)-1,7)+105 -> 46439 | AH9: =$D$2-MOD(WEEKDAY($D$2,1)-1,7)+112 -> 46446 | AI9: =$D$2-MOD(WEEKDAY($D$2,1)-1,7)+119 -> 46453 | AJ9: =$D$2-MOD(WEEKDAY($D$2,1)-1,7)+126 -> 46460 | AK9: =$D$2-MOD(WEEKDAY($D$2,1)-1,7)+133 -> 46467 | AL9: =$D$2-MOD(WEEKDAY($D$2,1)-1,7)+140 -> 46474 | AM9: =$D$2-MOD(WEEKDAY($D$2,1)-1,7)+147 -> 46481 | AN9: =$D$2-MOD(WEEKDAY($D$2,1)-1,7)+154 -> 46488 | AO9: =$D$2-MOD(WEEKDAY($D$2,1)-1,7)+161 -> 46495 | AP9: =$D$2-MOD(WEEKDAY($D$2,1)-1,7)+168 -> 46502 | AQ9: =$D$2-MOD(WEEKDAY($D$2,1)-1,7)+175 -> 46509 | AR9: =$D$2-MOD(WEEKDAY($D$2,1)-1,7)+182 -> 46516 | AS9: =$D$2-MOD(WEEKDAY($D$2,1)-1,7)+189 -> 46523 | AT9: =$D$2-MOD(WEEKDAY($D$2,1)-1,7)+196 -> 46530 | AU9: =$D$2-MOD(WEEKDAY($D$2,1)-1,7)+203 -> 46537 | AV9: =$D$2-MOD(WEEKDAY($D$2,1)-1,7)+210 -> 46544 | AW9: =$D$2-MOD(WEEKDAY($D$2,1)-1,7)+217 -> 46551 | AX9: =$D$2-MOD(WEEKDAY($D$2,1)-1,7)+224 -> 46558 | AY9: =$D$2-MOD(WEEKDAY($D$2,1)-1,7)+231 -> 46565 | AZ9: =$D$2-MOD(WEEKDAY($D$2,1)-1,7)+238 -> 46572 | BA9: =$D$2-MOD(WEEKDAY($D$2,1)-1,7)+245 -> 46579 | BB9: =$D$2-MOD(WEEKDAY($D$2,1)-1,7)+252 -> 46586 | BC9: =$D$2-MOD(WEEKDAY($D$2,1)-1,7)+259 -> 46593 | BD9: =$D$2-MOD(WEEKDAY($D$2,1)-1,7)+266 -> 46600 | BE9: =$D$2-MOD(WEEKDAY($D$2,1)-1,7)+273 -> 46607 | BF9: =$D$2-MOD(WEEKDAY($D$2,1)-1,7)+280 -> 46614 | BG9: =$D$2-MOD(WEEKDAY($D$2,1)-1,7)+287 -> 46621 | BH9: =$D$2-MOD(WEEKDAY($D$2,1)-1,7)+294 -> 46628 | BI9: =$D$2-MOD(WEEKDAY($D$2,1)-1,7)+301 -> 46635 | BJ9: =$D$2-MOD(WEEKDAY($D$2,1)-1,7)+308 -> 46642 | BK9: =$D$2-MOD(WEEKDAY($D$2,1)-1,7)+315 -> 46649 | BL9: =$D$2-MOD(WEEKDAY($D$2,1)-1,7)+322 -> 46656 | BM9: =$D$2-MOD(WEEKDAY($D$2,1)-1,7)+329 -> 46663 | BN9: =$D$2-MOD(WEEKDAY($D$2,1)-1,7)+336 -> 46670 | BO9: =$D$2-MOD(WEEKDAY($D$2,1)-1,7)+343 -> 46677 | BP9: =$D$2-MOD(WEEKDAY($D$2,1)-1,7)+350 -> 46684 | BQ9: =$D$2-MOD(WEEKDAY($D$2,1)-1,7)+357 -> 46691 | BR9: =$D$2-MOD(WEEKDAY($D$2,1)-1,7)+364 -> 46698 | BS9: =$D$2-MOD(WEEKDAY($D$2,1)-1,7)+371 -> 46705 | BT9: =$D$2-MOD(WEEKDAY($D$2,1)-1,7)+378 -> 46712 | BU9: =$D$2-MOD(WEEKDAY($D$2,1)-1,7)+385 -> 46719 | BV9: =$D$2-MOD(WEEKDAY($D$2,1)-1,7)+392 -> 46726 | BW9: =$D$2-MOD(WEEKDAY($D$2,1)-1,7)+399 -> 46733 | BX9: =$D$2-MOD(WEEKDAY($D$2,1)-1,7)+406 -> 46740 | BY9: =$D$2-MOD(WEEKDAY($D$2,1)-1,7)+413 -> 46747 | BZ9: =$D$2-MOD(WEEKDAY($D$2,1)-1,7)+420 -> 46754 | CA9: =$D$2-MOD(WEEKDAY($D$2,1)-1,7)+427 -> 46761 | CB9: =$D$2-MOD(WEEKDAY($D$2,1)-1,7)+434 -> 46768 | CC9: =$D$2-MOD(WEEKDAY($D$2,1)-1,7)+441 -> 46775 | CD9: =$D$2-MOD(WEEKDAY($D$2,1)-1,7)+448 -> 46782 | CE9: =$D$2-MOD(WEEKDAY($D$2,1)-1,7)+455 -> 46789 | CF9: =$D$2-MOD(WEEKDAY($D$2,1)-1,7)+462 -> 46796 | CG9: =$D$2-MOD(WEEKDAY($D$2,1)-1,7)+469 -> 46803 | CH9: =$D$2-MOD(WEEKDAY($D$2,1)-1,7)+476 -> 46810 | CI9: =$D$2-MOD(WEEKDAY($D$2,1)-1,7)+483 -> 46817
B10: ימים שאינם ימי עבודה בשבוע (חגים) | R10: =COUNTIFS('לוח שנה וחגים'!$F$5:$F$20,">="&R$9,'לוח שנה וחגים'!$F$5:$F$20,"<="&R$9+4) -> 0 | S10: =COUNTIFS('לוח שנה וחגים'!$F$5:$F$20,">="&S$9,'לוח שנה וחגים'!$F$5:$F$20,"<="&S$9+4) -> 0 | T10: =COUNTIFS('לוח שנה וחגים'!$F$5:$F$20,">="&T$9,'לוח שנה וחגים'!$F$5:$F$20,"<="&T$9+4) -> 0 | U10: =COUNTIFS('לוח שנה וחגים'!$F$5:$F$20,">="&U$9,'לוח שנה וחגים'!$F$5:$F$20,"<="&U$9+4) -> 0 | V10: =COUNTIFS('לוח שנה וחגים'!$F$5:$F$20,">="&V$9,'לוח שנה וחגים'!$F$5:$F$20,"<="&V$9+4) -> 0 | W10: =COUNTIFS('לוח שנה וחגים'!$F$5:$F$20,">="&W$9,'לוח שנה וחגים'!$F$5:$F$20,"<="&W$9+4) -> 0 | X10: =COUNTIFS('לוח שנה וחגים'!$F$5:$F$20,">="&X$9,'לוח שנה וחגים'!$F$5:$F$20,"<="&X$9+4) -> 0 | Y10: =COUNTIFS('לוח שנה וחגים'!$F$5:$F$20,">="&Y$9,'לוח שנה וחגים'!$F$5:$F$20,"<="&Y$9+4) -> 0 | ... CI10: =COUNTIFS('לוח שנה וחגים'!$F$5:$F$20,">="&CI$9,'לוח שנה וחגים'!$F$5:$F$20,"<="&CI$9+4) -> 0
A11: אישורים, היתרים והזמנות (חוק התכנון והבנייה)
A12: A010 | B12: חתימת חוזה וצו התחלת עבודה | C12: — | D12: 0 | E12: =IF(D12=0,0,MAX(1,ROUNDUP(D12/$D$5,0))) -> 0 | L12: =MAX($D$2-1,IFERROR(INDEX($N$11:$N$86,MATCH(F12,$A$11:$A$86,0)),0),IFERROR(INDEX($N$11:$N$86,MATCH(G12,$A$11:$A$86,0)),0),IFERROR(INDEX($N$11:$N$86,MATCH(H12,$A$11:$A$86,0)),0),IFERROR(INDEX($N$11:$N$86,MATCH(I12,$A$11:$A$86,0)),0),IFERROR(INDEX($N$11:$N$86,MATCH(J12,$A$11:$A$86,0)),0),IFERROR(INDEX($N$11:$N$86,MATCH(K12,$A$11:$A$86,0)),0)) -> 46333 | M12: =IF(E12=0,IF(COUNTA(F12:K12)=0,$D$2,L12),WORKDAY.INTL(L12,1,$D$3,'לוח שנה וחגים'!$F$5:$F$20)) -> 46334 | N12: =IF(E12=0,M12,WORKDAY.INTL(M12,E12-1,$D$3,'לוח שנה וחגים'!$F$5:$F$20)) -> 46334 | O12: ● | P12: קבלן
A13: A015 | B13: היתר בנייה בתוקף לתוספות ושינויי חזית (באחריות המזמין והאדריכלית) – להזין משך אם טרם התקבל | C13: 03.01–03.05, 02.15 | D13: 0 | E13: =IF(D13=0,0,MAX(1,ROUNDUP(D13/$D$5,0))) -> 0 | F13: A010 | L13: =MAX($D$2-1,IFERROR(INDEX($N$11:$N$86,MATCH(F13,$A$11:$A$86,0)),0),IFERROR(INDEX($N$11:$N$86,MATCH(G13,$A$11:$A$86,0)),0),IFERROR(INDEX($N$11:$N$86,MATCH(H13,$A$11:$A$86,0)),0),IFERROR(INDEX($N$11:$N$86,MATCH(I13,$A$11:$A$86,0)),0),IFERROR(INDEX($N$11:$N$86,MATCH(J13,$A$11:$A$86,0)),0),IFERROR(INDEX($N$11:$N$86,MATCH(K13,$A$11:$A$86,0)),0)) -> 46334 | M13: =IF(E13=0,IF(COUNTA(F13:K13)=0,$D$2,L13),WORKDAY.INTL(L13,1,$D$3,'לוח שנה וחגים'!$F$5:$F$20)) -> 46334 | N13: =IF(E13=0,M13,WORKDAY.INTL(M13,E13-1,$D$3,'לוח שנה וחגים'!$F$5:$F$20)) -> 46334 | P13: אחרים / מזמין / רשות
A14: A016 | B14: מינוי מנהל עבודה רשום, הודעה למפקח עבודה אזורי ותוכנית בטיחות | C14: — | D14: 3 | E14: =IF(D14=0,0,MAX(1,ROUNDUP(D14/$D$5,0))) -> 3 | F14: A010 | L14: =MAX($D$2-1,IFERROR(INDEX($N$11:$N$86,MATCH(F14,$A$11:$A$86,0)),0),IFERROR(INDEX($N$11:$N$86,MATCH(G14,$A$11:$A$86,0)),0),IFERROR(INDEX($N$11:$N$86,MATCH(H14,$A$11:$A$86,0)),0),IFERROR(INDEX($N$11:$N$86,MATCH(I14,$A$11:$A$86,0)),0),IFERROR(INDEX($N$11:$N$86,MATCH(J14,$A$11:$A$86,0)),0),IFERROR(INDEX($N$11:$N$86,MATCH(K14,$A$11:$A$86,0)),0)) -> 46334 | M14: =IF(E14=0,IF(COUNTA(F14:K14)=0,$D$2,L14),WORKDAY.INTL(L14,1,$D$3,'לוח שנה וחגים'!$F$5:$F$20)) -> 46335 | N14: =IF(E14=0,M14,WORKDAY.INTL(M14,E14-1,$D$3,'לוח שנה וחגים'!$F$5:$F$20)) -> 46337 | P14: קבלן
A15: A017 | B15: היתר העירייה להצבת פיגום ומכולת פסולת ברשות הרבים | C15: 01.07, 01.09 | D15: 10 | E15: =IF(D15=0,0,MAX(1,ROUNDUP(D15/$D$5,0))) -> 9 | F15: A010 | L15: =MAX($D$2-1,IFERROR(INDEX($N$11:$N$86,MATCH(F15,$A$11:$A$86,0)),0),IFERROR(INDEX($N$11:$N$86,MATCH(G15,$A$11:$A$86,0)),0),IFERROR(INDEX($N$11:$N$86,MATCH(H15,$A$11:$A$86,0)),0),IFERROR(INDEX($N$11:$N$86,MATCH(I15,$A$11:$A$86,0)),0),IFERROR(INDEX($N$11:$N$86,MATCH(J15,$A$11:$A$86,0)),0),IFERROR(INDEX($N$11:$N$86,MATCH(K15,$A$11:$A$86,0)),0)) -> 46334 | M15: =IF(E15=0,IF(COUNTA(F15:K15)=0,$D$2,L15),WORKDAY.INTL(L15,1,$D$3,'לוח שנה וחגים'!$F$5:$F$20)) -> 46335 | N15: =IF(E15=0,M15,WORKDAY.INTL(M15,E15-1,$D$3,'לוח שנה וחגים'!$F$5:$F$20)) -> 46345 | O15: ● | P15: קבלן
A16: A020 | B16: בקשה לחברת החשמל – הגדלת חיבור (3×40 אמפר) ופילר חדש | C16: 06.07 | D16: 40 | E16: =IF(D16=0,0,MAX(1,ROUNDUP(D16/$D$5,0))) -> 34 | F16: A010 | L16: =MAX($D$2-1,IFERROR(INDEX($N$11:$N$86,MATCH(F16,$A$11:$A$86,0)),0),IFERROR(INDEX($N$11:$N$86,MATCH(G16,$A$11:$A$86,0)),0),IFERROR(INDEX($N$11:$N$86,MATCH(H16,$A$11:$A$86,0)),0),IFERROR(INDEX($N$11:$N$86,MATCH(I16,$A$11:$A$86,0)),0),IFERROR(INDEX($N$11:$N$86,MATCH(J16,$A$11:$A$86,0)),0),IFERROR(INDEX($N$11:$N$86,MATCH(K16,$A$11:$A$86,0)),0)) -> 46334 | M16: =IF(E16=0,IF(COUNTA(F16:K16)=0,$D$2,L16),WORKDAY.INTL(L16,1,$D$3,'לוח שנה וחגים'!$F$5:$F$20)) -> 46335 | N16: =IF(E16=0,M16,WORKDAY.INTL(M16,E16-1,$D$3,'לוח שנה וחגים'!$F$5:$F$20)) -> 46380 | P16: אחרים / מזמין / רשות
A17: A030 | B17: אישור דוגמאות, חומרים וגוונים מול המעצבת (דוגמת טיח) | C17: 14.01 | D17: 10 | E17: =IF(D17=0,0,MAX(1,ROUNDUP(D17/$D$5,0))) -> 9 | F17: A010 | L17: =MAX($D$2-1,IFERROR(INDEX($N$11:$N$86,MATCH(F17,$A$11:$A$86,0)),0),IFERROR(INDEX($N$11:$N$86,MATCH(G17,$A$11:$A$86,0)),0),IFERROR(INDEX($N$11:$N$86,MATCH(H17,$A$11:$A$86,0)),0),IFERROR(INDEX($N$11:$N$86,MATCH(I17,$A$11:$A$86,0)),0),IFERROR(INDEX($N$11:$N$86,MATCH(J17,$A$11:$A$86,0)),0),IFERROR(INDEX($N$11:$N$86,MATCH(K17,$A$11:$A$86,0)),0)) -> 46334 | M17: =IF(E17=0,IF(COUNTA(F17:K17)=0,$D$2,L17),WORKDAY.INTL(L17,1,$D$3,'לוח שנה וחגים'!$F$5:$F$20)) -> 46335 | N17: =IF(E17=0,M17,WORKDAY.INTL(M17,E17-1,$D$3,'לוח שנה וחגים'!$F$5:$F$20)) -> 46345 | P17: קבלן
A18: A050 | B18: אספקת המזמין: הזמנה ואספקה של כלים סניטריים, ברזים וגופי תאורה | C18: 05, 07 | D18: 20 | E18: =IF(D18=0,0,MAX(1,ROUNDUP(D18/$D$5,0))) -> 17 | F18: A030 | L18: =MAX($D$2-1,IFERROR(INDEX($N$11:$N$86,MATCH(F18,$A$11:$A$86,0)),0),IFERROR(INDEX($N$11:$N$86,MATCH(G18,$A$11:$A$86,0)),0),IFERROR(INDEX($N$11:$N$86,MATCH(H18,$A$11:$A$86,0)),0),IFERROR(INDEX($N$11:$N$86,MATCH(I18,$A$11:$A$86,0)),0),IFERROR(INDEX($N$11:$N$86,MATCH(J18,$A$11:$A$86,0)),0),IFERROR(INDEX($N$11:$N$86,MATCH(K18,$A$11:$A$86,0)),0)) -> 46345 | M18: =IF(E18=0,IF(COUNTA(F18:K18)=0,$D$2,L18),WORKDAY.INTL(L18,1,$D$3,'לוח שנה וחגים'!$F$5:$F$20)) -> 46348 | N18: =IF(E18=0,M18,WORKDAY.INTL(M18,E18-1,$D$3,'לוח שנה וחגים'!$F$5:$F$20)) -> 46370 | P18: אחרים / מזמין / רשות
A19: A055 | B19: אספקת המזמין: הזמנה ואספקה של אריחי ריצוף וחיפוי | C19: 13 | D19: 20 | E19: =IF(D19=0,0,MAX(1,ROUNDUP(D19/$D$5,0))) -> 17 | F19: A030 | L19: =MAX($D$2-1,IFERROR(INDEX($N$11:$N$86,MATCH(F19,$A$11:$A$86,0)),0),IFERROR(INDEX($N$11:$N$86,MATCH(G19,$A$11:$A$86,0)),0),IFERROR(INDEX($N$11:$N$86,MATCH(H19,$A$11:$A$86,0)),0),IFERROR(INDEX($N$11:$N$86,MATCH(I19,$A$11:$A$86,0)),0),IFERROR(INDEX($N$11:$N$86,MATCH(J19,$A$11:$A$86,0)),0),IFERROR(INDEX($N$11:$N$86,MATCH(K19,$A$11:$A$86,0)),0)) -> 46345 | M19: =IF(E19=0,IF(COUNTA(F19:K19)=0,$D$2,L19),WORKDAY.INTL(L19,1,$D$3,'לוח שנה וחגים'!$F$5:$F$20)) -> 46348 | N19: =IF(E19=0,M19,WORKDAY.INTL(M19,E19-1,$D$3,'לוח שנה וחגים'!$F$5:$F$20)) -> 46370 | P19: אחרים / מזמין / רשות
A20: התארגנות
A21: S010 | B21: התארגנות אתר, גידור, חיבורי מים וחשמל זמניים, מכולת פסולת | C21: 01.01–01.04, 01.07 | D21: 5 | E21: =IF(D21=0,0,MAX(1,ROUNDUP(D21/$D$5,0))) -> 5 | F21: A016 | G21: A017 | L21: =MAX($D$2-1,IFERROR(INDEX($N$11:$N$86,MATCH(F21,$A$11:$A$86,0)),0),IFERROR(INDEX($N$11:$N$86,MATCH(G21,$A$11:$A$86,0)),0),IFERROR(INDEX($N$11:$N$86,MATCH(H21,$A$11:$A$86,0)),0),IFERROR(INDEX($N$11:$N$86,MATCH(I21,$A$11:$A$86,0)),0),IFERROR(INDEX($N$11:$N$86,MATCH(J21,$A$11:$A$86,0)),0),IFERROR(INDEX($N$11:$N$86,MATCH(K21,$A$11:$A$86,0)),0)) -> 46345 | M21: =IF(E21=0,IF(COUNTA(F21:K21)=0,$D$2,L21),WORKDAY.INTL(L21,1,$D$3,'לוח שנה וחגים'!$F$5:$F$20)) -> 46348 | N21: =IF(E21=0,M21,WORKDAY.INTL(M21,E21-1,$D$3,'לוח שנה וחגים'!$F$5:$F$20)) -> 46352 | O21: ● | P21: קבלן
A22: S020 | B22: הגנה על אלמנטים קיימים, מדידות וסימון בלייזר | C22: 01.05, 01.06 | D22: 4 | E22: =IF(D22=0,0,MAX(1,ROUNDUP(D22/$D$5,0))) -> 4 | F22: S010 | L22: =MAX($D$2-1,IFERROR(INDEX($N$11:$N$86,MATCH(F22,$A$11:$A$86,0)),0),IFERROR(INDEX($N$11:$N$86,MATCH(G22,$A$11:$A$86,0)),0),IFERROR(INDEX($N$11:$N$86,MATCH(H22,$A$11:$A$86,0)),0),IFERROR(INDEX($N$11:$N$86,MATCH(I22,$A$11:$A$86,0)),0),IFERROR(INDEX($N$11:$N$86,MATCH(J22,$A$11:$A$86,0)),0),IFERROR(INDEX($N$11:$N$86,MATCH(K22,$A$11:$A$86,0)),0)) -> 46352 | M22: =IF(E22=0,IF(COUNTA(F22:K22)=0,$D$2,L22),WORKDAY.INTL(L22,1,$D$3,'לוח שנה וחגים'!$F$5:$F$20)) -> 46355 | N22: =IF(E22=0,M22,WORKDAY.INTL(M22,E22-1,$D$3,'לוח שנה וחגים'!$F$5:$F$20)) -> 46358 | O22: ● | P22: קבלן
A23: S030 | B23: אישור כתוב של המתכננת למעבר להריסות | C23: — | D23: 1 | E23: =IF(D23=0,0,MAX(1,ROUNDUP(D23/$D$5,0))) -> 1 | F23: S020 | L23: =MAX($D$2-1,IFERROR(INDEX($N$11:$N$86,MATCH(F23,$A$11:$A$86,0)),0),IFERROR(INDEX($N$11:$N$86,MATCH(G23,$A$11:$A$86,0)),0),IFERROR(INDEX($N$11:$N$86,MATCH(H23,$A$11:$A$86,0)),0),IFERROR(INDEX($N$11:$N$86,MATCH(I23,$A$11:$A$86,0)),0),IFERROR(INDEX($N$11:$N$86,MATCH(J23,$A$11:$A$86,0)),0),IFERROR(INDEX($N$11:$N$86,MATCH(K23,$A$11:$A$86,0)),0)) -> 46358 | M23: =IF(E23=0,IF(COUNTA(F23:K23)=0,$D$2,L23),WORKDAY.INTL(L23,1,$D$3,'לוח שנה וחגים'!$F$5:$F$20)) -> 46359 | N23: =IF(E23=0,M23,WORKDAY.INTL(M23,E23-1,$D$3,'לוח שנה וחגים'!$F$5:$F$20)) -> 46359 | O23: ● | P23: קבלן
A24: הריסות ופירוקים
A25: D010 | B25: פירוק חלונות, דלתות, כלים סניטריים, ארונות, מיזוג, חשמל וצנרת גלויה | C25: 02.06–02.13 | D25: 8 | E25: =IF(D25=0,0,MAX(1,ROUNDUP(D25/$D$5,0))) -> 7 | F25: S030 | L25: =MAX($D$2-1,IFERROR(INDEX($N$11:$N$86,MATCH(F25,$A$11:$A$86,0)),0),IFERROR(INDEX($N$11:$N$86,MATCH(G25,$A$11:$A$86,0)),0),IFERROR(INDEX($N$11:$N$86,MATCH(H25,$A$11:$A$86,0)),0),IFERROR(INDEX($N$11:$N$86,MATCH(I25,$A$11:$A$86,0)),0),IFERROR(INDEX($N$11:$N$86,MATCH(J25,$A$11:$A$86,0)),0),IFERROR(INDEX($N$11:$N$86,MATCH(K25,$A$11:$A$86,0)),0)) -> 46359 | M25: =IF(E25=0,IF(COUNTA(F25:K25)=0,$D$2,L25),WORKDAY.INTL(L25,1,$D$3,'לוח שנה וחגים'!$F$5:$F$20)) -> 46362 | N25: =IF(E25=0,M25,WORKDAY.INTL(M25,E25-1,$D$3,'לוח שנה וחגים'!$F$5:$F$20)) -> 46370 | O25: ● | P25: קבלן
A26: D020 | B26: הריסת קירות ומחיצות – מרתף (62 מ"ר) | C26: 02.01 | D26: 3 | E26: =IF(D26=0,0,MAX(1,ROUNDUP(D26/$D$5,0))) -> 3 | F26: D010 | L26: =MAX($D$2-1,IFERROR(INDEX($N$11:$N$86,MATCH(F26,$A$11:$A$86,0)),0),IFERROR(INDEX($N$11:$N$86,MATCH(G26,$A$11:$A$86,0)),0),IFERROR(INDEX($N$11:$N$86,MATCH(H26,$A$11:$A$86,0)),0),IFERROR(INDEX($N$11:$N$86,MATCH(I26,$A$11:$A$86,0)),0),IFERROR(INDEX($N$11:$N$86,MATCH(J26,$A$11:$A$86,0)),0),IFERROR(INDEX($N$11:$N$86,MATCH(K26,$A$11:$A$86,0)),0)) -> 46370 | M26: =IF(E26=0,IF(COUNTA(F26:K26)=0,$D$2,L26),WORKDAY.INTL(L26,1,$D$3,'לוח שנה וחגים'!$F$5:$F$20)) -> 46371 | N26: =IF(E26=0,M26,WORKDAY.INTL(M26,E26-1,$D$3,'לוח שנה וחגים'!$F$5:$F$20)) -> 46373 | P26: קבלן
A27: D030 | B27: הריסת קירות ומחיצות – קומת קרקע (51 מ"ר) | C27: 02.02 | D27: 3 | E27: =IF(D27=0,0,MAX(1,ROUNDUP(D27/$D$5,0))) -> 3 | F27: D010 | L27: =MAX($D$2-1,IFERROR(INDEX($N$11:$N$86,MATCH(F27,$A$11:$A$86,0)),0),IFERROR(INDEX($N$11:$N$86,MATCH(G27,$A$11:$A$86,0)),0),IFERROR(INDEX($N$11:$N$86,MATCH(H27,$A$11:$A$86,0)),0),IFERROR(INDEX($N$11:$N$86,MATCH(I27,$A$11:$A$86,0)),0),IFERROR(INDEX($N$11:$N$86,MATCH(J27,$A$11:$A$86,0)),0),IFERROR(INDEX($N$11:$N$86,MATCH(K27,$A$11:$A$86,0)),0)) -> 46370 | M27: =IF(E27=0,IF(COUNTA(F27:K27)=0,$D$2,L27),WORKDAY.INTL(L27,1,$D$3,'לוח שנה וחגים'!$F$5:$F$20)) -> 46371 | N27: =IF(E27=0,M27,WORKDAY.INTL(M27,E27-1,$D$3,'לוח שנה וחגים'!$F$5:$F$20)) -> 46373 | P27: קבלן
A28: D040 | B28: הריסת קירות ומחיצות – קומה א׳ (85 מ"ר) | C28: 02.03 | D28: 4 | E28: =IF(D28=0,0,MAX(1,ROUNDUP(D28/$D$5,0))) -> 4 | F28: D010 | L28: =MAX($D$2-1,IFERROR(INDEX($N$11:$N$86,MATCH(F28,$A$11:$A$86,0)),0),IFERROR(INDEX($N$11:$N$86,MATCH(G28,$A$11:$A$86,0)),0),IFERROR(INDEX($N$11:$N$86,MATCH(H28,$A$11:$A$86,0)),0),IFERROR(INDEX($N$11:$N$86,MATCH(I28,$A$11:$A$86,0)),0),IFERROR(INDEX($N$11:$N$86,MATCH(J28,$A$11:$A$86,0)),0),IFERROR(INDEX($N$11:$N$86,MATCH(K28,$A$11:$A$86,0)),0)) -> 46370 | M28: =IF(E28=0,IF(COUNTA(F28:K28)=0,$D$2,L28),WORKDAY.INTL(L28,1,$D$3,'לוח שנה וחגים'!$F$5:$F$20)) -> 46371 | N28: =IF(E28=0,M28,WORKDAY.INTL(M28,E28-1,$D$3,'לוח שנה וחגים'!$F$5:$F$20)) -> 46376 | P28: קבלן
A29: D050 | B29: פירוק תקרות גבס, ריצופים ופנלים | C29: 02.04, 02.05, 02.18 | D29: 6 | E29: =IF(D29=0,0,MAX(1,ROUNDUP(D29/$D$5,0))) -> 6 | F29: D010 | L29: =MAX($D$2-1,IFERROR(INDEX($N$11:$N$86,MATCH(F29,$A$11:$A$86,0)),0),IFERROR(INDEX($N$11:$N$86,MATCH(G29,$A$11:$A$86,0)),0),IFERROR(INDEX($N$11:$N$86,MATCH(H29,$A$11:$A$86,0)),0),IFERROR(INDEX($N$11:$N$86,MATCH(I29,$A$11:$A$86,0)),0),IFERROR(INDEX($N$11:$N$86,MATCH(J29,$A$11:$A$86,0)),0),IFERROR(INDEX($N$11:$N$86,MATCH(K29,$A$11:$A$86,0)),0)) -> 46370 | M29: =IF(E29=0,IF(COUNTA(F29:K29)=0,$D$2,L29),WORKDAY.INTL(L29,1,$D$3,'לוח שנה וחגים'!$F$5:$F$20)) -> 46371 | N29: =IF(E29=0,M29,WORKDAY.INTL(M29,E29-1,$D$3,'לוח שנה וחגים'!$F$5:$F$20)) -> 46378 | O29: ● | P29: קבלן
A30: X010 | B30: הקמת פיגום חיצוני | C30: 01.09 | D30: 5 | E30: =IF(D30=0,0,MAX(1,ROUNDUP(D30/$D$5,0))) -> 5 | F30: S030 | G30: A017 | L30: =MAX($D$2-1,IFERROR(INDEX($N$11:$N$86,MATCH(F30,$A$11:$A$86,0)),0),IFERROR(INDEX($N$11:$N$86,MATCH(G30,$A$11:$A$86,0)),0),IFERROR(INDEX($N$11:$N$86,MATCH(H30,$A$11:$A$86,0)),0),IFERROR(INDEX($N$11:$N$86,MATCH(I30,$A$11:$A$86,0)),0),IFERROR(INDEX($N$11:$N$86,MATCH(J30,$A$11:$A$86,0)),0),IFERROR(INDEX($N$11:$N$86,MATCH(K30,$A$11:$A$86,0)),0)) -> 46359 | M30: =IF(E30=0,IF(COUNTA(F30:K30)=0,$D$2,L30),WORKDAY.INTL(L30,1,$D$3,'לוח שנה וחגים'!$F$5:$F$20)) -> 46362 | N30: =IF(E30=0,M30,WORKDAY.INTL(M30,E30-1,$D$3,'לוח שנה וחגים'!$F$5:$F$20)) -> 46366 | P30: קבלן
A31: X015 | B31: בדיקת הפיגום על ידי בודק מוסמך לפני תחילת עבודה | C31: 01.09 | D31: 1 | E31: =IF(D31=0,0,MAX(1,ROUNDUP(D31/$D$5,0))) -> 1 | F31: X010 | L31: =MAX($D$2-1,IFERROR(INDEX($N$11:$N$86,MATCH(F31,$A$11:$A$86,0)),0),IFERROR(INDEX($N$11:$N$86,MATCH(G31,$A$11:$A$86,0)),0),IFERROR(INDEX($N$11:$N$86,MATCH(H31,$A$11:$A$86,0)),0),IFERROR(INDEX($N$11:$N$86,MATCH(I31,$A$11:$A$86,0)),0),IFERROR(INDEX($N$11:$N$86,MATCH(J31,$A$11:$A$86,0)),0),IFERROR(INDEX($N$11:$N$86,MATCH(K31,$A$11:$A$86,0)),0)) -> 46366 | M31: =IF(E31=0,IF(COUNTA(F31:K31)=0,$D$2,L31),WORKDAY.INTL(L31,1,$D$3,'לוח שנה וחגים'!$F$5:$F$20)) -> 46369 | N31: =IF(E31=0,M31,WORKDAY.INTL(M31,E31-1,$D$3,'לוח שנה וחגים'!$F$5:$F$20)) -> 46369 | P31: קבלן
A32: D055 | B32: ניסור ופירוק מסגרות בטון דקורטיביות מהפיגום (באישור קונסטרוקטור והיתר, ככל שנדרש) | C32: 02.15 | D32: 6 | E32: =IF(D32=0,0,MAX(1,ROUNDUP(D32/$D$5,0))) -> 6 | F32: X015 | G32: D010 | H32: A015 | L32: =MAX($D$2-1,IFERROR(INDEX($N$11:$N$86,MATCH(F32,$A$11:$A$86,0)),0),IFERROR(INDEX($N$11:$N$86,MATCH(G32,$A$11:$A$86,0)),0),IFERROR(INDEX($N$11:$N$86,MATCH(H32,$A$11:$A$86,0)),0),IFERROR(INDEX($N$11:$N$86,MATCH(I32,$A$11:$A$86,0)),0),IFERROR(INDEX($N$11:$N$86,MATCH(J32,$A$11:$A$86,0)),0),IFERROR(INDEX($N$11:$N$86,MATCH(K32,$A$11:$A$86,0)),0)) -> 46370 | M32: =IF(E32=0,IF(COUNTA(F32:K32)=0,$D$2,L32),WORKDAY.INTL(L32,1,$D$3,'לוח שנה וחגים'!$F$5:$F$20)) -> 46371 | N32: =IF(E32=0,M32,WORKDAY.INTL(M32,E32-1,$D$3,'לוח שנה וחגים'!$F$5:$F$20)) -> 46378 | O32: ● | P32: קבלן
A33: D060 | B33: פירוק גרנוליט, מדרגות כניסה קיימות וצמחיית גינון | C33: 02.19–02.21 | D33: 7 | E33: =IF(D33=0,0,MAX(1,ROUNDUP(D33/$D$5,0))) -> 6 | F33: S030 | L33: =MAX($D$2-1,IFERROR(INDEX($N$11:$N$86,MATCH(F33,$A$11:$A$86,0)),0),IFERROR(INDEX($N$11:$N$86,MATCH(G33,$A$11:$A$86,0)),0),IFERROR(INDEX($N$11:$N$86,MATCH(H33,$A$11:$A$86,0)),0),IFERROR(INDEX($N$11:$N$86,MATCH(I33,$A$11:$A$86,0)),0),IFERROR(INDEX($N$11:$N$86,MATCH(J33,$A$11:$A$86,0)),0),IFERROR(INDEX($N$11:$N$86,MATCH(K33,$A$11:$A$86,0)),0)) -> 46359 | M33: =IF(E33=0,IF(COUNTA(F33:K33)=0,$D$2,L33),WORKDAY.INTL(L33,1,$D$3,'לוח שנה וחגים'!$F$5:$F$20)) -> 46362 | N33: =IF(E33=0,M33,WORKDAY.INTL(M33,E33-1,$D$3,'לוח שנה וחגים'!$F$5:$F$20)) -> 46369 | P33: קבלן
A34: D065 | B34: פינוי פסולת לאתר מורשה וניקיון יסודי | C34: 02.16, 02.17 | D34: 4 | E34: =IF(D34=0,0,MAX(1,ROUNDUP(D34/$D$5,0))) -> 4 | F34: D020 | G34: D030 | H34: D040 | I34: D050 | J34: D055 | K34: D060 | L34: =MAX($D$2-1,IFERROR(INDEX($N$11:$N$86,MATCH(F34,$A$11:$A$86,0)),0),IFERROR(INDEX($N$11:$N$86,MATCH(G34,$A$11:$A$86,0)),0),IFERROR(INDEX($N$11:$N$86,MATCH(H34,$A$11:$A$86,0)),0),IFERROR(INDEX($N$11:$N$86,MATCH(I34,$A$11:$A$86,0)),0),IFERROR(INDEX($N$11:$N$86,MATCH(J34,$A$11:$A$86,0)),0),IFERROR(INDEX($N$11:$N$86,MATCH(K34,$A$11:$A$86,0)),0)) -> 46378 | M34: =IF(E34=0,IF(COUNTA(F34:K34)=0,$D$2,L34),WORKDAY.INTL(L34,1,$D$3,'לוח שנה וחגים'!$F$5:$F$20)) -> 46379 | N34: =IF(E34=0,M34,WORKDAY.INTL(M34,E34-1,$D$3,'לוח שנה וחגים'!$F$5:$F$20)) -> 46384 | O34: ● | P34: קבלן
A35: D070 | B35: אישור קונסטרוקטור ומתכננת למעבר לבנייה | C35: — | D35: 2 | E35: =IF(D35=0,0,MAX(1,ROUNDUP(D35/$D$5,0))) -> 2 | F35: D065 | L35: =MAX($D$2-1,IFERROR(INDEX($N$11:$N$86,MATCH(F35,$A$11:$A$86,0)),0),IFERROR(INDEX($N$11:$N$86,MATCH(G35,$A$11:$A$86,0)),0),IFERROR(INDEX($N$11:$N$86,MATCH(H35,$A$11:$A$86,0)),0),IFERROR(INDEX($N$11:$N$86,MATCH(I35,$A$11:$A$86,0)),0),IFERROR(INDEX($N$11:$N$86,MATCH(J35,$A$11:$A$86,0)),0),IFERROR(INDEX($N$11:$N$86,MATCH(K35,$A$11:$A$86,0)),0)) -> 46384 | M35: =IF(E35=0,IF(COUNTA(F35:K35)=0,$D$2,L35),WORKDAY.INTL(L35,1,$D$3,'לוח שנה וחגים'!$F$5:$F$20)) -> 46385 | N35: =IF(E35=0,M35,WORKDAY.INTL(M35,E35-1,$D$3,'לוח שנה וחגים'!$F$5:$F$20)) -> 46386 | O35: ● | P35: קבלן
A36: שלד ותוספות מבניות
A37: K010 | B37: חיזוק גרם המדרגות הפנימי הקיים | C37: 03.04 | D37: 10 | E37: =IF(D37=0,0,MAX(1,ROUNDUP(D37/$D$5,0))) -> 9 | F37: D070 | L37: =MAX($D$2-1,IFERROR(INDEX($N$11:$N$86,MATCH(F37,$A$11:$A$86,0)),0),IFERROR(INDEX($N$11:$N$86,MATCH(G37,$A$11:$A$86,0)),0),IFERROR(INDEX($N$11:$N$86,MATCH(H37,$A$11:$A$86,0)),0),IFERROR(INDEX($N$11:$N$86,MATCH(I37,$A$11:$A$86,0)),0),IFERROR(INDEX($N$11:$N$86,MATCH(J37,$A$11:$A$86,0)),0),IFERROR(INDEX($N$11:$N$86,MATCH(K37,$A$11:$A$86,0)),0)) -> 46386 | M37: =IF(E37=0,IF(COUNTA(F37:K37)=0,$D$2,L37),WORKDAY.INTL(L37,1,$D$3,'לוח שנה וחגים'!$F$5:$F$20)) -> 46387 | N37: =IF(E37=0,M37,WORKDAY.INTL(M37,E37-1,$D$3,'לוח שנה וחגים'!$F$5:$F$20)) -> 46399 | P37: קבלן
A38: K020 | B38: שלד כניסה חדשה וגרם מדרגות | C38: 03.03 | D38: 15 | E38: =IF(D38=0,0,MAX(1,ROUNDUP(D38/$D$5,0))) -> 13 | F38: D070 | G38: A015 | L38: =MAX($D$2-1,IFERROR(INDEX($N$11:$N$86,MATCH(F38,$A$11:$A$86,0)),0),IFERROR(INDEX($N$11:$N$86,MATCH(G38,$A$11:$A$86,0)),0),IFERROR(INDEX($N$11:$N$86,MATCH(H38,$A$11:$A$86,0)),0),IFERROR(INDEX($N$11:$N$86,MATCH(I38,$A$11:$A$86,0)),0),IFERROR(INDEX($N$11:$N$86,MATCH(J38,$A$11:$A$86,0)),0),IFERROR(INDEX($N$11:$N$86,MATCH(K38,$A$11:$A$86,0)),0)) -> 46386 | M38: =IF(E38=0,IF(COUNTA(F38:K38)=0,$D$2,L38),WORKDAY.INTL(L38,1,$D$3,'לוח שנה וחגים'!$F$5:$F$20)) -> 46387 | N38: =IF(E38=0,M38,WORKDAY.INTL(M38,E38-1,$D$3,'לוח שנה וחגים'!$F$5:$F$20)) -> 46405 | P38: קבלן
A39: K025 | B39: מדרגות כניסה מרחפות (12 מדרגות) | C39: 03.05 | D39: 8 | E39: =IF(D39=0,0,MAX(1,ROUNDUP(D39/$D$5,0))) -> 7 | F39: K020 | L39: =MAX($D$2-1,IFERROR(INDEX($N$11:$N$86,MATCH(F39,$A$11:$A$86,0)),0),IFERROR(INDEX($N$11:$N$86,MATCH(G39,$A$11:$A$86,0)),0),IFERROR(INDEX($N$11:$N$86,MATCH(H39,$A$11:$A$86,0)),0),IFERROR(INDEX($N$11:$N$86,MATCH(I39,$A$11:$A$86,0)),0),IFERROR(INDEX($N$11:$N$86,MATCH(J39,$A$11:$A$86,0)),0),IFERROR(INDEX($N$11:$N$86,MATCH(K39,$A$11:$A$86,0)),0)) -> 46405 | M39: =IF(E39=0,IF(COUNTA(F39:K39)=0,$D$2,L39),WORKDAY.INTL(L39,1,$D$3,'לוח שנה וחגים'!$F$5:$F$20)) -> 46406 | N39: =IF(E39=0,M39,WORKDAY.INTL(M39,E39-1,$D$3,'לוח שנה וחגים'!$F$5:$F$20)) -> 46414 | P39: קבלן
A40: K030 | B40: הגדלת מרפסת הסלון ותוספת פרגולה | C40: 03.01 | D40: 28 | E40: =IF(D40=0,0,MAX(1,ROUNDUP(D40/$D$5,0))) -> 24 | F40: D070 | G40: A015 | L40: =MAX($D$2-1,IFERROR(INDEX($N$11:$N$86,MATCH(F40,$A$11:$A$86,0)),0),IFERROR(INDEX($N$11:$N$86,MATCH(G40,$A$11:$A$86,0)),0),IFERROR(INDEX($N$11:$N$86,MATCH(H40,$A$11:$A$86,0)),0),IFERROR(INDEX($N$11:$N$86,MATCH(I40,$A$11:$A$86,0)),0),IFERROR(INDEX($N$11:$N$86,MATCH(J40,$A$11:$A$86,0)),0),IFERROR(INDEX($N$11:$N$86,MATCH(K40,$A$11:$A$86,0)),0)) -> 46386 | M40: =IF(E40=0,IF(COUNTA(F40:K40)=0,$D$2,L40),WORKDAY.INTL(L40,1,$D$3,'לוח שנה וחגים'!$F$5:$F$20)) -> 46387 | N40: =IF(E40=0,M40,WORKDAY.INTL(M40,E40-1,$D$3,'לוח שנה וחגים'!$F$5:$F$20)) -> 46420 | P40: קבלן
A41: K040 | B41: תוספת חדר בקומת הגלריה | C41: 03.02 | D41: 35 | E41: =IF(D41=0,0,MAX(1,ROUNDUP(D41/$D$5,0))) -> 30 | F41: D070 | G41: A015 | L41: =MAX($D$2-1,IFERROR(INDEX($N$11:$N$86,MATCH(F41,$A$11:$A$86,0)),0),IFERROR(INDEX($N$11:$N$86,MATCH(G41,$A$11:$A$86,0)),0),IFERROR(INDEX($N$11:$N$86,MATCH(H41,$A$11:$A$86,0)),0),IFERROR(INDEX($N$11:$N$86,MATCH(I41,$A$11:$A$86,0)),0),IFERROR(INDEX($N$11:$N$86,MATCH(J41,$A$11:$A$86,0)),0),IFERROR(INDEX($N$11:$N$86,MATCH(K41,$A$11:$A$86,0)),0)) -> 46386 | M41: =IF(E41=0,IF(COUNTA(F41:K41)=0,$D$2,L41),WORKDAY.INTL(L41,1,$D$3,'לוח שנה וחגים'!$F$5:$F$20)) -> 46387 | N41: =IF(E41=0,M41,WORKDAY.INTL(M41,E41-1,$D$3,'לוח שנה וחגים'!$F$5:$F$20)) -> 46428 | O41: ● | P41: קבלן
A42: K050 | B42: אישור קונסטרוקטור: השלד הושלם | C42: — | D42: 2 | E42: =IF(D42=0,0,MAX(1,ROUNDUP(D42/$D$5,0))) -> 2 | F42: K010 | G42: K020 | H42: K025 | I42: K030 | J42: K040 | L42: =MAX($D$2-1,IFERROR(INDEX($N$11:$N$86,MATCH(F42,$A$11:$A$86,0)),0),IFERROR(INDEX($N$11:$N$86,MATCH(G42,$A$11:$A$86,0)),0),IFERROR(INDEX($N$11:$N$86,MATCH(H42,$A$11:$A$86,0)),0),IFERROR(INDEX($N$11:$N$86,MATCH(I42,$A$11:$A$86,0)),0),IFERROR(INDEX($N$11:$N$86,MATCH(J42,$A$11:$A$86,0)),0),IFERROR(INDEX($N$11:$N$86,MATCH(K42,$A$11:$A$86,0)),0)) -> 46428 | M42: =IF(E42=0,IF(COUNTA(F42:K42)=0,$D$2,L42),WORKDAY.INTL(L42,1,$D$3,'לוח שנה וחגים'!$F$5:$F$20)) -> 46429 | N42: =IF(E42=0,M42,WORKDAY.INTL(M42,E42-1,$D$3,'לוח שנה וחגים'!$F$5:$F$20)) -> 46432 | O42: ● | P42: קבלן
...

Sheet לוח שנה וחגים
A1: לוח שנה וחגים – ישראל (תשפ"ז, נובמבר 2026 – יולי 2027)
A2: עמודה E ניתנת לעריכה: "כן" = יום שאינו יום עבודה בלוח; "לא" = יום עבודה (לעדכון לפי החלטת האתר). עמודה F מחושבת ומזינה את הגאנט. חגים עבריים חושבו בספריית לוח עברי ואומתו מול לוחות חב"ד ומשרד החינוך.
A4: תאריך | B4: יום | C4: חג / מועד | D4: סוג | E4: לא יום עבודה? (כן/לא) | F4: תאריך בלוח
A5: 46361 | B5: שבת | C5: חנוכה – נר ראשון (יום עבודה רגיל) | D5: חג – לא יום חופש | E5: לא | F5: =IF(E5="כן",A5,0) -> 0
A6: 46469 | B6: שלישי | C6: פורים (יום עבודה, ייתכנו היעדרויות) | D6: מועד – לא יום חופש חוקי | E6: לא | F6: =IF(E6="כן",A6,0) -> 0
A7: 46498 | B7: רביעי | C7: ערב פסח – עבודה עד אחה"צ | D7: ערב חג – יום קצר | E7: לא | F7: =IF(E7="כן",A7,0) -> 0
A8: 46499 | B8: חמישי | C8: פסח – יום ראשון | D8: חג – יום חופש | E8: כן | F8: =IF(E8="כן",A8,0) -> 46499
A9: 46500 | B9: שישי | C9: חול המועד פסח | D9: חול המועד – אתרים רבים סגורים | E9: כן | F9: =IF(E9="כן",A9,0) -> 46500
A10: 46501 | B10: שבת | C10: חול המועד פסח | D10: חול המועד – אתרים רבים סגורים | E10: כן | F10: =IF(E10="כן",A10,0) -> 46501
A11: 46502 | B11: ראשון | C11: חול המועד פסח | D11: חול המועד – אתרים רבים סגורים | E11: כן | F11: =IF(E11="כן",A11,0) -> 46502
A12: 46503 | B12: שני | C12: חול המועד פסח | D12: חול המועד – אתרים רבים סגורים | E12: כן | F12: =IF(E12="כן",A12,0) -> 46503
A13: 46504 | B13: שלישי | C13: חול המועד פסח | D13: חול המועד – אתרים רבים סגורים | E13: כן | F13: =IF(E13="כן",A13,0) -> 46504
A14: 46505 | B14: רביעי | C14: פסח – שביעי של פסח | D14: חג – יום חופש | E14: כן | F14: =IF(E14="כן",A14,0) -> 46505
A15: 46511 | B15: שלישי | C15: יום הזיכרון לשואה ולגבורה | D15: יום זיכרון – עבודה רגילה | E15: לא | F15: =IF(E15="כן",A15,0) -> 0
A16: 46518 | B16: שלישי | C16: יום הזיכרון לחללי צה"ל – עבודה עד אחה"צ | D16: יום זיכרון – יום קצר | E16: לא | F16: =IF(E16="כן",A16,0) -> 0
... A20: 46549 | B20: שישי | C20: שבועות | D20: חג – יום חופש | E20: כן | F20: =IF(E20="כן",A20,0) -> 46549
A22: הערות: שבת ושישי אינם ימי עבודה בלוח (ניתן לשנות בתא D3 בגיליון הראשי). ראש השנה, יום כיפור וסוכות (ספט׳–אוק׳ 2026) קודמים לתחילת הפרויקט. ראש השנה תשפ"ח – ספט׳ 2027, אחרי סיום הפרויקט. ראש השנה הסיני 6/2/2027 חל בשבת ואין לו השפעה על לוח הימים.

Sheet חוק התכנון והבנייה
A1: חוק התכנון והבנייה – שלבי היתר ותעודת גמר בלוח הזמנים
A3: # | B3: נושא | C3: התייחסות בלוח הזמנים
A4: 1 | B4: היתר בנייה | C4: תוספות בנייה (הגדלת מרפסת, פרגולה, חדר גלריה, כניסה ומדרגות) ושינויי חזית טעונים היתר מהוועדה המקומית (חיפה), בדרך כלל באמצעות מערכת "רישוי זמין". בלוח הוגדרה משימה A015 "היתר בנייה בתוקף" שמשכה 0 ימים (הנחה: ההיתר בידי המזמין לפני תחילת העבודה). אם טרם התקבל – יש להזין את משך הטיפול בעמודה D של A015, והעבודות הטעונות היתר (D055, K020, K025, K030, K040) יידחו בהתאם. משך הטיפול בפועל תלוי בוועדה (לרוב חודשים) ואינו מובטח.
A5: 2 | B5: עבודות פטורות מהיתר | C5: עבודות פנים שאינן משנות קונסטרוקציה או חזית (כגון חלוקה פנימית בגבס, ריצוף, טיח, צבע) עשויות להיות פטורות מהיתר לפי תקנות התכנון והבנייה (עבודה ושימוש הטעונים היתר). יש לאמת את הסיווג מול האדריכלית/המהנדס, במיוחד לגבי הריסת קירות נושאים, חיזוק גרם המדרגות ופירוק מסגרות בטון בחזית.
A6: 3 | B6: תנאי היתר ותשלומים | C6: אגרות בנייה והיטל השבחה (ככל שחלים) הן בדרך כלל תנאי לקבלת ההיתר ובאחריות המזמין; מינוי אחראי לביקורת על הביצוע (מהנדס/אדריכל) ותצהירי סיום נדרשים להגשת בקשה לתעודת גמר – כלולים בלוח כמשימה H055.
A7: 4 | B7: תעודת גמר (טופס 4) | C7: לאחר סיום העבודות מוגשת בקשה לתעודת גמר/טופס 4 לוועדה המקומית; האישור ניתן לאחר בדיקת מהנדס הרשות. חיבור קבע לחשמל ולמים מותנה לרוב באישור. טופס 4 מורכב ממעבר דו-שלבי (ללא אכלוס ועם אישור אכלוס) לפי נוהג הרשות. בלוח: H055 (הגשה – 10 ימים) ו-H070 (קבלה – הנחה של 30 ימי עבודה, אינה מחייבת). ברוב הרשויות נדרש טופס 4 גם לתוספת בנייה, אך יש לברר מול העירייה.
A8: 5 | B8: בטיחות בעבודה | C8: מבצע הבנייה ממנה מנהל עבודה רשום בתחילת העבודות ומעביר את פרטי המינוי למפקח העבודה האזורי (A016); תוכנית בטיחות נשמרת בפנקס הכללי באתר. פיגום נבדק על ידי בודק מוסמך לפני שימוש (X015). לפי מאמר של משרד עו"ד, תקנות בטיחות חדשות (עבודות בנייה, הדרכה, עבודה בגובה) אמורות להיכנס לתוקף ב-16.10.2026 – יש לוודא מול הנוסח הרשמי.
A9: 6 | B9: עיריית חיפה | C9: היתר להצבת פיגום ומכולת פסולת ברשות הרבים (A017, 10 ימי עבודה – הנחה). יש לבדוק מגבלות שעות עבודה ורעש מול העירייה לפני עבודה של 10–11 שעות ביום, כולל הפסקות צהריים.
A10: 7 | B10: פינוי פסולת | C10: פסולת הבנייה מפונה לאתר מורשה בצירוף אישורי פינוי (D065) – כלול בהצעת המחיר.
A11: 8 | B11: חיבור חשמל | C11: בקשה להגדלת חיבור ל-3×40 אמפר ופילר חדש (A020 – 40 ימי עבודה, הנחה; תלוי בחברת החשמל). בדיקת חשמלאי בודק וטופס/תעודת בדיקה נדרשים לפני חיבור קבע (H010).
A13: הערה: מסמך זה אינו ייעוץ משפטי; הדרישות נבדקו מול מקורות ציבוריים בלבד ויש לאמתן מול האדריכלית, המהנדס והוועדה המקומית.

Sheet שעות עבודה ופועלים
A1: שעות עבודה ופועלים סינים – הנחות ואזהרות
A3: # | B3: נושא | C3: פירוט
A4: 1 | B4: הנחת עבודה | C4: צוות פועלים סינים הרגיל ל-10–11 שעות ביום, א׳–ה׳. ב-10 שעות מקדם התפוקה 1.18 (לא 1.25 – עייפות ותפוקה שולית יורדת). ב-11 שעות מקדם משוער 1.27. אפשר לשנות את שעות העבודה בתא D4 בגיליון הראשי.
A5: 2 | B5: חוק שעות עבודה ומנוחה | C5: לפי חוק שעות עבודה ומנוחה: יום עבודה רגיל עד 8 שעות ושבוע רגיל של 42 שעות במגזר הפרטי; יום שלפני המנוחה השבועית – עד 7 שעות; מנוחה שבועית של 36 שעות רצופות. שעות מעבר ליום הרגיל הן שעות נוספות בתשלום מוגדל (125% ו-150%), והחוק מגביל את היקפן ודורש היתר/הסכם. 10 שעות ביום × 5 ימים = 50 שעות, כלומר 8 שעות נוספות בשבוע; 11 שעות × 5 = 55 שעות = 13 שעות נוספות. יש לאמת את התקרה השבועית ואת הצורך בהיתר מול משרד העבודה ויועץ משפטי לפני התחייבות ללוח זה.
A6: 3 | B6: עלות | C6: מחירי היחידה בהצעה אינם כוללים תוספת שעות נוספות. עבודה של 10–11 שעות ביום מייקרת את שעת העבודה (125%/150% על השעות מעבר ל-8) ומקצרת את הלוח; יש לבחון את הכדאיות הכוללת.
A7: 4 | B7: היתרי העסקה | C7: העסקת עובדים זרים בענף הבנייה מחייבת היתרי העסקה בתוקף (רשות האוכלוסין וההגירה), תנאי דיור, ביטוח ושכר – באחריות הקבלן ואינה כלולה בלוח.
A8: 5 | B8: ימי עבודה | C8: לוח השבוע: א׳–ה׳ (שישי ושבת – מנוחה). אם הצוות יעבוד גם בשישי, שנו את התא D3 ל-0000100 (שבת בלבד). ימי ערב חג ויום העצמאות/זיכרון מוגדרים בלוח השנה (ימים קצרים אינם מחושבים).
A9: 6 | B9: מזג אוויר חורפי | C9: משכי עבודות חוץ (פיגום, חזית, שבילים, עפר, גינון, מרפסות) הוגדלו ב-10% בגלל עונת הגשמים בחיפה (נובמבר–מרץ).
A10: 7 | B10: אחרים | C10: אלומיניום ודלתות מבוצעים על ידי אחרים (40 ימי עבודה, הנחה) ואינם בהיקף ההצעה; טיח חזית, אדנים ואיטום חלונות תלויים בהם. הלוח אינו כולל בריכה, פרפט/גג, נגרות. כל המשכים הם הנחות שיש לאמת מול מנהל העבודה וקבלני המשנה.
