Workbook

Sheet הצעת מחיר
A1: הצעת מחיר – שיפוץ ותוספות בבית ברחוב שלונסקי 53, חיפה
A2: מזמין: זהר מור יוסף ורמי דנה | קבלן: [שם הקבלן] | תאריך: 08/10/2026 | מס׳ הצעה: [__]
A3: כל הסכומים בש״ח, לפני מע״מ, בסיס מחירים אוקטובר 2026. מחירי היחידה כוללים הוצאות כלליות ורווח קבלן.
A5: מס׳ סעיף | B5: שם הסעיף | C5: תיאור | D5: יחידה | E5: כמות | F5: בסיס הכמות | G5: מחיר יחידה (₪) | H5: סה״כ (₪) | I5: הערות
A6: פרק 1 — הכנות והתארגנות לביצוע
A7: 01.01 | B7: התארגנות אתר | C7: התארגנות לביצוע עבודות השיפוץ, לרבות הקצאת אזורי עבודה ואחסון חומרים, הסדרת שירותים לעובדים ותיאום דרכי הגישה לעבודה, בהתאם לתנאי האתר ולהנחיות המתכננת. סעיף זה אינו כולל את הגידור, החיבורים הזמניים, ההגנות ומכולת הפסולת המפורטים בנפרד. | D7: קומפ׳ | E7: 1 | F7: לפי המסמכים | G7: 9200 | H7: =ROUND(E7*G7,2) -> 9200
A8: 01.02 | B8: גידור, שילוט ואמצעי בטיחות באתר | C8: הקמה והחזקה של גידור זמני מפח או מרשת תקנית, שילוט אתר ואזהרה, סימון אזורים מסוכנים ואמצעי הבטיחות הנדרשים, לאורך כל שלבי הביצוע, לרבות פירוק הגידור בתום הצורך. | D8: קומפ׳ | E8: 1 | F8: לפי המסמכים | G8: 4600 | H8: =ROUND(E8*G8,2) -> 4600
A9: 01.03 | B9: חיבור מים זמני | C9: הסדרת חיבור מים זמני לצורכי ביצוע העבודות, לרבות חיבור למקור המים המאושר באתר ובדיקת תקינות החיבור. | D9: קומפ׳ | E9: 1 | F9: לפי המסמכים | G9: 1725 | H9: =ROUND(E9*G9,2) -> 1725
A10: 01.04 | B10: חיבור חשמל זמני | C10: הסדרת חיבור חשמל זמני לצורכי ביצוע העבודות, באמצעות חשמלאי בעל רישיון מתאים, לרבות אמצעי ההגנה הנדרשים ובדיקת תקינות החיבור. | D10: קומפ׳ | E10: 1 | F10: לפי המסמכים | G10: 3450 | H10: =ROUND(E10*G10,2) -> 3450
A11: 01.05 | B11: הגנה על אלמנטים קיימים | C11: ביצוע והחזקה של כיסויי הגנה לאלמנטים המיועדים להישאר, לרבות ריצופים, פתחים, חלונות, מדרגות, מעקות, קירות, ציוד וצמחייה לשימור, בהתאם להיקף העבודה ולמצב הקיים. | D11: קומפ׳ | E11: 1 | F11: לפי המסמכים | G11: 5750 | H11: =ROUND(E11*G11,2) -> 5750
A12: 01.06 | B12: מדידות, אימות וסימון בלייזר | C12: מדידת המבנה הקיים ואימות המידות מול תוכניות האדריכלות והמערכות, סימון מיקומי העבודות ומפלסי הביצוע באמצעות פלס לייזר, תיעוד המצב הקיים ודיווח על אי־התאמות לפני תחילת העבודה. | D12: קומפ׳ | E12: 1 | F12: לפי המסמכים | G12: 3450 | H12: =ROUND(E12*G12,2) -> 3450
A13: 01.07 | B13: מכולת פסולת והסדרת אזור ריכוז פסולת | C13: הצבת מכולת פסולת והסדרת מקום לריכוז פסולת הבנייה באתר, בהתאם לתנאי הגישה ולשלבי הביצוע. פינוי הפסולת לאתר מורשה מפורט בפרק ההריסות. | D13: קומפ׳ | E13: 1 | F13: לפי המסמכים | G13: 10350 | H13: =ROUND(E13*G13,2) -> 10350
A14: 01.08 | B14: ניקיון שוטף בתקופת הביצוע | C14: ניקיון שוטף של שטחי העבודה והמעברים לאורך תקופת הביצוע, איסוף שאריות חומרים וריכוז הפסולת באזור המיועד לכך, לשמירת אתר מסודר ובטוח. | D14: קומפ׳ | E14: 1 | F14: לפי המסמכים | G14: 10350 | H14: =ROUND(E14*G14,2) -> 10350
A15: 01.09 | B15: פיגום חיצוני לחזיתות | C15: הקמה, שכירות לתקופה, תחזוקה ופירוק של פיגום חיצוני תקני בהיקף החזיתות, לצורך ניסור ופירוק מסגרות הבטון הדקורטיביות, עבודות הפרפט וטיח החזיתות. כולל הגנות, רשת, אישור בודק ופיגום תקני לפי תקנות הבטיחות בעבודה. | D15: מ״ר | E15: 225 | F15: זמנית – תימדד בפועל | G15: 98 | H15: =ROUND(E15*G15,2) -> 22050 | I15: כולל שכירות כ-4.5 חודשים
A16: סה״כ פרק 1 — הכנות והתארגנות לביצוע | H16: =SUM(H7:H15) -> 70925
A18: פרק 2 — הריסות, פירוקים ופינוי
A19: 02.01 | B19: פירוק קירות ומחיצות במרתף | C19: הריסה מבוקרת של כל הקירות והמחיצות המסומנים להריסה בקומת המרתף, בהתאם לתוכנית ההריסה: 10 מ״ר קירות בלוקים ו־52 מ״ר מחיצות גבס. אלמנטים נושאים – רק באישור קונסטרוקטור בכתב. | D19: מ״ר | E19: 62 | F19: לפי המסמכים | G19: 138 | H19: =ROUND(E19*G19,2) -> 8556
A20: 02.02 | B20: פירוק קירות ומחיצות בקומת הקרקע | C20: הריסה ופירוק מבוקרים של כל הקירות והמחיצות (בלוקים, בטון וגבס) המסומנים להריסה בקומת הקרקע, בהתאם לתוכנית ההריסה. קירות בטון ואלמנטים נושאים – רק לאחר אישור הקונסטרוקטור בכתב. | D20: מ״ר | E20: 51 | F20: לפי המסמכים | G20: 138 | H20: =ROUND(E20*G20,2) -> 7038
A21: 02.03 | B21: פירוק קירות ומחיצות בקומה א׳ | C21: הריסה ופירוק מבוקרים של כל הקירות והמחיצות (בלוקים, בטון וגבס) המסומנים להריסה בקומה א׳, בהתאם לתוכנית ההריסה (כמות משוערת לפי התוכנית). קירות בטון ואלמנטים נושאים – רק לאחר אישור הקונסטרוקטור בכתב. | D21: מ״ר | E21: 85 | F21: לפי המסמכים | G21: 138 | H21: =ROUND(E21*G21,2) -> 11730
A22: 02.04 | B22: פירוק תקרות גבס קיימות | C22: פירוק תקרות גבס קיימות המיועדות להסרה, לרבות לוחות, פרופילים ומתלים, בתיאום עם בעלי המקצוע ולאחר ניתוק המערכות הרלוונטיות. | D22: מ״ר | E22: 10 | F22: לפי המסמכים | G22: 57 | H22: =ROUND(E22*G22,2) -> 570
A23: 02.05 | B23: פירוק ריצופים קיימים | C23: פירוק ריצופים קיימים באזורים שיאושרו לביצוע, בהתאם להחלטה משותפת בשטח ובהתחשב במצב הריצוף הקיים. היקף הפירוק ייקבע לפני תחילת העבודה. | D23: מ״ר | E23: 40 | F23: לפי המסמכים | G23: 103 | H23: =ROUND(E23*G23,2) -> 4120
A24: 02.06 | B24: פירוק ארונות מטבח קיימים | C24: פירוק ארונות מטבח קיימים, לרבות יחידות הארונות ורכיבי החיבור שלהן למבנה, בתיאום עם המזמין לגבי פריטים המיועדים לשימור. | D24: קומפ׳ | E24: 1 | F24: לפי המסמכים | G24: 2300 | H24: =ROUND(E24*G24,2) -> 2300
A25: 02.07 | B25: פירוק ארונות ונגרות קיימת אחרת | C25: פירוק ארונות הלבשה ופריטי נגרות קיימים אחרים המיועדים להסרה, לרבות רכיבי החיבור למבנה, בהתאם להחלטת המזמין בדבר שימור או פינוי. | D25: יח׳ | E25: 1 | F25: לפי המסמכים | G25: 2875 | H25: =ROUND(E25*G25,2) -> 2875
A26: 02.08 | B26: פירוק חלונות אלומיניום ותריסים קיימים – קומפלט | C26: פירוק כל החלונות והתריסים הקיימים המיועדים להחלפה לפי תוכנית הבנייה, לרבות כנפיים, זיגוג, מסגרות, רכיבי הפעלה ועיגון, וניתוק הזנת תריסים חשמליים, תוך שמירה על הפתח. | D26: קומפ׳ | E26: 1 | F26: לפי המסמכים | G26: 6900 | H26: =ROUND(E26*G26,2) -> 6900
A27: 02.09 | B27: פירוק דלתות פנים וכניסה ומשקופים – קומפלט | C27: פירוק כל הדלתות המסומנות בתוכניות ההריסה, לרבות כנפיים, משקופים ופרזול, ובתיאום הסדרת הגישה למבנה במהלך הביצוע. | D27: קומפ׳ | E27: 1 | F27: לפי המסמכים | G27: 4025 | H27: =ROUND(E27*G27,2) -> 4025
A28: 02.10 | B28: פירוק חדרי רחצה, שירותים וכלים סניטריים – קומפלט | C28: פירוק מלא של חדרי הרחצה והשירותים הקיימים: אסלות, כיורים, אמבטיות, מקלחונים, ברזים וחיפויי קירות, לרבות ניתוק וסגירת חיבורי מים וביוב, בהתאם לתוכניות ההריסה. | D28: קומפ׳ | E28: 1 | F28: לפי המסמכים | G28: 9200 | H28: =ROUND(E28*G28,2) -> 9200
A29: 02.11 | B29: פירוק נקודות, אביזרי חשמל וגופי תאורה קיימים | C29: ניתוק ופירוק נקודות, שקעים, מפסקים וגופי תאורה קיימים המיועדים לביטול או להחלפה, באמצעות חשמלאי בעל רישיון מתאים, בתיאום עם המזמין לגבי פריטים לשימור. | D29: קומפ׳ | E29: 1 | F29: לפי המסמכים | G29: 4600 | H29: =ROUND(E29*G29,2) -> 4600
A30: 02.12 | B30: פירוק צנרת אינסטלציה גלויה קיימת | C30: ניתוק ופירוק צנרת אינסטלציה גלויה המיועדת להסרה, לרבות אביזרי החיבור והקיבוע הרלוונטיים, לאחר זיהוי הקווים הפעילים וסגירת החיבורים הנדרשים. | D30: קומפ׳ | E30: 1 | F30: לפי המסמכים | G30: 3450 | H30: =ROUND(E30*G30,2) -> 3450
... A39: 02.21 | B39: פירוק דשא וצמחיית גינון | C39: פירוק וכריתת דשא, שיחים וצמחיית גינון קיימת בשטחי הפיתוח, כולל עקירת שורשים, העמסה והובלה לאתר מורשה, ללא עצים בוגרים הטעונים אישור. | D39: מ״ר | E39: 65 | F39: זמנית – תימדד בפועל | G39: 40 | H39: =ROUND(E39*G39,2) -> 2600
A40: סה״כ פרק 2 — הריסות, פירוקים ופינוי | H40: =SUM(H19:H39) -> 137689
A42: פרק 3 — בנייה ותוספות מבניות
A43: 03.01 | B43: הגדלת מרפסת הסלון ותוספת פרגולה | C43: ביצוע הגדלת מרפסת הסלון ותוספת הפרגולה, קומפלט בתחום העבודות המבניות ובהתאם לתוכניות ולמפרט הקונסטרוקטור, לרבות ביסוס, רכיבי בטון וזיון, שלד פלדה מפרופילי RHS, לוחות בסיס, עיגונים, חיבורים וריתוכים, ככל שנדרשים בתכנון. העבודה כוללת את הבדיקות, אישורי הביצוע ותוכנית העדות הנדרשים במפרט. עבודות האיטום והגמר יבוצעו במסגרת הפרקים הייעודיים. | D43: קומפ׳ | E43: 1 | F43: אומדן – לפי קונסטרוקטור | G43: 80500 | H43: =ROUND(E43*G43,2) -> 80500 | I43: סכום זמני עד קבלת תוכניות
A44: 03.02 | B44: תוספת חדר בקומת הגלריה | C44: ביצוע העבודות המבניות לתוספת החדר בקומת הגלריה, קומפלט לפי תוכניות הקונסטרוקטור והאדריכלות, לרבות רכיבי השלד, החיבורים והעיגונים למבנה הקיים, פתחים והכנות מבניות למערכות, בהתאם לתכנון. העבודה כוללת בדיקות, אישורים ותוכנית עדות; גמרים ומערכות מפורטים בפרקים הייעודיים. | D44: קומפ׳ | E44: 1 | F44: אומדן – לפי קונסטרוקטור | G44: 138000 | H44: =ROUND(E44*G44,2) -> 138000 | I44: סכום זמני עד קבלת תוכניות
A45: 03.03 | B45: כניסה חדשה וגרם מדרגות חדש | C45: ביצוע העבודות המבניות לכניסה החדשה ולגרם המדרגות החדש, קומפלט לפי תוכניות הקונסטרוקטור והאדריכלות, לרבות ביסוס, רכיבי השלד, זיון, יציקות, חיבורים ועיגונים, וכן אלמנטי מעקה ככל שנכללים בתכנון המבני. גמרים יבוצעו במסגרת הפרקים הייעודיים. | D45: קומפ׳ | E45: 1 | F45: אומדן – לפי קונסטרוקטור | G45: 43700 | H45: =ROUND(E45*G45,2) -> 43700 | I45: סכום זמני עד קבלת תוכניות
A46: 03.04 | B46: חיזוק גרם המדרגות הפנימי הקיים | C46: חיזוק גרם המדרגות הפנימי לאחר פירוק המעקה הקיים, קומפלט לפי פרטי הקונסטרוקטור, לרבות רכיבי החיזוק, החיבורים והעיגונים המוגדרים בתכנון, בדיקות וקבלת אישור הקונסטרוקטור לביצוע. | D46: קומפ׳ | E46: 1 | F46: אומדן – לפי קונסטרוקטור | G46: 20700 | H46: =ROUND(E46*G46,2) -> 20700 | I46: סכום זמני עד קבלת תוכניות
A47: סה״כ פרק 3 — בנייה ותוספות מבניות | H47: =SUM(H43:H46) -> 282900
A49: פרק 4 — חלוקה חדשה בקירות בלוקים
A50: 04.01 | B50: קירות בלוקים במרתף | C50: בניית קירות בלוקים בעובי 20 ס״מ בקומת המרתף, במיקומים המסומנים בתוכנית הבנייה החדשה, בהתאם לפרטי הקונסטרוקטור, לרבות חומרי החיבור, חיבור למבנה הקיים ורכיבי זיון או חיזוק ככל שנדרשים בפרטים. טיח וגמר אינם כלולים בסעיף זה. | D50: מ״ר | E50: 6.3 | F50: לפי המסמכים | G50: 345 | H50: =ROUND(E50*G50,2) -> 2173.5
A51: 04.02 | B51: קירות בלוקים בקומת הקרקע | C51: בניית קירות בלוקים בעובי 20 ס״מ בקומת הקרקע, במיקומים המסומנים בתוכנית הבנייה החדשה, בהתאם לפרטי הקונסטרוקטור, לרבות חומרי החיבור, חיבור למבנה הקיים ורכיבי זיון או חיזוק ככל שנדרשים בפרטים. טיח וגמר אינם כלולים בסעיף זה. | D51: מ״ר | E51: 17.7 | F51: לפי המסמכים | G51: 345 | H51: =ROUND(E51*G51,2) -> 6106.5
A52: 04.03 | B52: קירות בלוקים בקומה א׳ ובגלריה | C52: בניית קירות בלוקים בעובי 20 ס״מ בקומה א׳ ובגלריה, במיקומים המסומנים בתוכנית הבנייה החדשה, בהתאם לפרטי הקונסטרוקטור, לרבות חומרי החיבור, חיבור למבנה הקיים ורכיבי זיון או חיזוק ככל שנדרשים בפרטים. טיח וגמר אינם כלולים בסעיף זה. | D52: מ״ר | E52: 2.08 | F52: לפי המסמכים | G52: 345 | H52: =ROUND(E52*G52,2) -> 717.6
...

Sheet סיכום
A1: סיכום הצעת מחיר
A3: פרק | B3: סכום (₪)
A4: 1. הכנות והתארגנות לביצוע | B4: ='הצעת מחיר'!H16 -> 70925
A5: 2. הריסות, פירוקים ופינוי | B5: ='הצעת מחיר'!H40 -> 137689
A6: 3. בנייה ותוספות מבניות | B6: ='הצעת מחיר'!H47 -> 282900
A7: 4. חלוקה חדשה בקירות בלוקים | B7: ='הצעת מחיר'!H53 -> 8997.6
A8: 5. אינסטלציה, התקנת כלים סניטריים וברזים | B8: ='הצעת מחיר'!H89 -> 157375
A9: 6. חשמל | B9: ='הצעת מחיר'!H107 -> 112359
A10: 7. תאורה ומפסקי תאורה | B10: ='הצעת מחיר'!H130 -> 103006
A11: 8. מיזוג אוויר | B11: ='הצעת מחיר'!H137 -> 31055
A12: 9. מחיצות ותקרות גבס | B12: ='הצעת מחיר'!H144 -> 70741.7
A13: 10. איטום פנים | B13: ='הצעת מחיר'!H151 -> 43027.5
A14: 11. איטום גג ופרפט | B14: ='הצעת מחיר'!H159 -> 93550
A15: 12. אדני חלונות וספי פתחים | B15: ='הצעת מחיר'!H166 -> 34462.73
A16: 13. ריצופים, חיפויים ופנלים | B16: ='הצעת מחיר'!H175 -> 278823.7
A17: 14. טיח וגמר צבעוני חוץ | B17: ='הצעת מחיר'!H181 -> 63425
A18: 15. תיקוני טיח, שפכטל וצבע פנים | B18: ='הצעת מחיר'!H187 -> 66240
A19: 17. פיתוח חוץ | B19: ='הצעת מחיר'!H195 -> 87240
A20: 18. תשתיות תקשורת, מיגון, אינטרקום ושמע | B20: ='הצעת מחיר'!H203 -> 26462
A21: סה״כ לפני הנחה | B21: =SUM(B4:B20) -> 1668279.2
A22: הנחה | B22: =-ROUND(B21*C22,2) -> -417069.81 | C22: 0.25
A23: סה״כ לאחר הנחה, לפני מע״מ | B23: =B21+B22 -> 1251209.4
A24: מע״מ | B24: =ROUND(B23*C24,2) -> 225217.7 | C24: 0.18
A25: סה״כ כולל מע״מ | B25: =B23+B24 -> 1476427.1

Sheet הערות והחרגות
A1: # | B1: סוג | C1: הערה
A2: 1 | B2: בסיס | C2: ההצעה מבוססת על: ספר מפרט טכני מהדורה 20 (06/07/2026); תוכניות אדריכלות "בנייה חדשה" – קרקע (גיליון 13) וקומה א׳ (גיליון 23) מ-17/09/2026; כתב הכמויות לקבלן מ-24/09/2026; וכתב הכמויות של המזמין. בכל מקום שבו המסמכים סותרים נלקח כתב הכמויות מ-24/09/2026.
A3: 2 | B3: כמויות | C3: סעיפים המסומנים "זמנית – תימדד בפועל" אינם כוללים כמות במסמכים שהתקבלו (מיזוג, מפסקים, תאורת חירום, דודים, נקודות חיבור ישיר, נקודות תקשורת, גג ופרפט, פיגומים). הם מתומחרים לפי כמות משוערת ויימדדו בפועל.
A4: 3 | B4: שלד | C4: פרק 3 (מרפסת ופרגולה, חדר גלריה, כניסה ומדרגות, חיזוק גרם המדרגות) הוא סכום זמני. תוכניות הקונסטרוקטור המלאות לא התקבלו, והמחיר יותאם עם קבלתן.
A5: 4 | B5: פיגום | C5: סעיף 01.09 – פיגום חיצוני לניסור המסגרות הדקורטיביות, לפרפט ולטיח החזיתות. כולל שכירות לכ-4.5 חודשים לפי לוח הזמנים.
A6: 5 | B6: אספקה | C6: כלים סניטריים וברזים, גופי תאורה, יחידות מיזוג, דודים ואריחי ריצוף וחיפוי – אספקה על המזמין, והקבלן מתקין. אלומיניום, דלתות, שערים, תריסים ואדני אבן – אספקה והתקנה.
A7: 6 | B7: החרגות | C7: בריכת שחייה (כל העבודות), נגרות (ארונות מטבח, רחצה והלבשה), ריהוט, אגרות והיתרים, שכר יועצים, והיטלי חברת החשמל להגדלת החיבור.
A8: 7 | B8: החרגות | C8: פריטים התלויים בהחלטות המזמין: תריסים חשמליים (אופציה), סוגי צמחייה, דגמים סופיים.
A9: 8 | B9: בדיקות | C9: הבדיקות והאישורים הנדרשים (קונסטרוקטור, יועץ איטום, חשמלאי בודק, בדיקות הצפה) כלולים לפי המפרט.
A10: 9 | B10: מסחרי | C10: תוקף ההצעה: [__ ימים] | תנאי תשלום: [__] | הצמדה: [__]
A11: 10 | B11: הנחה | C11: הנחה של 25% על סך ההצעה מוצגת בגיליון הסיכום.

Sheet לוח זמנים
A1: שלב | B1: התחלה | C1: סיום
A2: התקשרות והזמנות | B2: 46327 | C2: 46327
A3: התארגנות ואישור להריסות | B3: 46328 | C3: 46341
A4: הריסות ופירוקים | B4: 46342 | C4: 46369
A5: פיגום חיצוני – הקמה ופירוק | B5: 46342 | C5: 46475
A6: שלד ותוספות מבניות | B6: 46370 | C6: 46420
A7: גג ופרפט | B7: 46370 | C7: 46405
A8: תשתיות אינסטלציה, חשמל, מיזוג ותקשורת ובדיקות | B8: 46376 | C8: 46406
A9: גבס ואיטום | B9: 46407 | C9: 46448
A10: חזיתות ופיתוח | B10: 46421 | C10: 46484
A11: גמרי פנים (ריצוף, טיח, צבע, התקנות) | B11: 46422 | C11: 46525
A12: בדיקות והכנה למסירה | B12: 46526 | C12: 46546
A13: מסירה | B13: 46546 | C13: 46546
A15: לוח זמנים מנחה: שבוע עבודה א׳–ה׳, תחילת עבודה 01/11/2026. ללא חגים ועיכובי מזג אוויר. משך כולל כ-31 שבועות.
