Workbook

Sheet הצעת מחיר
A1: הצעת מחיר – שיפוץ ותוספות בבית ברחוב שלונסקי 53, חיפה
A2: מחירים בש״ח לפני מע״מ, בסיס מחירים אוקטובר 2026. מחירי היחידה הם אומדן (ראו גיליונות "בסיס תמחור" ו"סקר שוק"). כמויות זמניות מסומנות ויתומדו לפי מדידה בפועל.
A4: מס׳ סעיף | B4: שם הסעיף | C4: תיאור סעיף | D4: יחידה | E4: כמות (מהמסמכים) | F4: כמות זמנית (הנחה) | G4: מחיר יחידה (₪) | H4: סה״כ (₪) | I4: הערות
A5: פרק 01 — הכנות והתארגנות לביצוע
A6: 01.01 | B6: התארגנות אתר | C6: התארגנות לביצוע עבודות השיפוץ, לרבות הקצאת אזורי עבודה ואחסון חומרים, הסדרת שירותים לעובדים ותיאום דרכי הגישה לעבודה, בהתאם לתנאי האתר ולהנחיות המתכננת. סעיף זה אינו כולל את הגידור, החיבורים הזמניים, ההגנות ומכולת הפסולת המפורטים בנפרד. | D6: קומפ׳ | E6: 1 | G6: 8000 | H6: =ROUND(IF(ISNUMBER(E6),E6,N(F6))*G6,2) -> 8000
A7: 01.02 | B7: גידור, שילוט ואמצעי בטיחות באתר | C7: הקמה והחזקה של גידור זמני מפח או מרשת תקנית, שילוט אתר ואזהרה, סימון אזורים מסוכנים ואמצעי הבטיחות הנדרשים, לאורך כל שלבי הביצוע, לרבות פירוק הגידור בתום הצורך. | D7: קומפ׳ | E7: 1 | G7: 4000 | H7: =ROUND(IF(ISNUMBER(E7),E7,N(F7))*G7,2) -> 4000
A8: 01.03 | B8: חיבור מים זמני | C8: הסדרת חיבור מים זמני לצורכי ביצוע העבודות, לרבות חיבור למקור המים המאושר באתר ובדיקת תקינות החיבור. | D8: קומפ׳ | E8: 1 | G8: 1500 | H8: =ROUND(IF(ISNUMBER(E8),E8,N(F8))*G8,2) -> 1500
A9: 01.04 | B9: חיבור חשמל זמני | C9: הסדרת חיבור חשמל זמני לצורכי ביצוע העבודות, באמצעות חשמלאי בעל רישיון מתאים, לרבות אמצעי ההגנה הנדרשים ובדיקת תקינות החיבור. | D9: קומפ׳ | E9: 1 | G9: 3000 | H9: =ROUND(IF(ISNUMBER(E9),E9,N(F9))*G9,2) -> 3000
A10: 01.05 | B10: הגנה על אלמנטים קיימים | C10: ביצוע והחזקה של כיסויי הגנה לאלמנטים המיועדים להישאר, לרבות ריצופים, פתחים, חלונות, מדרגות, מעקות, קירות, ציוד וצמחייה לשימור, בהתאם להיקף העבודה ולמצב הקיים. | D10: קומפ׳ | E10: 1 | G10: 5000 | H10: =ROUND(IF(ISNUMBER(E10),E10,N(F10))*G10,2) -> 5000
A11: 01.06 | B11: מדידות, אימות וסימון בלייזר | C11: מדידת המבנה הקיים ואימות המידות מול תוכניות האדריכלות והמערכות, סימון מיקומי העבודות ומפלסי הביצוע באמצעות פלס לייזר, תיעוד המצב הקיים ודיווח על אי־התאמות לפני תחילת העבודה. | D11: קומפ׳ | E11: 1 | G11: 3000 | H11: =ROUND(IF(ISNUMBER(E11),E11,N(F11))*G11,2) -> 3000
A12: 01.07 | B12: מכולת פסולת והסדרת אזור ריכוז פסולת | C12: הצבת מכולת פסולת והסדרת מקום לריכוז פסולת הבנייה באתר, בהתאם לתנאי הגישה ולשלבי הביצוע. פינוי הפסולת לאתר מורשה מפורט בפרק ההריסות. | D12: קומפ׳ | E12: 1 | G12: 9000 | H12: =ROUND(IF(ISNUMBER(E12),E12,N(F12))*G12,2) -> 9000
A13: 01.08 | B13: ניקיון שוטף בתקופת הביצוע | C13: ניקיון שוטף של שטחי העבודה והמעברים לאורך תקופת הביצוע, איסוף שאריות חומרים וריכוז הפסולת באזור המיועד לכך, לשמירת אתר מסודר ובטוח. | D13: קומפ׳ | E13: 1 | G13: 9000 | H13: =ROUND(IF(ISNUMBER(E13),E13,N(F13))*G13,2) -> 9000
A14: 01.09 | B14: פיגום חיצוני לחזיתות | C14: הקמה, שכירות לתקופה, תחזוקה ופירוק של פיגום חיצוני תקני בהיקף החזיתות, לצורך ניסור ופירוק מסגרות הבטון הדקורטיביות, עבודות הפרפט וטיח החזיתות. כולל הגנות, רשת, אישור בודק ופיגום תקני לפי תקנות הבטיחות בעבודה. | D14: מ״ר | F14: 225 | G14: 85 | H14: =ROUND(IF(ISNUMBER(E14),E14,N(F14))*G14,2) -> 19125 | I14: כמות זמנית = שטח טיח החזיתות; כולל שכירות לכ-4.5 חודשים לפי לוח הזמנים; כמות זמנית: שטח חזיתות מטויחות (14.01); לאימות במדידה – תחשיב לפי מדידה בפועל
A15: סה״כ פרק 01 — הכנות והתארגנות לביצוע | H15: =SUM(H6:H14) -> 61625
A17: פרק 02 — הריסות, פירוקים ופינוי
A18: 02.01 | B18: פירוק קירות ומחיצות במרתף | C18: הריסה מבוקרת של כל הקירות והמחיצות המסומנים להריסה בקומת המרתף, בהתאם לתוכנית ההריסה: 10 מ״ר קירות בלוקים ו־52 מ״ר מחיצות גבס. אלמנטים נושאים – רק באישור קונסטרוקטור בכתב. | D18: מ״ר | E18: 62 | G18: 120 | H18: =ROUND(IF(ISNUMBER(E18),E18,N(F18))*G18,2) -> 7440
A19: 02.02 | B19: פירוק קירות ומחיצות בקומת הקרקע | C19: הריסה ופירוק מבוקרים של כל הקירות והמחיצות (בלוקים, בטון וגבס) המסומנים להריסה בקומת הקרקע, בהתאם לתוכנית ההריסה. קירות בטון ואלמנטים נושאים – רק לאחר אישור הקונסטרוקטור בכתב. | D19: מ״ר | E19: 51 | G19: 120 | H19: =ROUND(IF(ISNUMBER(E19),E19,N(F19))*G19,2) -> 6120
A20: 02.03 | B20: פירוק קירות ומחיצות בקומה א׳ | C20: הריסה ופירוק מבוקרים של כל הקירות והמחיצות (בלוקים, בטון וגבס) המסומנים להריסה בקומה א׳, בהתאם לתוכנית ההריסה (כמות משוערת לפי התוכנית). קירות בטון ואלמנטים נושאים – רק לאחר אישור הקונסטרוקטור בכתב. | D20: מ״ר | E20: 85 | G20: 120 | H20: =ROUND(IF(ISNUMBER(E20),E20,N(F20))*G20,2) -> 10200
A21: 02.04 | B21: פירוק תקרות גבס קיימות | C21: פירוק תקרות גבס קיימות המיועדות להסרה, לרבות לוחות, פרופילים ומתלים, בתיאום עם בעלי המקצוע ולאחר ניתוק המערכות הרלוונטיות. | D21: מ״ר | E21: 10 | G21: 50 | H21: =ROUND(IF(ISNUMBER(E21),E21,N(F21))*G21,2) -> 500
A22: 02.05 | B22: פירוק ריצופים קיימים | C22: פירוק ריצופים קיימים באזורים שיאושרו לביצוע, בהתאם להחלטה משותפת בשטח ובהתחשב במצב הריצוף הקיים. היקף הפירוק ייקבע לפני תחילת העבודה. | D22: מ״ר | E22: 40 | G22: 90 | H22: =ROUND(IF(ISNUMBER(E22),E22,N(F22))*G22,2) -> 3600
A23: 02.06 | B23: פירוק ארונות מטבח קיימים | C23: פירוק ארונות מטבח קיימים, לרבות יחידות הארונות ורכיבי החיבור שלהן למבנה, בתיאום עם המזמין לגבי פריטים המיועדים לשימור. | D23: קומפ׳ | E23: 1 | G23: 2000 | H23: =ROUND(IF(ISNUMBER(E23),E23,N(F23))*G23,2) -> 2000
A24: 02.07 | B24: פירוק ארונות ונגרות קיימת אחרת | C24: פירוק ארונות הלבשה ופריטי נגרות קיימים אחרים המיועדים להסרה, לרבות רכיבי החיבור למבנה, בהתאם להחלטת המזמין בדבר שימור או פינוי. | D24: יח׳ | E24: 1 | G24: 2500 | H24: =ROUND(IF(ISNUMBER(E24),E24,N(F24))*G24,2) -> 2500
A25: 02.08 | B25: פירוק חלונות אלומיניום ותריסים קיימים – קומפלט | C25: פירוק כל החלונות והתריסים הקיימים המיועדים להחלפה לפי תוכנית הבנייה, לרבות כנפיים, זיגוג, מסגרות, רכיבי הפעלה ועיגון, וניתוק הזנת תריסים חשמליים, תוך שמירה על הפתח. | D25: קומפ׳ | E25: 1 | G25: 6000 | H25: =ROUND(IF(ISNUMBER(E25),E25,N(F25))*G25,2) -> 6000
A26: 02.09 | B26: פירוק דלתות פנים וכניסה ומשקופים – קומפלט | C26: פירוק כל הדלתות המסומנות בתוכניות ההריסה, לרבות כנפיים, משקופים ופרזול, ובתיאום הסדרת הגישה למבנה במהלך הביצוע. | D26: קומפ׳ | E26: 1 | G26: 3500 | H26: =ROUND(IF(ISNUMBER(E26),E26,N(F26))*G26,2) -> 3500
A27: 02.10 | B27: פירוק חדרי רחצה, שירותים וכלים סניטריים – קומפלט | C27: פירוק מלא של חדרי הרחצה והשירותים הקיימים: אסלות, כיורים, אמבטיות, מקלחונים, ברזים וחיפויי קירות, לרבות ניתוק וסגירת חיבורי מים וביוב, בהתאם לתוכניות ההריסה. | D27: קומפ׳ | E27: 1 | G27: 8000 | H27: =ROUND(IF(ISNUMBER(E27),E27,N(F27))*G27,2) -> 8000
A28: 02.11 | B28: פירוק נקודות, אביזרי חשמל וגופי תאורה קיימים | C28: ניתוק ופירוק נקודות, שקעים, מפסקים וגופי תאורה קיימים המיועדים לביטול או להחלפה, באמצעות חשמלאי בעל רישיון מתאים, בתיאום עם המזמין לגבי פריטים לשימור. | D28: קומפ׳ | E28: 1 | G28: 4000 | H28: =ROUND(IF(ISNUMBER(E28),E28,N(F28))*G28,2) -> 4000
A29: 02.12 | B29: פירוק צנרת אינסטלציה גלויה קיימת | C29: ניתוק ופירוק צנרת אינסטלציה גלויה המיועדת להסרה, לרבות אביזרי החיבור והקיבוע הרלוונטיים, לאחר זיהוי הקווים הפעילים וסגירת החיבורים הנדרשים. | D29: קומפ׳ | E29: 1 | G29: 3000 | H29: =ROUND(IF(ISNUMBER(E29),E29,N(F29))*G29,2) -> 3000
... A31: 02.14 | B31: פירוק מעקה גרם המדרגות הפנימי | C31: פירוק זהיר ומבוקר של המעקה הקיים בגרם המדרגות הפנימי, בהתאם להנחיות הקונסטרוקטור ולאישורו בכתב. חיזוק גרם המדרגות מתואר בנפרד בפרק הבנייה. | D31: קומפ׳ | E31: 1 | G31: 2000 | H31: =ROUND(IF(ISNUMBER(E31),E31,N(F31))*G31,2) -> 2000
A32: 02.15 | B32: ניסור ופירוק מסגרות בטון דקורטיביות סביב חלונות | C32: ניסור ופירוק מבוקר של מסגרות הבטון הדקורטיביות סביב פתחי החלונות בחזיתות, בהתאם להנחיות ולאישור הקונסטרוקטור, עד להסרת הבליטות והכנת האזור להשלמת גמר חזית אחיד. עבודות הטיח והגמר מתוארות בפרק טיח החוץ. | D32: מ״א | E32: 45 | G32: 170 | H32: =ROUND(IF(ISNUMBER(E32),E32,N(F32))*G32,2) -> 7650 | I32: הניסור מבוצע מפיגום (01.09) ובאישור קונסטרוקטור בכתב
A33: 02.16 | B33: מיון ופינוי פסולת לאתר מורשה | C33: מיון פסולת ההריסה והפירוק לפי סוגי החומרים, העמסה והובלה לאתר מורשה, לרבות מסירת אישורי הפינוי הנדרשים. | D33: קומפ׳ | E33: 1 | G33: 28000 | H33: =ROUND(IF(ISNUMBER(E33),E33,N(F33))*G33,2) -> 28000
A34: 02.17 | B34: ניקיון יסודי לאחר ההריסות | C34: ניקיון יסודי של שטחי ההריסה והפירוק לאחר השלמתם, הסרת שאריות וריכוז פסולת שנותרה, והכנת השטחים לתחילת עבודות הבנייה. | D34: קומפ׳ | E34: 1 | G34: 3000 | H34: =ROUND(IF(ISNUMBER(E34),E34,N(F34))*G34,2) -> 3000
A35: 02.18 | B35: פירוק פנלים קיימים בכל הבית | C35: פירוק פנלים קיימים בכל שטחי הבית, כולל ניקוי הקיר ושאריות הדבק, לפי הערות תוכניות ההריסה. | D35: קומפ׳ | E35: 1 | G35: 4500 | H35: =ROUND(IF(ISNUMBER(E35),E35,N(F35))*G35,2) -> 4500
A36: 02.19 | B36: פירוק מדרגות חוץ | C36: פירוק והריסת מדרגות בטון בגמר גרנוליט, לרבות פירוק המעקות ועיגוניהם, חיתוך הזיון לפי הצורך, איסוף הפסולת, העמסתה ,הובלתה לאתר מורשה, כולל אגרות פינוי וניקוי שטח העבודה בגמר הביצוע. | D36: קומפ׳ | E36: 1 | G36: 3000 | H36: =ROUND(IF(ISNUMBER(E36),E36,N(F36))*G36,2) -> 3000
A37: 02.20 | B37: פירוק רצפת גרנוליט בחניה, בכניסה ובשבילים | C37: פירוק רצפת גרנוליט ומצעה באזור החניה, הכניסה לבית והשבילים, כמפורט בתכולת פרק 2 בחוברת, לרבות ריכוז הפסולת. | D37: מ״ר | E37: 100 | G37: 100 | H37: =ROUND(IF(ISNUMBER(E37),E37,N(F37))*G37,2) -> 10000
A38: סה״כ פרק 02 — הריסות, פירוקים ופינוי | H38: =SUM(H18:H37) -> 117510
A40: פרק 03 — בנייה ותוספות מבניות
A41: 03.01 | B41: הגדלת מרפסת הסלון ותוספת פרגולה | C41: ביצוע הגדלת מרפסת הסלון ותוספת הפרגולה, קומפלט בתחום העבודות המבניות ובהתאם לתוכניות ולמפרט הקונסטרוקטור, לרבות ביסוס, רכיבי בטון וזיון, שלד פלדה מפרופילי RHS, לוחות בסיס, עיגונים, חיבורים וריתוכים, ככל שנדרשים בתכנון. העבודה כוללת את הבדיקות, אישורי הביצוע ותוכנית העדות הנדרשים במפרט. עבודות האיטום והגמר יבוצעו במסגרת הפרקים הייעודיים. | D41: קומפ׳ | E41: 1 | G41: 70000 | H41: =ROUND(IF(ISNUMBER(E41),E41,N(F41))*G41,2) -> 70000
A42: 03.02 | B42: תוספת חדר בקומת הגלריה | C42: ביצוע העבודות המבניות לתוספת החדר בקומת הגלריה, קומפלט לפי תוכניות הקונסטרוקטור והאדריכלות, לרבות רכיבי השלד, החיבורים והעיגונים למבנה הקיים, פתחים והכנות מבניות למערכות, בהתאם לתכנון. העבודה כוללת בדיקות, אישורים ותוכנית עדות; גמרים ומערכות מפורטים בפרקים הייעודיים. | D42: קומפ׳ | E42: 1 | G42: 120000 | H42: =ROUND(IF(ISNUMBER(E42),E42,N(F42))*G42,2) -> 120000
A43: 03.03 | B43: כניסה חדשה וגרם מדרגות חדש | C43: ביצוע העבודות המבניות לכניסה החדשה ולגרם המדרגות החדש, קומפלט לפי תוכניות הקונסטרוקטור והאדריכלות, לרבות ביסוס, רכיבי השלד, זיון, יציקות, חיבורים ועיגונים, וכן אלמנטי מעקה ככל שנכללים בתכנון המבני. גמרים יבוצעו במסגרת הפרקים הייעודיים. | D43: קומפ׳ | E43: 1 | G43: 38000 | H43: =ROUND(IF(ISNUMBER(E43),E43,N(F43))*G43,2) -> 38000
A44: 03.04 | B44: חיזוק גרם המדרגות הפנימי הקיים | C44: חיזוק גרם המדרגות הפנימי לאחר פירוק המעקה הקיים, קומפלט לפי פרטי הקונסטרוקטור, לרבות רכיבי החיזוק, החיבורים והעיגונים המוגדרים בתכנון, בדיקות וקבלת אישור הקונסטרוקטור לביצוע. | D44: קומפ׳ | E44: 1 | G44: 18000 | H44: =ROUND(IF(ISNUMBER(E44),E44,N(F44))*G44,2) -> 18000
...

Sheet סיכום הצעה
A1: סיכום הצעת מחיר – שלונסקי 53
A3: פרק | B3: סה״כ (₪)
A4: פרק 01 — הכנות והתארגנות לביצוע | B4: ='הצעת מחיר'!H15 -> 61625
A5: פרק 02 — הריסות, פירוקים ופינוי | B5: ='הצעת מחיר'!H38 -> 117510
A6: פרק 03 — בנייה ותוספות מבניות | B6: ='הצעת מחיר'!H45 -> 246000
A7: פרק 04 — חלוקה חדשה בקירות בלוקים | B7: ='הצעת מחיר'!H51 -> 7824
A8: פרק 05 — אינסטלציה, התקנת כלים סניטריים וברזים | B8: ='הצעת מחיר'!H87 -> 136840
A9: פרק 06 — חשמל | B9: ='הצעת מחיר'!H105 -> 97760
A10: פרק 07 — תאורה ומפסקי תאורה | B10: ='הצעת מחיר'!H128 -> 89605
A11: פרק 08 — מיזוג אוויר | B11: ='הצעת מחיר'!H135 -> 27050
A12: פרק 09 — מחיצות ותקרות גבס | B12: ='הצעת מחיר'!H142 -> 61529
A13: פרק 10 — איטום פנים | B13: ='הצעת מחיר'!H149 -> 37519
A14: פרק 11 — איטום גג ופרפט | B14: ='הצעת מחיר'!H157 -> 81450
A15: פרק 12 — אדני חלונות וספי פתחים | B15: ='הצעת מחיר'!H164 -> 29994.9
A16: פרק 13 — ריצופים, חיפויים ופנלים | B16: ='הצעת מחיר'!H173 -> 242563
A17: פרק 14 — טיח וגמר צבעוני חוץ | B17: ='הצעת מחיר'!H179 -> 55250
A18: פרק 15 — תיקוני טיח, שפכטל וצבע פנים | B18: ='הצעת מחיר'!H185 -> 57600
A19: פרק 16 — אלומיניום, דלתות ושערים | B19: ='הצעת מחיר'!H196 -> 232200
A20: פרק 17 — פיתוח חוץ | B20: ='הצעת מחיר'!H203 -> 51875
A21: פרק 18 — תשתיות תקשורת, מיגון, אינטרקום ושמע | B21: ='הצעת מחיר'!H211 -> 23000
A22: סה״כ עלות ישירה | B22: =SUM(B4:B21) -> 1657194.9
A23: הוצאות כלליות, ניהול, ביטוחים, ערבויות ורווח קבלן | B23: =ROUND(B22*C23,2) -> 248579.24 | C23: 0.15
A24: סה״כ לפני מע״מ | B24: =B22+B23 -> 1905774.1
A25: מע״מ | B25: =ROUND(B24*C25,2) -> 343039.35 | C25: 0.18
A26: סה״כ כולל מע״מ | B26: =B24+B25 -> 2248813.5
A28: מזה: סעיפים על בסיס כמויות זמניות (לפני תוספות) | B28: =SUMPRODUCT(--NOT(ISNUMBER('הצעת מחיר'!E5:E211)),--ISNUMBER('הצעת מחיר'!F5:F211),'הצעת מחיר'!H5:H211) -> 153735
A29: מזה: סעיפי קומפלט קונסטרוקטיביים (פרק 3, אומדן גס) | B29: ='הצעת מחיר'!H45 -> 246000
A30: לא כלול: אספקת כלים סניטריים וברזים, גופי תאורה, יחידות מיזוג ודודים; אספקת אריחי ריצוף וחיפוי; בריכה; נגרות; אגרות והגדלת חיבור חשמל לחברת החשמל; יועצים (איטום, קונסטרוקטור, תאורה)

Sheet בסיס תמחור
A1: סעיף | B1: שם | C1: יחידה | D1: מחיר יחידה (₪) | E1: בסיס המחיר | F1: הערה
A2: 01.01 | B2: התארגנות אתר | C2: קומפ׳ | D2: 8000 | E2: הערכת כמאי מעודכנת – רמת מחירי שיפוץ פרטי (הופחת ~15–25% לעומת הגרסה הקודמת)
A3: 01.02 | B3: גידור, שילוט ואמצעי בטיחות באתר | C3: קומפ׳ | D3: 4000 | E3: הערכת כמאי מעודכנת – רמת מחירי שיפוץ פרטי (הופחת ~15–25% לעומת הגרסה הקודמת)
A4: 01.03 | B4: חיבור מים זמני | C4: קומפ׳ | D4: 1500 | E4: הערכת כמאי מעודכנת – רמת מחירי שיפוץ פרטי (הופחת ~15–25% לעומת הגרסה הקודמת)
A5: 01.04 | B5: חיבור חשמל זמני | C5: קומפ׳ | D5: 3000 | E5: הערכת כמאי מעודכנת – רמת מחירי שיפוץ פרטי (הופחת ~15–25% לעומת הגרסה הקודמת)
A6: 01.05 | B6: הגנה על אלמנטים קיימים | C6: קומפ׳ | D6: 5000 | E6: הערכת כמאי מעודכנת – רמת מחירי שיפוץ פרטי (הופחת ~15–25% לעומת הגרסה הקודמת)
A7: 01.06 | B7: מדידות, אימות וסימון בלייזר | C7: קומפ׳ | D7: 3000 | E7: הערכת כמאי מעודכנת – רמת מחירי שיפוץ פרטי (הופחת ~15–25% לעומת הגרסה הקודמת)
A8: 01.07 | B8: מכולת פסולת והסדרת אזור ריכוז פסולת | C8: קומפ׳ | D8: 9000 | E8: הערכת כמאי מעודכנת – רמת מחירי שיפוץ פרטי (הופחת ~15–25% לעומת הגרסה הקודמת)
A9: 01.08 | B9: ניקיון שוטף בתקופת הביצוע | C9: קומפ׳ | D9: 9000 | E9: הערכת כמאי מעודכנת – רמת מחירי שיפוץ פרטי (הופחת ~15–25% לעומת הגרסה הקודמת)
A10: 01.09 | B10: פיגום חיצוני לחזיתות | C10: מ״ר | D10: 85 | E10: הערכת כמאי: הקמה ופירוק ~40 + שכירות ~4.5 חודשים ×10 ₪/מ"ר/חודש; לפי לוח הזמנים | F10: כמות זמנית
A11: 02.01 | B11: פירוק קירות ומחיצות במרתף | C11: מ״ר | D11: 120 | E11: הערכת כמאי מעודכנת – רמת מחירי שיפוץ פרטי (הופחת ~15–25% לעומת הגרסה הקודמת)
A12: 02.02 | B12: פירוק קירות ומחיצות בקומת הקרקע | C12: מ״ר | D12: 120 | E12: הערכת כמאי מעודכנת – רמת מחירי שיפוץ פרטי (הופחת ~15–25% לעומת הגרסה הקודמת)
A13: 02.03 | B13: פירוק קירות ומחיצות בקומה א׳ | C13: מ״ר | D13: 120 | E13: הערכת כמאי מעודכנת – רמת מחירי שיפוץ פרטי (הופחת ~15–25% לעומת הגרסה הקודמת)
A14: 02.04 | B14: פירוק תקרות גבס קיימות | C14: מ״ר | D14: 50 | E14: הערכת כמאי מעודכנת – רמת מחירי שיפוץ פרטי (הופחת ~15–25% לעומת הגרסה הקודמת)
A15: 02.05 | B15: פירוק ריצופים קיימים | C15: מ״ר | D15: 90 | E15: סקר: pro.co.il – פירוק ריצוף 90–110 ₪/מ"ר כולל מע"מ, ללא תאריך | הותאם לשיפוץ
A16: 02.06 | B16: פירוק ארונות מטבח קיימים | C16: קומפ׳ | D16: 2000 | E16: הערכת כמאי מעודכנת – רמת מחירי שיפוץ פרטי (הופחת ~15–25% לעומת הגרסה הקודמת)
A17: 02.07 | B17: פירוק ארונות ונגרות קיימת אחרת | C17: יח׳ | D17: 2500 | E17: הערכת כמאי מעודכנת – רמת מחירי שיפוץ פרטי (הופחת ~15–25% לעומת הגרסה הקודמת)
A18: 02.08 | B18: פירוק חלונות אלומיניום ותריסים קיימים – קומפלט | C18: קומפ׳ | D18: 6000 | E18: הערכת כמאי מעודכנת – רמת מחירי שיפוץ פרטי (הופחת ~15–25% לעומת הגרסה הקודמת)
A19: 02.09 | B19: פירוק דלתות פנים וכניסה ומשקופים – קומפלט | C19: קומפ׳ | D19: 3500 | E19: הערכת כמאי מעודכנת – רמת מחירי שיפוץ פרטי (הופחת ~15–25% לעומת הגרסה הקודמת)
A20: 02.10 | B20: פירוק חדרי רחצה, שירותים וכלים סניטריים – קומפלט | C20: קומפ׳ | D20: 8000 | E20: הערכת כמאי מעודכנת – רמת מחירי שיפוץ פרטי (הופחת ~15–25% לעומת הגרסה הקודמת)
A21: 02.11 | B21: פירוק נקודות, אביזרי חשמל וגופי תאורה קיימים | C21: קומפ׳ | D21: 4000 | E21: הערכת כמאי מעודכנת – רמת מחירי שיפוץ פרטי (הופחת ~15–25% לעומת הגרסה הקודמת)
A22: 02.12 | B22: פירוק צנרת אינסטלציה גלויה קיימת | C22: קומפ׳ | D22: 3000 | E22: הערכת כמאי מעודכנת – רמת מחירי שיפוץ פרטי (הופחת ~15–25% לעומת הגרסה הקודמת)
... A68: 05.33 | B68: מערכת ביוב וניקוז ראשית | C68: קומפ׳ | D68: 18000 | E68: הערכת כמאי מעודכנת – רמת מחירי שיפוץ פרטי (הופחת ~15–25% לעומת הגרסה הקודמת)
A69: 05.34 | B69: דוד מים חמים – התקנה וחיבור | C69: יח׳ | D69: 1200 | E69: הערכת כמאי מעודכנת – רמת מחירי שיפוץ פרטי (הופחת ~15–25% לעומת הגרסה הקודמת) | F69: כמות זמנית
A70: 05.35 | B70: בדיקות לחץ ואטימות ותוכנית עדות | C70: קומפ׳ | D70: 2500 | E70: הערכת כמאי מעודכנת – רמת מחירי שיפוץ פרטי (הופחת ~15–25% לעומת הגרסה הקודמת)
A71: 06.01 | B71: נקודת שקע רגיל | C71: יח׳ | D71: 270 | E71: סקר: midrag.co.il / oz-shiputsim.co.il – נקודת חשמל 350–700 ₪ (עד 2,000 בנקודה מורכבת) | הותאם לשיפוץ
A72: 06.02 | B72: נקודת שקע מוגן מים | C72: יח׳ | D72: 320 | E72: סקר: midrag.co.il / oz-shiputsim.co.il – נקודת חשמל 350–700 ₪ (עד 2,000 בנקודה מורכבת) | הותאם לשיפוץ
A73: 06.03 | B73: תשתית להפעלת תריס חשמלי | C73: יח׳ | D73: 380 | E73: הערכת כמאי מעודכנת – רמת מחירי שיפוץ פרטי (הופחת ~15–25% לעומת הגרסה הקודמת)
A74: 06.04 | B74: שקע מנוע תריס | C74: יח׳ | D74: 220 | E74: הערכת כמאי מעודכנת – רמת מחירי שיפוץ פרטי (הופחת ~15–25% לעומת הגרסה הקודמת)
A75: 06.05 | B75: נקודת שקע תלת־פאזי | C75: יח׳ | D75: 900 | E75: סקר: midrag.co.il / oz-shiputsim.co.il – נקודת חשמל 350–700 ₪ (עד 2,000 בנקודה מורכבת) | הותאם לשיפוץ
A76: 06.06 | B76: הרחבת לוח החשמל הראשי | C76: קומפ׳ | D76: 8500 | E76: הערכת כמאי מעודכנת – רמת מחירי שיפוץ פרטי (הופחת ~15–25% לעומת הגרסה הקודמת)
A77: 06.07 | B77: אספקה והתקנת פילר חברת החשמל | C77: קומפ׳ | D77: 7000 | E77: הערכת כמאי מעודכנת – רמת מחירי שיפוץ פרטי (הופחת ~15–25% לעומת הגרסה הקודמת)
A78: 06.08 | B78: טיפול בהגדלת חיבור החשמל | C78: קומפ׳ | D78: 4500 | E78: הערכת כמאי מעודכנת – רמת מחירי שיפוץ פרטי (הופחת ~15–25% לעומת הגרסה הקודמת)
A79: 06.09 | B79: בדיקת חשמל סופית | C79: קומפ׳ | D79: 2500 | E79: הערכת כמאי מעודכנת – רמת מחירי שיפוץ פרטי (הופחת ~15–25% לעומת הגרסה הקודמת)
A80: 06.10 | B80: נקודת שקע כוח | C80: יח׳ | D80: 380 | E80: סקר: midrag.co.il / oz-shiputsim.co.il – נקודת חשמל 350–700 ₪ (עד 2,000 בנקודה מורכבת) | הותאם לשיפוץ
A81: 06.11 | B81: נקודת הזנה ליחידת מיזוג | C81: נק׳ | D81: 750 | E81: הערכת כמאי מעודכנת – רמת מחירי שיפוץ פרטי (הופחת ~15–25% לעומת הגרסה הקודמת) | F81: כמות זמנית
A82: 06.12 | B82: נקודת חיבור ישיר | C82: נק׳ | D82: 520 | E82: הערכת כמאי מעודכנת – רמת מחירי שיפוץ פרטי (הופחת ~15–25% לעומת הגרסה הקודמת) | F82: כמות זמנית
A83: 06.13 | B83: מפסק זרם לדוד עם נורת סימון | C83: יח׳ | D83: 350 | E83: הערכת כמאי מעודכנת – רמת מחירי שיפוץ פרטי (הופחת ~15–25% לעומת הגרסה הקודמת) | F83: כמות זמנית
A84: 06.14 | B84: נקודת תרמוסטט למזגן | C84: נק׳ | D84: 400 | E84: הערכת כמאי מעודכנת – רמת מחירי שיפוץ פרטי (הופחת ~15–25% לעומת הגרסה הקודמת) | F84: כמות זמנית
A85: 06.15 | B85: פעמון ולחצן פעמון | C85: קומפ׳ | D85: 650 | E85: הערכת כמאי מעודכנת – רמת מחירי שיפוץ פרטי (הופחת ~15–25% לעומת הגרסה הקודמת)
...

Sheet סקר שוק
A1: נושא | B1: ממצא | C1: מקור | D1: הערת אמינות
A2: איטום חדר רטוב | B2: 100–250 ₪ למ"ר | C2: https://www.midrag.co.il/Content/Tip/19385 ; https://www.itum1.co.il | D2: אתרי פרסום; ללא תאריך ברור
A3: גבס | B3: 350–400 ₪ למ"ר כולל חומר והתקנה | C3: https://bonimbayit.co.il/private-home-construction-costs-2026/ | D3: מחירון 2026 לבית פרטי
A4: נקודת חשמל | B4: 350–2,000 ₪; חד־פאזית בבלוקים 500–700; בגבס מ-220 | C4: https://www.midrag.co.il/Content/Price/5586 ; https://oz-shiputsim.co.il | D4: אתרי חשמלאים; טווחים רחבים
A5: נקודת מים | B5: 700–1,500 ₪; חמים וקרים 1,600–2,500 ₪ | C5: https://mrplumber.co.il ; https://piper.co.il | D5: אתרי אינסטלטורים
A6: ריצוף, פירוק וחיפוי | B6: פירוק ריצוף 90–110; הדבקת ריצוף 200–250; חיפוי קיר 600–700 ₪ למ"ר, כולל מע"מ | C6: https://www.pro.co.il/general-contractors | D6: מחירון ללא תאריך, כולל מע"מ
A7: מדד תשומות הבנייה | B7: עלייה של 3.7% בשנה עד יוני 2026; רוב העלייה משכר עבודה | C7: https://klikatnadlan.co.il/tashumotjune2026/ (מצטט את הלמ"ס, הודעה 221/2026) | D7: נתוני יולי–ספטמבר לא נמצאו
A8: מגבלות הסקר | B8: לא נמצאו מחירים למ"ר לצבע, שפכטל, אלומיניום, שערים, מיזוג ופיתוח. שאר מחירי היחידה הם הערכת כמאי. לא נעשה שימוש במחירון דקל (אין גישה מורשית) | C8: — | D8: מומלץ לאמת מול הצעות ספקים ו/או דקל לפני הגשה
A9: תאריך הסקר | B9: 08/10/2026 | C9: — | D9: —

Sheet הנחות והחרגות
A1: # | B1: סוג | C1: תיאור
A2: 1 | B2: הנחה | C2: מחירי היחידה הם לפני מע״מ, בסיס אוקטובר 2026, לפרויקט שיפוץ פרטי (לא מכרז גדול), ללא הצמדה
A3: 2 | B3: הנחה | C3: אספקה: כלים סניטריים, ברזים, גופי תאורה, יחידות מיזוג, דודים ואריחי ריצוף/חיפוי – אספקה על המזמין; התמחור להתקנה בלבד. עד שיתקבלו דגמים (פרק 19 במפרט טרם הושלם). אלומיניום, דלתות, שערים, תריסים ואדני אבן – אספקה והתקנה
A4: 3 | B4: הנחה | C4: סעיפים ללא כמות בתוכניות: כמות זמנית לתמחור (עמודה F). החשבון הסופי לפי מדידה בפועל
A5: 4 | B5: הנחה | C5: פרק 3 (שלד): אומדן גס ללא תוכניות קונסטרוקציה – מומלץ סכום זמני עד לקבלת תוכניות
A6: 5 | B6: הנחה | C6: תוספת 15% להוצאות כלליות, ביטוחים, ערבויות ורווח (ניתנת לשינוי בגיליון הסיכום). אין תוספת בלתי צפויים
A7: 6 | B7: החרגה | C7: בריכה, נגרות (מטבחים וארונות), גינון מעבר לסכום הקומפלט, אגרות והיתרים, יועצים, הגדלת חיבור חשמל (התשלום לחברת החשמל), ריהוט
A8: 7 | B8: החרגה | C8: סתירות בכמויות (ראו "יומן חריגים"): הריסה קרקע 51/86, גבס קומה א׳ 52/57, ספוטים 111/115, מאווררים 6/12, כפל אפשרי 06.04/06.10
A9: 8 | B9: הנחה | C9: לוח זמנים: ראו קובץ לוח הזמנים (כ-31 שבועות). אין התחשבות במחירי הארכת זמן
A10: 9 | B10: אזהרה | C10: ההצעה היא טיוטה פנימית של כמאי הקבלן ולא הצעה חתומה. יש לאמת מחירים מול ספקים וקבלני משנה לפני שליחה

Sheet שינויים מגרסה קודמת
A1: נושא | B1: שינוי
A2: פיגום חיצוני | B2: נוסף סעיף 01.09 (מ"ר, 225 זמני) – נדרש לניסור המסגרות הדקורטיביות (02.15), לפרפט ולטיח החזיתות. בלוח הזמנים: הקמה 16/11/2026, פירוק 29/03/2027
A3: דלתות פנים | B3: 16.02: 4,200 → 1,200 ₪ ליחידה (לפי הקבלן)
A4: מחירים בכלל | B4: הופחתו מרמה גבוהה לרמת שיפוץ פרטי בכ-15–25% ברוב הסעיפים (פרטים בגיליון "בסיס תמחור"). נשמרו עוגני הסקר
A5: לוח זמנים | B5: ניסור המסגרות (D055) הופרד מהפירוקים ומבוצע מהפיגום; נוסף פירוק פיגום (X030)

Sheet מעקב כמויות
A1: סעיף | B1: שם | C1: יחידה | D1: כמות | E1: סטטוס | F1: מקור / בסיס
A2: 01.01 | B2: התארגנות אתר | C2: קומפ׳ | D2: 1 | E2: ORIGINAL | F2: כמות מהכתב המקורי; סכום חד־פעמי או לא ניתן לאימות מול המסמכים שהתקבלו
A3: 01.02 | B3: גידור, שילוט ואמצעי בטיחות באתר | C3: קומפ׳ | D3: 1 | E3: ORIGINAL | F3: כמות מהכתב המקורי; סכום חד־פעמי או לא ניתן לאימות מול המסמכים שהתקבלו
A4: 01.03 | B4: חיבור מים זמני | C4: קומפ׳ | D4: 1 | E4: ORIGINAL | F4: כמות מהכתב המקורי; סכום חד־פעמי או לא ניתן לאימות מול המסמכים שהתקבלו
A5: 01.04 | B5: חיבור חשמל זמני | C5: קומפ׳ | D5: 1 | E5: ORIGINAL | F5: כמות מהכתב המקורי; סכום חד־פעמי או לא ניתן לאימות מול המסמכים שהתקבלו
A6: 01.05 | B6: הגנה על אלמנטים קיימים | C6: קומפ׳ | D6: 1 | E6: ORIGINAL | F6: כמות מהכתב המקורי; סכום חד־פעמי או לא ניתן לאימות מול המסמכים שהתקבלו
A7: 01.06 | B7: מדידות, אימות וסימון בלייזר | C7: קומפ׳ | D7: 1 | E7: ORIGINAL | F7: כמות מהכתב המקורי; סכום חד־פעמי או לא ניתן לאימות מול המסמכים שהתקבלו
A8: 01.07 | B8: מכולת פסולת והסדרת אזור ריכוז פסולת | C8: קומפ׳ | D8: 1 | E8: ORIGINAL | F8: כמות מהכתב המקורי; סכום חד־פעמי או לא ניתן לאימות מול המסמכים שהתקבלו
A9: 01.08 | B9: ניקיון שוטף בתקופת הביצוע | C9: קומפ׳ | D9: 1 | E9: ORIGINAL | F9: כמות מהכתב המקורי; סכום חד־פעמי או לא ניתן לאימות מול המסמכים שהתקבלו
A10: 01.09 | B10: פיגום חיצוני לחזיתות | C10: מ״ר | E10: ASSUMED | F10: כמות זמנית = שטח החזיתות המטויחות (225 מ"ר, סעיף 14.01); שטח הפיגום בפועל ייקבע במדידה
A11: 02.01 | B11: פירוק קירות ומחיצות במרתף | C11: מ״ר | D11: 62 | E11: VERIFIED | F11: כתב כמויות קירות להריסה – כמויות לקבלן (סריקה 24/09/2026); ומפרט פרק 2 סעיפים 1,3
A12: 02.02 | B12: פירוק קירות ומחיצות בקומת הקרקע | C12: מ״ר | D12: 51 | E12: CONFLICT | F12: סריקה ומפרט (טבלה): 51 מ"ר. בפתיח המפרט: קרקע 86 מ"ר (סה"כ 233 במקום 198). נבחר 51 – לפי הסריקה העדכנית
A13: 02.03 | B13: פירוק קירות ומחיצות בקומה א׳ | C13: מ״ר | D13: 85 | E13: VERIFIED | F13: כתב כמויות קירות להריסה – כמויות לקבלן (סריקה 24/09/2026); ומפרט פרק 2 סעיפים 1,3
A14: 02.04 | B14: פירוק תקרות גבס קיימות | C14: מ״ר | D14: 10 | E14: UNVERIFIED | F14: אין תוכנית הריסה בין המסמכים שהתקבלו
A15: 02.05 | B15: פירוק ריצופים קיימים | C15: מ״ר | D15: 40 | E15: UNVERIFIED | F15: אין תוכנית הריסה בין המסמכים שהתקבלו
A16: 02.06 | B16: פירוק ארונות מטבח קיימים | C16: קומפ׳ | D16: 1 | E16: ORIGINAL | F16: כמות מהכתב המקורי; סכום חד־פעמי או לא ניתן לאימות מול המסמכים שהתקבלו
A17: 02.07 | B17: פירוק ארונות ונגרות קיימת אחרת | C17: יח׳ | D17: 1 | E17: ORIGINAL | F17: כמות מהכתב המקורי; סכום חד־פעמי או לא ניתן לאימות מול המסמכים שהתקבלו
A18: 02.08 | B18: פירוק חלונות אלומיניום ותריסים קיימים – קומפלט | C18: קומפ׳ | D18: 1 | E18: ORIGINAL | F18: כמות מהכתב המקורי; סכום חד־פעמי או לא ניתן לאימות מול המסמכים שהתקבלו
A19: 02.09 | B19: פירוק דלתות פנים וכניסה ומשקופים – קומפלט | C19: קומפ׳ | D19: 1 | E19: ORIGINAL | F19: כמות מהכתב המקורי; סכום חד־פעמי או לא ניתן לאימות מול המסמכים שהתקבלו
A20: 02.10 | B20: פירוק חדרי רחצה, שירותים וכלים סניטריים – קומפלט | C20: קומפ׳ | D20: 1 | E20: ORIGINAL | F20: כמות מהכתב המקורי; סכום חד־פעמי או לא ניתן לאימות מול המסמכים שהתקבלו
A21: 02.11 | B21: פירוק נקודות, אביזרי חשמל וגופי תאורה קיימים | C21: קומפ׳ | D21: 1 | E21: ORIGINAL | F21: כמות מהכתב המקורי; סכום חד־פעמי או לא ניתן לאימות מול המסמכים שהתקבלו
A22: 02.12 | B22: פירוק צנרת אינסטלציה גלויה קיימת | C22: קומפ׳ | D22: 1 | E22: ORIGINAL | F22: כמות מהכתב המקורי; סכום חד־פעמי או לא ניתן לאימות מול המסמכים שהתקבלו
... A68: 05.33 | B68: מערכת ביוב וניקוז ראשית | C68: קומפ׳ | D68: 1 | E68: ORIGINAL | F68: כמות מהכתב המקורי; סכום חד־פעמי או לא ניתן לאימות מול המסמכים שהתקבלו
A69: 05.34 | B69: דוד מים חמים – התקנה וחיבור | C69: יח׳ | E69: UNVERIFIED | F69: הכמות נקבעת מספירה בתוכניות חשמל/מיזוג/אינסטלציה שלא התקבלו
A70: 05.35 | B70: בדיקות לחץ ואטימות ותוכנית עדות | C70: קומפ׳ | D70: 1 | E70: ORIGINAL | F70: כמות מהכתב המקורי; סכום חד־פעמי או לא ניתן לאימות מול המסמכים שהתקבלו
A71: 06.01 | B71: נקודת שקע רגיל | C71: יח׳ | D71: 119 | E71: VERIFIED | F71: כתב כמויות חשמל (כמויות לקבלן (סריקה 24/09/2026)) ומפרט פרק 6. הערה בסריקה: שקע כפול נספר כ-1.5 – לאמת אם הכמות משוקללת
A72: 06.02 | B72: נקודת שקע מוגן מים | C72: יח׳ | D72: 51 | E72: VERIFIED | F72: כתב כמויות חשמל (כמויות לקבלן (סריקה 24/09/2026)) ומפרט פרק 6. הערה בסריקה: שקע כפול נספר כ-1.5 – לאמת אם הכמות משוקללת
A73: 06.03 | B73: תשתית להפעלת תריס חשמלי | C73: יח׳ | D73: 18 | E73: VERIFIED | F73: כתב כמויות חשמל (כמויות לקבלן (סריקה 24/09/2026)) ומפרט פרק 6. הערה בסריקה: שקע כפול נספר כ-1.5 – לאמת אם הכמות משוקללת
A74: 06.04 | B74: שקע מנוע תריס | C74: יח׳ | D74: 9 | E74: CONFLICT | F74: שניהם 9 – בסריקה רק "שקע כח 9"; במפרט שני סעיפים נפרדים. ייתכן כפל
A75: 06.05 | B75: נקודת שקע תלת־פאזי | C75: יח׳ | D75: 1 | E75: VERIFIED | F75: כתב כמויות חשמל (כמויות לקבלן (סריקה 24/09/2026)) ומפרט פרק 6. הערה בסריקה: שקע כפול נספר כ-1.5 – לאמת אם הכמות משוקללת
A76: 06.06 | B76: הרחבת לוח החשמל הראשי | C76: קומפ׳ | D76: 1 | E76: ORIGINAL | F76: כמות מהכתב המקורי; סכום חד־פעמי או לא ניתן לאימות מול המסמכים שהתקבלו
A77: 06.07 | B77: אספקה והתקנת פילר חברת החשמל | C77: קומפ׳ | D77: 1 | E77: ORIGINAL | F77: כמות מהכתב המקורי; סכום חד־פעמי או לא ניתן לאימות מול המסמכים שהתקבלו
A78: 06.08 | B78: טיפול בהגדלת חיבור החשמל | C78: קומפ׳ | D78: 1 | E78: ORIGINAL | F78: כמות מהכתב המקורי; סכום חד־פעמי או לא ניתן לאימות מול המסמכים שהתקבלו
A79: 06.09 | B79: בדיקת חשמל סופית | C79: קומפ׳ | D79: 1 | E79: ORIGINAL | F79: כמות מהכתב המקורי; סכום חד־פעמי או לא ניתן לאימות מול המסמכים שהתקבלו
A80: 06.10 | B80: נקודת שקע כוח | C80: יח׳ | D80: 9 | E80: CONFLICT | F80: שניהם 9 – בסריקה רק "שקע כח 9"; במפרט שני סעיפים נפרדים. ייתכן כפל
A81: 06.11 | B81: נקודת הזנה ליחידת מיזוג | C81: נק׳ | E81: UNVERIFIED | F81: הכמות נקבעת מספירה בתוכניות חשמל/מיזוג/אינסטלציה שלא התקבלו
A82: 06.12 | B82: נקודת חיבור ישיר | C82: נק׳ | E82: UNVERIFIED | F82: הכמות נקבעת מספירה בתוכניות חשמל/מיזוג/אינסטלציה שלא התקבלו
A83: 06.13 | B83: מפסק זרם לדוד עם נורת סימון | C83: יח׳ | E83: UNVERIFIED | F83: הכמות נקבעת מספירה בתוכניות חשמל/מיזוג/אינסטלציה שלא התקבלו
A84: 06.14 | B84: נקודת תרמוסטט למזגן | C84: נק׳ | E84: UNVERIFIED | F84: הכמות נקבעת מספירה בתוכניות חשמל/מיזוג/אינסטלציה שלא התקבלו
A85: 06.15 | B85: פעמון ולחצן פעמון | C85: קומפ׳ | D85: 1 | E85: ORIGINAL | F85: כמות מהכתב המקורי; סכום חד־פעמי או לא ניתן לאימות מול המסמכים שהתקבלו
...
